/Users/mrjones/Github/Projects/sheltr-ai/apps/api/.venv/lib/python3.9/site-packages/urllib3/__init__.py:35: NotOpenSSLWarning: urllib3 v2 only supports OpenSSL 1.1.1+, currently the 'ssl' module is compiled with 'LibreSSL 2.8.3'. See: https://github.com/urllib3/urllib3/issues/3020
  warnings.warn(
INFO:services.analytics_service:Analytics Service: Firebase initialized successfully
INFO:services.chatbot.orchestrator:ü§ñ Chatbot Orchestrator initialized
INFO:__main__:üè† Starting SHELTR-AI API server...
INFO:__main__:üîê Multi-tenant authentication system ready
INFO:__main__:üìö API documentation: http://localhost:8000/docs
INFO:__main__:üè• Health check: http://localhost:8000/health
INFO:     Will watch for changes in these directories: ['/Users/mrjones/Github/Projects/sheltr-ai/apps/api']
INFO:     Uvicorn running on http://0.0.0.0:8000 (Press CTRL+C to quit)
INFO:     Started reloader process [1371] using WatchFiles
/Users/mrjones/Github/Projects/sheltr-ai/apps/api/.venv/lib/python3.9/site-packages/urllib3/__init__.py:35: NotOpenSSLWarning: urllib3 v2 only supports OpenSSL 1.1.1+, currently the 'ssl' module is compiled with 'LibreSSL 2.8.3'. See: https://github.com/urllib3/urllib3/issues/3020
  warnings.warn(
INFO:services.analytics_service:Analytics Service: Firebase initialized successfully
INFO:services.chatbot.orchestrator:ü§ñ Chatbot Orchestrator initialized
INFO:     Started server process [1385]
INFO:     Waiting for application startup.
INFO:main:üöÄ SHELTR-AI API starting up...
INFO:main:üîê Authentication system initialized
INFO:main:üè¢ Multi-tenant architecture ready
INFO:     Application startup complete.
INFO:     127.0.0.1:55929 - "GET /health HTTP/1.1" 200 OK
INFO:     127.0.0.1:57853 - "OPTIONS /analytics/test-platform HTTP/1.1" 200 OK
INFO:     127.0.0.1:57855 - "OPTIONS /analytics/test-platform HTTP/1.1" 200 OK
INFO:routers.analytics:Testing platform analytics (no auth)
ERROR:grpc._plugin_wrapping:AuthMetadataPluginCallback "<google.auth.transport.grpc.AuthMetadataPlugin object at 0x108428ac0>" raised exception!
Traceback (most recent call last):
  File "/Users/mrjones/Github/Projects/sheltr-ai/apps/api/.venv/lib/python3.9/site-packages/grpc/_plugin_wrapping.py", line 105, in __call__
    self._metadata_plugin(
  File "/Users/mrjones/Github/Projects/sheltr-ai/apps/api/.venv/lib/python3.9/site-packages/google/auth/transport/grpc.py", line 95, in __call__
    callback(self._get_authorization_headers(context), None)
  File "/Users/mrjones/Github/Projects/sheltr-ai/apps/api/.venv/lib/python3.9/site-packages/google/auth/transport/grpc.py", line 81, in _get_authorization_headers
    self._credentials.before_request(
  File "/Users/mrjones/Github/Projects/sheltr-ai/apps/api/.venv/lib/python3.9/site-packages/google/auth/credentials.py", line 175, in before_request
    self.refresh(request)
  File "/Users/mrjones/Github/Projects/sheltr-ai/apps/api/.venv/lib/python3.9/site-packages/google/oauth2/service_account.py", line 449, in refresh
    access_token, expiry, _ = _client.jwt_grant(
  File "/Users/mrjones/Github/Projects/sheltr-ai/apps/api/.venv/lib/python3.9/site-packages/google/oauth2/_client.py", line 308, in jwt_grant
    response_data = _token_endpoint_request(
  File "/Users/mrjones/Github/Projects/sheltr-ai/apps/api/.venv/lib/python3.9/site-packages/google/oauth2/_client.py", line 279, in _token_endpoint_request
    _handle_error_response(response_data, retryable_error)
  File "/Users/mrjones/Github/Projects/sheltr-ai/apps/api/.venv/lib/python3.9/site-packages/google/oauth2/_client.py", line 72, in _handle_error_response
    raise exceptions.RefreshError(
google.auth.exceptions.RefreshError: ('invalid_grant: Invalid JWT Signature.', {'error': 'invalid_grant', 'error_description': 'Invalid JWT Signature.'})
ERROR:grpc._plugin_wrapping:AuthMetadataPluginCallback "<google.auth.transport.grpc.AuthMetadataPlugin object at 0x108428ac0>" raised exception!
Traceback (most recent call last):
  File "/Users/mrjones/Github/Projects/sheltr-ai/apps/api/.venv/lib/python3.9/site-packages/grpc/_plugin_wrapping.py", line 105, in __call__
    self._metadata_plugin(
  File "/Users/mrjones/Github/Projects/sheltr-ai/apps/api/.venv/lib/python3.9/site-packages/google/auth/transport/grpc.py", line 95, in __call__
    callback(self._get_authorization_headers(context), None)
  File "/Users/mrjones/Github/Projects/sheltr-ai/apps/api/.venv/lib/python3.9/site-packages/google/auth/transport/grpc.py", line 81, in _get_authorization_headers
    self._credentials.before_request(
  File "/Users/mrjones/Github/Projects/sheltr-ai/apps/api/.venv/lib/python3.9/site-packages/google/auth/credentials.py", line 175, in before_request
    self.refresh(request)
  File "/Users/mrjones/Github/Projects/sheltr-ai/apps/api/.venv/lib/python3.9/site-packages/google/oauth2/service_account.py", line 449, in refresh
    access_token, expiry, _ = _client.jwt_grant(
  File "/Users/mrjones/Github/Projects/sheltr-ai/apps/api/.venv/lib/python3.9/site-packages/google/oauth2/_client.py", line 308, in jwt_grant
    response_data = _token_endpoint_request(
  File "/Users/mrjones/Github/Projects/sheltr-ai/apps/api/.venv/lib/python3.9/site-packages/google/oauth2/_client.py", line 279, in _token_endpoint_request
    _handle_error_response(response_data, retryable_error)
  File "/Users/mrjones/Github/Projects/sheltr-ai/apps/api/.venv/lib/python3.9/site-packages/google/oauth2/_client.py", line 72, in _handle_error_response
    raise exceptions.RefreshError(
google.auth.exceptions.RefreshError: ('invalid_grant: Invalid JWT Signature.', {'error': 'invalid_grant', 'error_description': 'Invalid JWT Signature.'})
ERROR:grpc._plugin_wrapping:AuthMetadataPluginCallback "<google.auth.transport.grpc.AuthMetadataPlugin object at 0x108428ac0>" raised exception!
Traceback (most recent call last):
  File "/Users/mrjones/Github/Projects/sheltr-ai/apps/api/.venv/lib/python3.9/site-packages/grpc/_plugin_wrapping.py", line 105, in __call__
    self._metadata_plugin(
  File "/Users/mrjones/Github/Projects/sheltr-ai/apps/api/.venv/lib/python3.9/site-packages/google/auth/transport/grpc.py", line 95, in __call__
    callback(self._get_authorization_headers(context), None)
  File "/Users/mrjones/Github/Projects/sheltr-ai/apps/api/.venv/lib/python3.9/site-packages/google/auth/transport/grpc.py", line 81, in _get_authorization_headers
    self._credentials.before_request(
  File "/Users/mrjones/Github/Projects/sheltr-ai/apps/api/.venv/lib/python3.9/site-packages/google/auth/credentials.py", line 175, in before_request
    self.refresh(request)
  File "/Users/mrjones/Github/Projects/sheltr-ai/apps/api/.venv/lib/python3.9/site-packages/google/oauth2/service_account.py", line 449, in refresh
    access_token, expiry, _ = _client.jwt_grant(
  File "/Users/mrjones/Github/Projects/sheltr-ai/apps/api/.venv/lib/python3.9/site-packages/google/oauth2/_client.py", line 308, in jwt_grant
    response_data = _token_endpoint_request(
  File "/Users/mrjones/Github/Projects/sheltr-ai/apps/api/.venv/lib/python3.9/site-packages/google/oauth2/_client.py", line 279, in _token_endpoint_request
    _handle_error_response(response_data, retryable_error)
  File "/Users/mrjones/Github/Projects/sheltr-ai/apps/api/.venv/lib/python3.9/site-packages/google/oauth2/_client.py", line 72, in _handle_error_response
    raise exceptions.RefreshError(
google.auth.exceptions.RefreshError: ('invalid_grant: Invalid JWT Signature.', {'error': 'invalid_grant', 'error_description': 'Invalid JWT Signature.'})
ERROR:grpc._plugin_wrapping:AuthMetadataPluginCallback "<google.auth.transport.grpc.AuthMetadataPlugin object at 0x108428ac0>" raised exception!
Traceback (most recent call last):
  File "/Users/mrjones/Github/Projects/sheltr-ai/apps/api/.venv/lib/python3.9/site-packages/grpc/_plugin_wrapping.py", line 105, in __call__
    self._metadata_plugin(
  File "/Users/mrjones/Github/Projects/sheltr-ai/apps/api/.venv/lib/python3.9/site-packages/google/auth/transport/grpc.py", line 95, in __call__
    callback(self._get_authorization_headers(context), None)
  File "/Users/mrjones/Github/Projects/sheltr-ai/apps/api/.venv/lib/python3.9/site-packages/google/auth/transport/grpc.py", line 81, in _get_authorization_headers
    self._credentials.before_request(
  File "/Users/mrjones/Github/Projects/sheltr-ai/apps/api/.venv/lib/python3.9/site-packages/google/auth/credentials.py", line 175, in before_request
    self.refresh(request)
  File "/Users/mrjones/Github/Projects/sheltr-ai/apps/api/.venv/lib/python3.9/site-packages/google/oauth2/service_account.py", line 449, in refresh
    access_token, expiry, _ = _client.jwt_grant(
  File "/Users/mrjones/Github/Projects/sheltr-ai/apps/api/.venv/lib/python3.9/site-packages/google/oauth2/_client.py", line 308, in jwt_grant
    response_data = _token_endpoint_request(
  File "/Users/mrjones/Github/Projects/sheltr-ai/apps/api/.venv/lib/python3.9/site-packages/google/oauth2/_client.py", line 279, in _token_endpoint_request
    _handle_error_response(response_data, retryable_error)
  File "/Users/mrjones/Github/Projects/sheltr-ai/apps/api/.venv/lib/python3.9/site-packages/google/oauth2/_client.py", line 72, in _handle_error_response
    raise exceptions.RefreshError(
google.auth.exceptions.RefreshError: ('invalid_grant: Invalid JWT Signature.', {'error': 'invalid_grant', 'error_description': 'Invalid JWT Signature.'})
ERROR:grpc._plugin_wrapping:AuthMetadataPluginCallback "<google.auth.transport.grpc.AuthMetadataPlugin object at 0x108428ac0>" raised exception!
Traceback (most recent call last):
  File "/Users/mrjones/Github/Projects/sheltr-ai/apps/api/.venv/lib/python3.9/site-packages/grpc/_plugin_wrapping.py", line 105, in __call__
    self._metadata_plugin(
  File "/Users/mrjones/Github/Projects/sheltr-ai/apps/api/.venv/lib/python3.9/site-packages/google/auth/transport/grpc.py", line 95, in __call__
    callback(self._get_authorization_headers(context), None)
  File "/Users/mrjones/Github/Projects/sheltr-ai/apps/api/.venv/lib/python3.9/site-packages/google/auth/transport/grpc.py", line 81, in _get_authorization_headers
    self._credentials.before_request(
  File "/Users/mrjones/Github/Projects/sheltr-ai/apps/api/.venv/lib/python3.9/site-packages/google/auth/credentials.py", line 175, in before_request
    self.refresh(request)
  File "/Users/mrjones/Github/Projects/sheltr-ai/apps/api/.venv/lib/python3.9/site-packages/google/oauth2/service_account.py", line 449, in refresh
    access_token, expiry, _ = _client.jwt_grant(
  File "/Users/mrjones/Github/Projects/sheltr-ai/apps/api/.venv/lib/python3.9/site-packages/google/oauth2/_client.py", line 308, in jwt_grant
    response_data = _token_endpoint_request(
  File "/Users/mrjones/Github/Projects/sheltr-ai/apps/api/.venv/lib/python3.9/site-packages/google/oauth2/_client.py", line 279, in _token_endpoint_request
    _handle_error_response(response_data, retryable_error)
  File "/Users/mrjones/Github/Projects/sheltr-ai/apps/api/.venv/lib/python3.9/site-packages/google/oauth2/_client.py", line 72, in _handle_error_response
    raise exceptions.RefreshError(
google.auth.exceptions.RefreshError: ('invalid_grant: Invalid JWT Signature.', {'error': 'invalid_grant', 'error_description': 'Invalid JWT Signature.'})
ERROR:grpc._plugin_wrapping:AuthMetadataPluginCallback "<google.auth.transport.grpc.AuthMetadataPlugin object at 0x108428ac0>" raised exception!
Traceback (most recent call last):
  File "/Users/mrjones/Github/Projects/sheltr-ai/apps/api/.venv/lib/python3.9/site-packages/grpc/_plugin_wrapping.py", line 105, in __call__
    self._metadata_plugin(
  File "/Users/mrjones/Github/Projects/sheltr-ai/apps/api/.venv/lib/python3.9/site-packages/google/auth/transport/grpc.py", line 95, in __call__
    callback(self._get_authorization_headers(context), None)
  File "/Users/mrjones/Github/Projects/sheltr-ai/apps/api/.venv/lib/python3.9/site-packages/google/auth/transport/grpc.py", line 81, in _get_authorization_headers
    self._credentials.before_request(
  File "/Users/mrjones/Github/Projects/sheltr-ai/apps/api/.venv/lib/python3.9/site-packages/google/auth/credentials.py", line 175, in before_request
    self.refresh(request)
  File "/Users/mrjones/Github/Projects/sheltr-ai/apps/api/.venv/lib/python3.9/site-packages/google/oauth2/service_account.py", line 449, in refresh
    access_token, expiry, _ = _client.jwt_grant(
  File "/Users/mrjones/Github/Projects/sheltr-ai/apps/api/.venv/lib/python3.9/site-packages/google/oauth2/_client.py", line 308, in jwt_grant
    response_data = _token_endpoint_request(
  File "/Users/mrjones/Github/Projects/sheltr-ai/apps/api/.venv/lib/python3.9/site-packages/google/oauth2/_client.py", line 279, in _token_endpoint_request
    _handle_error_response(response_data, retryable_error)
  File "/Users/mrjones/Github/Projects/sheltr-ai/apps/api/.venv/lib/python3.9/site-packages/google/oauth2/_client.py", line 72, in _handle_error_response
    raise exceptions.RefreshError(
google.auth.exceptions.RefreshError: ('invalid_grant: Invalid JWT Signature.', {'error': 'invalid_grant', 'error_description': 'Invalid JWT Signature.'})
ERROR:grpc._plugin_wrapping:AuthMetadataPluginCallback "<google.auth.transport.grpc.AuthMetadataPlugin object at 0x108428ac0>" raised exception!
Traceback (most recent call last):
  File "/Users/mrjones/Github/Projects/sheltr-ai/apps/api/.venv/lib/python3.9/site-packages/grpc/_plugin_wrapping.py", line 105, in __call__
    self._metadata_plugin(
  File "/Users/mrjones/Github/Projects/sheltr-ai/apps/api/.venv/lib/python3.9/site-packages/google/auth/transport/grpc.py", line 95, in __call__
    callback(self._get_authorization_headers(context), None)
  File "/Users/mrjones/Github/Projects/sheltr-ai/apps/api/.venv/lib/python3.9/site-packages/google/auth/transport/grpc.py", line 81, in _get_authorization_headers
    self._credentials.before_request(
  File "/Users/mrjones/Github/Projects/sheltr-ai/apps/api/.venv/lib/python3.9/site-packages/google/auth/credentials.py", line 175, in before_request
    self.refresh(request)
  File "/Users/mrjones/Github/Projects/sheltr-ai/apps/api/.venv/lib/python3.9/site-packages/google/oauth2/service_account.py", line 449, in refresh
    access_token, expiry, _ = _client.jwt_grant(
  File "/Users/mrjones/Github/Projects/sheltr-ai/apps/api/.venv/lib/python3.9/site-packages/google/oauth2/_client.py", line 308, in jwt_grant
    response_data = _token_endpoint_request(
  File "/Users/mrjones/Github/Projects/sheltr-ai/apps/api/.venv/lib/python3.9/site-packages/google/oauth2/_client.py", line 279, in _token_endpoint_request
    _handle_error_response(response_data, retryable_error)
  File "/Users/mrjones/Github/Projects/sheltr-ai/apps/api/.venv/lib/python3.9/site-packages/google/oauth2/_client.py", line 72, in _handle_error_response
    raise exceptions.RefreshError(
google.auth.exceptions.RefreshError: ('invalid_grant: Invalid JWT Signature.', {'error': 'invalid_grant', 'error_description': 'Invalid JWT Signature.'})
ERROR:grpc._plugin_wrapping:AuthMetadataPluginCallback "<google.auth.transport.grpc.AuthMetadataPlugin object at 0x108428ac0>" raised exception!
Traceback (most recent call last):
  File "/Users/mrjones/Github/Projects/sheltr-ai/apps/api/.venv/lib/python3.9/site-packages/grpc/_plugin_wrapping.py", line 105, in __call__
    self._metadata_plugin(
  File "/Users/mrjones/Github/Projects/sheltr-ai/apps/api/.venv/lib/python3.9/site-packages/google/auth/transport/grpc.py", line 95, in __call__
    callback(self._get_authorization_headers(context), None)
  File "/Users/mrjones/Github/Projects/sheltr-ai/apps/api/.venv/lib/python3.9/site-packages/google/auth/transport/grpc.py", line 81, in _get_authorization_headers
    self._credentials.before_request(
  File "/Users/mrjones/Github/Projects/sheltr-ai/apps/api/.venv/lib/python3.9/site-packages/google/auth/credentials.py", line 175, in before_request
    self.refresh(request)
  File "/Users/mrjones/Github/Projects/sheltr-ai/apps/api/.venv/lib/python3.9/site-packages/google/oauth2/service_account.py", line 449, in refresh
    access_token, expiry, _ = _client.jwt_grant(
  File "/Users/mrjones/Github/Projects/sheltr-ai/apps/api/.venv/lib/python3.9/site-packages/google/oauth2/_client.py", line 308, in jwt_grant
    response_data = _token_endpoint_request(
  File "/Users/mrjones/Github/Projects/sheltr-ai/apps/api/.venv/lib/python3.9/site-packages/google/oauth2/_client.py", line 279, in _token_endpoint_request
    _handle_error_response(response_data, retryable_error)
  File "/Users/mrjones/Github/Projects/sheltr-ai/apps/api/.venv/lib/python3.9/site-packages/google/oauth2/_client.py", line 72, in _handle_error_response
    raise exceptions.RefreshError(
google.auth.exceptions.RefreshError: ('invalid_grant: Invalid JWT Signature.', {'error': 'invalid_grant', 'error_description': 'Invalid JWT Signature.'})
ERROR:grpc._plugin_wrapping:AuthMetadataPluginCallback "<google.auth.transport.grpc.AuthMetadataPlugin object at 0x108428ac0>" raised exception!
Traceback (most recent call last):
  File "/Users/mrjones/Github/Projects/sheltr-ai/apps/api/.venv/lib/python3.9/site-packages/grpc/_plugin_wrapping.py", line 105, in __call__
    self._metadata_plugin(
  File "/Users/mrjones/Github/Projects/sheltr-ai/apps/api/.venv/lib/python3.9/site-packages/google/auth/transport/grpc.py", line 95, in __call__
    callback(self._get_authorization_headers(context), None)
  File "/Users/mrjones/Github/Projects/sheltr-ai/apps/api/.venv/lib/python3.9/site-packages/google/auth/transport/grpc.py", line 81, in _get_authorization_headers
    self._credentials.before_request(
  File "/Users/mrjones/Github/Projects/sheltr-ai/apps/api/.venv/lib/python3.9/site-packages/google/auth/credentials.py", line 175, in before_request
    self.refresh(request)
  File "/Users/mrjones/Github/Projects/sheltr-ai/apps/api/.venv/lib/python3.9/site-packages/google/oauth2/service_account.py", line 449, in refresh
    access_token, expiry, _ = _client.jwt_grant(
  File "/Users/mrjones/Github/Projects/sheltr-ai/apps/api/.venv/lib/python3.9/site-packages/google/oauth2/_client.py", line 308, in jwt_grant
    response_data = _token_endpoint_request(
  File "/Users/mrjones/Github/Projects/sheltr-ai/apps/api/.venv/lib/python3.9/site-packages/google/oauth2/_client.py", line 279, in _token_endpoint_request
    _handle_error_response(response_data, retryable_error)
  File "/Users/mrjones/Github/Projects/sheltr-ai/apps/api/.venv/lib/python3.9/site-packages/google/oauth2/_client.py", line 72, in _handle_error_response
    raise exceptions.RefreshError(
google.auth.exceptions.RefreshError: ('invalid_grant: Invalid JWT Signature.', {'error': 'invalid_grant', 'error_description': 'Invalid JWT Signature.'})
ERROR:grpc._plugin_wrapping:AuthMetadataPluginCallback "<google.auth.transport.grpc.AuthMetadataPlugin object at 0x108428ac0>" raised exception!
Traceback (most recent call last):
  File "/Users/mrjones/Github/Projects/sheltr-ai/apps/api/.venv/lib/python3.9/site-packages/grpc/_plugin_wrapping.py", line 105, in __call__
    self._metadata_plugin(
  File "/Users/mrjones/Github/Projects/sheltr-ai/apps/api/.venv/lib/python3.9/site-packages/google/auth/transport/grpc.py", line 95, in __call__
    callback(self._get_authorization_headers(context), None)
  File "/Users/mrjones/Github/Projects/sheltr-ai/apps/api/.venv/lib/python3.9/site-packages/google/auth/transport/grpc.py", line 81, in _get_authorization_headers
    self._credentials.before_request(
  File "/Users/mrjones/Github/Projects/sheltr-ai/apps/api/.venv/lib/python3.9/site-packages/google/auth/credentials.py", line 175, in before_request
    self.refresh(request)
  File "/Users/mrjones/Github/Projects/sheltr-ai/apps/api/.venv/lib/python3.9/site-packages/google/oauth2/service_account.py", line 449, in refresh
    access_token, expiry, _ = _client.jwt_grant(
  File "/Users/mrjones/Github/Projects/sheltr-ai/apps/api/.venv/lib/python3.9/site-packages/google/oauth2/_client.py", line 308, in jwt_grant
    response_data = _token_endpoint_request(
  File "/Users/mrjones/Github/Projects/sheltr-ai/apps/api/.venv/lib/python3.9/site-packages/google/oauth2/_client.py", line 279, in _token_endpoint_request
    _handle_error_response(response_data, retryable_error)
  File "/Users/mrjones/Github/Projects/sheltr-ai/apps/api/.venv/lib/python3.9/site-packages/google/oauth2/_client.py", line 72, in _handle_error_response
    raise exceptions.RefreshError(
google.auth.exceptions.RefreshError: ('invalid_grant: Invalid JWT Signature.', {'error': 'invalid_grant', 'error_description': 'Invalid JWT Signature.'})
ERROR:grpc._plugin_wrapping:AuthMetadataPluginCallback "<google.auth.transport.grpc.AuthMetadataPlugin object at 0x108428ac0>" raised exception!
Traceback (most recent call last):
  File "/Users/mrjones/Github/Projects/sheltr-ai/apps/api/.venv/lib/python3.9/site-packages/grpc/_plugin_wrapping.py", line 105, in __call__
    self._metadata_plugin(
  File "/Users/mrjones/Github/Projects/sheltr-ai/apps/api/.venv/lib/python3.9/site-packages/google/auth/transport/grpc.py", line 95, in __call__
    callback(self._get_authorization_headers(context), None)
  File "/Users/mrjones/Github/Projects/sheltr-ai/apps/api/.venv/lib/python3.9/site-packages/google/auth/transport/grpc.py", line 81, in _get_authorization_headers
    self._credentials.before_request(
  File "/Users/mrjones/Github/Projects/sheltr-ai/apps/api/.venv/lib/python3.9/site-packages/google/auth/credentials.py", line 175, in before_request
    self.refresh(request)
  File "/Users/mrjones/Github/Projects/sheltr-ai/apps/api/.venv/lib/python3.9/site-packages/google/oauth2/service_account.py", line 449, in refresh
    access_token, expiry, _ = _client.jwt_grant(
  File "/Users/mrjones/Github/Projects/sheltr-ai/apps/api/.venv/lib/python3.9/site-packages/google/oauth2/_client.py", line 308, in jwt_grant
    response_data = _token_endpoint_request(
  File "/Users/mrjones/Github/Projects/sheltr-ai/apps/api/.venv/lib/python3.9/site-packages/google/oauth2/_client.py", line 279, in _token_endpoint_request
    _handle_error_response(response_data, retryable_error)
  File "/Users/mrjones/Github/Projects/sheltr-ai/apps/api/.venv/lib/python3.9/site-packages/google/oauth2/_client.py", line 72, in _handle_error_response
    raise exceptions.RefreshError(
google.auth.exceptions.RefreshError: ('invalid_grant: Invalid JWT Signature.', {'error': 'invalid_grant', 'error_description': 'Invalid JWT Signature.'})
ERROR:grpc._plugin_wrapping:AuthMetadataPluginCallback "<google.auth.transport.grpc.AuthMetadataPlugin object at 0x108428ac0>" raised exception!
Traceback (most recent call last):
  File "/Users/mrjones/Github/Projects/sheltr-ai/apps/api/.venv/lib/python3.9/site-packages/grpc/_plugin_wrapping.py", line 105, in __call__
    self._metadata_plugin(
  File "/Users/mrjones/Github/Projects/sheltr-ai/apps/api/.venv/lib/python3.9/site-packages/google/auth/transport/grpc.py", line 95, in __call__
    callback(self._get_authorization_headers(context), None)
  File "/Users/mrjones/Github/Projects/sheltr-ai/apps/api/.venv/lib/python3.9/site-packages/google/auth/transport/grpc.py", line 81, in _get_authorization_headers
    self._credentials.before_request(
  File "/Users/mrjones/Github/Projects/sheltr-ai/apps/api/.venv/lib/python3.9/site-packages/google/auth/credentials.py", line 175, in before_request
    self.refresh(request)
  File "/Users/mrjones/Github/Projects/sheltr-ai/apps/api/.venv/lib/python3.9/site-packages/google/oauth2/service_account.py", line 449, in refresh
    access_token, expiry, _ = _client.jwt_grant(
  File "/Users/mrjones/Github/Projects/sheltr-ai/apps/api/.venv/lib/python3.9/site-packages/google/oauth2/_client.py", line 308, in jwt_grant
    response_data = _token_endpoint_request(
  File "/Users/mrjones/Github/Projects/sheltr-ai/apps/api/.venv/lib/python3.9/site-packages/google/oauth2/_client.py", line 279, in _token_endpoint_request
    _handle_error_response(response_data, retryable_error)
  File "/Users/mrjones/Github/Projects/sheltr-ai/apps/api/.venv/lib/python3.9/site-packages/google/oauth2/_client.py", line 72, in _handle_error_response
    raise exceptions.RefreshError(
google.auth.exceptions.RefreshError: ('invalid_grant: Invalid JWT Signature.', {'error': 'invalid_grant', 'error_description': 'Invalid JWT Signature.'})
ERROR:grpc._plugin_wrapping:AuthMetadataPluginCallback "<google.auth.transport.grpc.AuthMetadataPlugin object at 0x108428ac0>" raised exception!
Traceback (most recent call last):
  File "/Users/mrjones/Github/Projects/sheltr-ai/apps/api/.venv/lib/python3.9/site-packages/grpc/_plugin_wrapping.py", line 105, in __call__
    self._metadata_plugin(
  File "/Users/mrjones/Github/Projects/sheltr-ai/apps/api/.venv/lib/python3.9/site-packages/google/auth/transport/grpc.py", line 95, in __call__
    callback(self._get_authorization_headers(context), None)
  File "/Users/mrjones/Github/Projects/sheltr-ai/apps/api/.venv/lib/python3.9/site-packages/google/auth/transport/grpc.py", line 81, in _get_authorization_headers
    self._credentials.before_request(
  File "/Users/mrjones/Github/Projects/sheltr-ai/apps/api/.venv/lib/python3.9/site-packages/google/auth/credentials.py", line 175, in before_request
    self.refresh(request)
  File "/Users/mrjones/Github/Projects/sheltr-ai/apps/api/.venv/lib/python3.9/site-packages/google/oauth2/service_account.py", line 449, in refresh
    access_token, expiry, _ = _client.jwt_grant(
  File "/Users/mrjones/Github/Projects/sheltr-ai/apps/api/.venv/lib/python3.9/site-packages/google/oauth2/_client.py", line 308, in jwt_grant
    response_data = _token_endpoint_request(
  File "/Users/mrjones/Github/Projects/sheltr-ai/apps/api/.venv/lib/python3.9/site-packages/google/oauth2/_client.py", line 279, in _token_endpoint_request
    _handle_error_response(response_data, retryable_error)
  File "/Users/mrjones/Github/Projects/sheltr-ai/apps/api/.venv/lib/python3.9/site-packages/google/oauth2/_client.py", line 72, in _handle_error_response
    raise exceptions.RefreshError(
google.auth.exceptions.RefreshError: ('invalid_grant: Invalid JWT Signature.', {'error': 'invalid_grant', 'error_description': 'Invalid JWT Signature.'})
ERROR:grpc._plugin_wrapping:AuthMetadataPluginCallback "<google.auth.transport.grpc.AuthMetadataPlugin object at 0x108428ac0>" raised exception!
Traceback (most recent call last):
  File "/Users/mrjones/Github/Projects/sheltr-ai/apps/api/.venv/lib/python3.9/site-packages/grpc/_plugin_wrapping.py", line 105, in __call__
    self._metadata_plugin(
  File "/Users/mrjones/Github/Projects/sheltr-ai/apps/api/.venv/lib/python3.9/site-packages/google/auth/transport/grpc.py", line 95, in __call__
    callback(self._get_authorization_headers(context), None)
  File "/Users/mrjones/Github/Projects/sheltr-ai/apps/api/.venv/lib/python3.9/site-packages/google/auth/transport/grpc.py", line 81, in _get_authorization_headers
    self._credentials.before_request(
  File "/Users/mrjones/Github/Projects/sheltr-ai/apps/api/.venv/lib/python3.9/site-packages/google/auth/credentials.py", line 175, in before_request
    self.refresh(request)
  File "/Users/mrjones/Github/Projects/sheltr-ai/apps/api/.venv/lib/python3.9/site-packages/google/oauth2/service_account.py", line 449, in refresh
    access_token, expiry, _ = _client.jwt_grant(
  File "/Users/mrjones/Github/Projects/sheltr-ai/apps/api/.venv/lib/python3.9/site-packages/google/oauth2/_client.py", line 308, in jwt_grant
    response_data = _token_endpoint_request(
  File "/Users/mrjones/Github/Projects/sheltr-ai/apps/api/.venv/lib/python3.9/site-packages/google/oauth2/_client.py", line 279, in _token_endpoint_request
    _handle_error_response(response_data, retryable_error)
  File "/Users/mrjones/Github/Projects/sheltr-ai/apps/api/.venv/lib/python3.9/site-packages/google/oauth2/_client.py", line 72, in _handle_error_response
    raise exceptions.RefreshError(
google.auth.exceptions.RefreshError: ('invalid_grant: Invalid JWT Signature.', {'error': 'invalid_grant', 'error_description': 'Invalid JWT Signature.'})
ERROR:grpc._plugin_wrapping:AuthMetadataPluginCallback "<google.auth.transport.grpc.AuthMetadataPlugin object at 0x108428ac0>" raised exception!
Traceback (most recent call last):
  File "/Users/mrjones/Github/Projects/sheltr-ai/apps/api/.venv/lib/python3.9/site-packages/grpc/_plugin_wrapping.py", line 105, in __call__
    self._metadata_plugin(
  File "/Users/mrjones/Github/Projects/sheltr-ai/apps/api/.venv/lib/python3.9/site-packages/google/auth/transport/grpc.py", line 95, in __call__
    callback(self._get_authorization_headers(context), None)
  File "/Users/mrjones/Github/Projects/sheltr-ai/apps/api/.venv/lib/python3.9/site-packages/google/auth/transport/grpc.py", line 81, in _get_authorization_headers
    self._credentials.before_request(
  File "/Users/mrjones/Github/Projects/sheltr-ai/apps/api/.venv/lib/python3.9/site-packages/google/auth/credentials.py", line 175, in before_request
    self.refresh(request)
  File "/Users/mrjones/Github/Projects/sheltr-ai/apps/api/.venv/lib/python3.9/site-packages/google/oauth2/service_account.py", line 449, in refresh
    access_token, expiry, _ = _client.jwt_grant(
  File "/Users/mrjones/Github/Projects/sheltr-ai/apps/api/.venv/lib/python3.9/site-packages/google/oauth2/_client.py", line 308, in jwt_grant
    response_data = _token_endpoint_request(
  File "/Users/mrjones/Github/Projects/sheltr-ai/apps/api/.venv/lib/python3.9/site-packages/google/oauth2/_client.py", line 279, in _token_endpoint_request
    _handle_error_response(response_data, retryable_error)
  File "/Users/mrjones/Github/Projects/sheltr-ai/apps/api/.venv/lib/python3.9/site-packages/google/oauth2/_client.py", line 72, in _handle_error_response
    raise exceptions.RefreshError(
google.auth.exceptions.RefreshError: ('invalid_grant: Invalid JWT Signature.', {'error': 'invalid_grant', 'error_description': 'Invalid JWT Signature.'})
ERROR:grpc._plugin_wrapping:AuthMetadataPluginCallback "<google.auth.transport.grpc.AuthMetadataPlugin object at 0x108428ac0>" raised exception!
Traceback (most recent call last):
  File "/Users/mrjones/Github/Projects/sheltr-ai/apps/api/.venv/lib/python3.9/site-packages/grpc/_plugin_wrapping.py", line 105, in __call__
    self._metadata_plugin(
  File "/Users/mrjones/Github/Projects/sheltr-ai/apps/api/.venv/lib/python3.9/site-packages/google/auth/transport/grpc.py", line 95, in __call__
    callback(self._get_authorization_headers(context), None)
  File "/Users/mrjones/Github/Projects/sheltr-ai/apps/api/.venv/lib/python3.9/site-packages/google/auth/transport/grpc.py", line 81, in _get_authorization_headers
    self._credentials.before_request(
  File "/Users/mrjones/Github/Projects/sheltr-ai/apps/api/.venv/lib/python3.9/site-packages/google/auth/credentials.py", line 175, in before_request
    self.refresh(request)
  File "/Users/mrjones/Github/Projects/sheltr-ai/apps/api/.venv/lib/python3.9/site-packages/google/oauth2/service_account.py", line 449, in refresh
    access_token, expiry, _ = _client.jwt_grant(
  File "/Users/mrjones/Github/Projects/sheltr-ai/apps/api/.venv/lib/python3.9/site-packages/google/oauth2/_client.py", line 308, in jwt_grant
    response_data = _token_endpoint_request(
  File "/Users/mrjones/Github/Projects/sheltr-ai/apps/api/.venv/lib/python3.9/site-packages/google/oauth2/_client.py", line 279, in _token_endpoint_request
    _handle_error_response(response_data, retryable_error)
  File "/Users/mrjones/Github/Projects/sheltr-ai/apps/api/.venv/lib/python3.9/site-packages/google/oauth2/_client.py", line 72, in _handle_error_response
    raise exceptions.RefreshError(
google.auth.exceptions.RefreshError: ('invalid_grant: Invalid JWT Signature.', {'error': 'invalid_grant', 'error_description': 'Invalid JWT Signature.'})
ERROR:grpc._plugin_wrapping:AuthMetadataPluginCallback "<google.auth.transport.grpc.AuthMetadataPlugin object at 0x108428ac0>" raised exception!
Traceback (most recent call last):
  File "/Users/mrjones/Github/Projects/sheltr-ai/apps/api/.venv/lib/python3.9/site-packages/grpc/_plugin_wrapping.py", line 105, in __call__
    self._metadata_plugin(
  File "/Users/mrjones/Github/Projects/sheltr-ai/apps/api/.venv/lib/python3.9/site-packages/google/auth/transport/grpc.py", line 95, in __call__
    callback(self._get_authorization_headers(context), None)
  File "/Users/mrjones/Github/Projects/sheltr-ai/apps/api/.venv/lib/python3.9/site-packages/google/auth/transport/grpc.py", line 81, in _get_authorization_headers
    self._credentials.before_request(
  File "/Users/mrjones/Github/Projects/sheltr-ai/apps/api/.venv/lib/python3.9/site-packages/google/auth/credentials.py", line 175, in before_request
    self.refresh(request)
  File "/Users/mrjones/Github/Projects/sheltr-ai/apps/api/.venv/lib/python3.9/site-packages/google/oauth2/service_account.py", line 449, in refresh
    access_token, expiry, _ = _client.jwt_grant(
  File "/Users/mrjones/Github/Projects/sheltr-ai/apps/api/.venv/lib/python3.9/site-packages/google/oauth2/_client.py", line 308, in jwt_grant
    response_data = _token_endpoint_request(
  File "/Users/mrjones/Github/Projects/sheltr-ai/apps/api/.venv/lib/python3.9/site-packages/google/oauth2/_client.py", line 279, in _token_endpoint_request
    _handle_error_response(response_data, retryable_error)
  File "/Users/mrjones/Github/Projects/sheltr-ai/apps/api/.venv/lib/python3.9/site-packages/google/oauth2/_client.py", line 72, in _handle_error_response
    raise exceptions.RefreshError(
google.auth.exceptions.RefreshError: ('invalid_grant: Invalid JWT Signature.', {'error': 'invalid_grant', 'error_description': 'Invalid JWT Signature.'})
ERROR:grpc._plugin_wrapping:AuthMetadataPluginCallback "<google.auth.transport.grpc.AuthMetadataPlugin object at 0x108428ac0>" raised exception!
Traceback (most recent call last):
  File "/Users/mrjones/Github/Projects/sheltr-ai/apps/api/.venv/lib/python3.9/site-packages/grpc/_plugin_wrapping.py", line 105, in __call__
    self._metadata_plugin(
  File "/Users/mrjones/Github/Projects/sheltr-ai/apps/api/.venv/lib/python3.9/site-packages/google/auth/transport/grpc.py", line 95, in __call__
    callback(self._get_authorization_headers(context), None)
  File "/Users/mrjones/Github/Projects/sheltr-ai/apps/api/.venv/lib/python3.9/site-packages/google/auth/transport/grpc.py", line 81, in _get_authorization_headers
    self._credentials.before_request(
  File "/Users/mrjones/Github/Projects/sheltr-ai/apps/api/.venv/lib/python3.9/site-packages/google/auth/credentials.py", line 175, in before_request
    self.refresh(request)
  File "/Users/mrjones/Github/Projects/sheltr-ai/apps/api/.venv/lib/python3.9/site-packages/google/oauth2/service_account.py", line 449, in refresh
    access_token, expiry, _ = _client.jwt_grant(
  File "/Users/mrjones/Github/Projects/sheltr-ai/apps/api/.venv/lib/python3.9/site-packages/google/oauth2/_client.py", line 308, in jwt_grant
    response_data = _token_endpoint_request(
  File "/Users/mrjones/Github/Projects/sheltr-ai/apps/api/.venv/lib/python3.9/site-packages/google/oauth2/_client.py", line 279, in _token_endpoint_request
    _handle_error_response(response_data, retryable_error)
  File "/Users/mrjones/Github/Projects/sheltr-ai/apps/api/.venv/lib/python3.9/site-packages/google/oauth2/_client.py", line 72, in _handle_error_response
    raise exceptions.RefreshError(
google.auth.exceptions.RefreshError: ('invalid_grant: Invalid JWT Signature.', {'error': 'invalid_grant', 'error_description': 'Invalid JWT Signature.'})
ERROR:grpc._plugin_wrapping:AuthMetadataPluginCallback "<google.auth.transport.grpc.AuthMetadataPlugin object at 0x108428ac0>" raised exception!
Traceback (most recent call last):
  File "/Users/mrjones/Github/Projects/sheltr-ai/apps/api/.venv/lib/python3.9/site-packages/grpc/_plugin_wrapping.py", line 105, in __call__
    self._metadata_plugin(
  File "/Users/mrjones/Github/Projects/sheltr-ai/apps/api/.venv/lib/python3.9/site-packages/google/auth/transport/grpc.py", line 95, in __call__
    callback(self._get_authorization_headers(context), None)
  File "/Users/mrjones/Github/Projects/sheltr-ai/apps/api/.venv/lib/python3.9/site-packages/google/auth/transport/grpc.py", line 81, in _get_authorization_headers
    self._credentials.before_request(
  File "/Users/mrjones/Github/Projects/sheltr-ai/apps/api/.venv/lib/python3.9/site-packages/google/auth/credentials.py", line 175, in before_request
    self.refresh(request)
  File "/Users/mrjones/Github/Projects/sheltr-ai/apps/api/.venv/lib/python3.9/site-packages/google/oauth2/service_account.py", line 449, in refresh
    access_token, expiry, _ = _client.jwt_grant(
  File "/Users/mrjones/Github/Projects/sheltr-ai/apps/api/.venv/lib/python3.9/site-packages/google/oauth2/_client.py", line 308, in jwt_grant
    response_data = _token_endpoint_request(
  File "/Users/mrjones/Github/Projects/sheltr-ai/apps/api/.venv/lib/python3.9/site-packages/google/oauth2/_client.py", line 279, in _token_endpoint_request
    _handle_error_response(response_data, retryable_error)
  File "/Users/mrjones/Github/Projects/sheltr-ai/apps/api/.venv/lib/python3.9/site-packages/google/oauth2/_client.py", line 72, in _handle_error_response
    raise exceptions.RefreshError(
google.auth.exceptions.RefreshError: ('invalid_grant: Invalid JWT Signature.', {'error': 'invalid_grant', 'error_description': 'Invalid JWT Signature.'})
ERROR:grpc._plugin_wrapping:AuthMetadataPluginCallback "<google.auth.transport.grpc.AuthMetadataPlugin object at 0x108428ac0>" raised exception!
Traceback (most recent call last):
  File "/Users/mrjones/Github/Projects/sheltr-ai/apps/api/.venv/lib/python3.9/site-packages/grpc/_plugin_wrapping.py", line 105, in __call__
    self._metadata_plugin(
  File "/Users/mrjones/Github/Projects/sheltr-ai/apps/api/.venv/lib/python3.9/site-packages/google/auth/transport/grpc.py", line 95, in __call__
    callback(self._get_authorization_headers(context), None)
  File "/Users/mrjones/Github/Projects/sheltr-ai/apps/api/.venv/lib/python3.9/site-packages/google/auth/transport/grpc.py", line 81, in _get_authorization_headers
    self._credentials.before_request(
  File "/Users/mrjones/Github/Projects/sheltr-ai/apps/api/.venv/lib/python3.9/site-packages/google/auth/credentials.py", line 175, in before_request
    self.refresh(request)
  File "/Users/mrjones/Github/Projects/sheltr-ai/apps/api/.venv/lib/python3.9/site-packages/google/oauth2/service_account.py", line 449, in refresh
    access_token, expiry, _ = _client.jwt_grant(
  File "/Users/mrjones/Github/Projects/sheltr-ai/apps/api/.venv/lib/python3.9/site-packages/google/oauth2/_client.py", line 308, in jwt_grant
    response_data = _token_endpoint_request(
  File "/Users/mrjones/Github/Projects/sheltr-ai/apps/api/.venv/lib/python3.9/site-packages/google/oauth2/_client.py", line 279, in _token_endpoint_request
    _handle_error_response(response_data, retryable_error)
  File "/Users/mrjones/Github/Projects/sheltr-ai/apps/api/.venv/lib/python3.9/site-packages/google/oauth2/_client.py", line 72, in _handle_error_response
    raise exceptions.RefreshError(
google.auth.exceptions.RefreshError: ('invalid_grant: Invalid JWT Signature.', {'error': 'invalid_grant', 'error_description': 'Invalid JWT Signature.'})
ERROR:grpc._plugin_wrapping:AuthMetadataPluginCallback "<google.auth.transport.grpc.AuthMetadataPlugin object at 0x108428ac0>" raised exception!
Traceback (most recent call last):
  File "/Users/mrjones/Github/Projects/sheltr-ai/apps/api/.venv/lib/python3.9/site-packages/grpc/_plugin_wrapping.py", line 105, in __call__
    self._metadata_plugin(
  File "/Users/mrjones/Github/Projects/sheltr-ai/apps/api/.venv/lib/python3.9/site-packages/google/auth/transport/grpc.py", line 95, in __call__
    callback(self._get_authorization_headers(context), None)
  File "/Users/mrjones/Github/Projects/sheltr-ai/apps/api/.venv/lib/python3.9/site-packages/google/auth/transport/grpc.py", line 81, in _get_authorization_headers
    self._credentials.before_request(
  File "/Users/mrjones/Github/Projects/sheltr-ai/apps/api/.venv/lib/python3.9/site-packages/google/auth/credentials.py", line 175, in before_request
    self.refresh(request)
  File "/Users/mrjones/Github/Projects/sheltr-ai/apps/api/.venv/lib/python3.9/site-packages/google/oauth2/service_account.py", line 449, in refresh
    access_token, expiry, _ = _client.jwt_grant(
  File "/Users/mrjones/Github/Projects/sheltr-ai/apps/api/.venv/lib/python3.9/site-packages/google/oauth2/_client.py", line 308, in jwt_grant
    response_data = _token_endpoint_request(
  File "/Users/mrjones/Github/Projects/sheltr-ai/apps/api/.venv/lib/python3.9/site-packages/google/oauth2/_client.py", line 279, in _token_endpoint_request
    _handle_error_response(response_data, retryable_error)
  File "/Users/mrjones/Github/Projects/sheltr-ai/apps/api/.venv/lib/python3.9/site-packages/google/oauth2/_client.py", line 72, in _handle_error_response
    raise exceptions.RefreshError(
google.auth.exceptions.RefreshError: ('invalid_grant: Invalid JWT Signature.', {'error': 'invalid_grant', 'error_description': 'Invalid JWT Signature.'})
ERROR:grpc._plugin_wrapping:AuthMetadataPluginCallback "<google.auth.transport.grpc.AuthMetadataPlugin object at 0x108428ac0>" raised exception!
Traceback (most recent call last):
  File "/Users/mrjones/Github/Projects/sheltr-ai/apps/api/.venv/lib/python3.9/site-packages/grpc/_plugin_wrapping.py", line 105, in __call__
    self._metadata_plugin(
  File "/Users/mrjones/Github/Projects/sheltr-ai/apps/api/.venv/lib/python3.9/site-packages/google/auth/transport/grpc.py", line 95, in __call__
    callback(self._get_authorization_headers(context), None)
  File "/Users/mrjones/Github/Projects/sheltr-ai/apps/api/.venv/lib/python3.9/site-packages/google/auth/transport/grpc.py", line 81, in _get_authorization_headers
    self._credentials.before_request(
  File "/Users/mrjones/Github/Projects/sheltr-ai/apps/api/.venv/lib/python3.9/site-packages/google/auth/credentials.py", line 175, in before_request
    self.refresh(request)
  File "/Users/mrjones/Github/Projects/sheltr-ai/apps/api/.venv/lib/python3.9/site-packages/google/oauth2/service_account.py", line 449, in refresh
    access_token, expiry, _ = _client.jwt_grant(
  File "/Users/mrjones/Github/Projects/sheltr-ai/apps/api/.venv/lib/python3.9/site-packages/google/oauth2/_client.py", line 308, in jwt_grant
    response_data = _token_endpoint_request(
  File "/Users/mrjones/Github/Projects/sheltr-ai/apps/api/.venv/lib/python3.9/site-packages/google/oauth2/_client.py", line 279, in _token_endpoint_request
    _handle_error_response(response_data, retryable_error)
  File "/Users/mrjones/Github/Projects/sheltr-ai/apps/api/.venv/lib/python3.9/site-packages/google/oauth2/_client.py", line 72, in _handle_error_response
    raise exceptions.RefreshError(
google.auth.exceptions.RefreshError: ('invalid_grant: Invalid JWT Signature.', {'error': 'invalid_grant', 'error_description': 'Invalid JWT Signature.'})
ERROR:grpc._plugin_wrapping:AuthMetadataPluginCallback "<google.auth.transport.grpc.AuthMetadataPlugin object at 0x108428ac0>" raised exception!
Traceback (most recent call last):
  File "/Users/mrjones/Github/Projects/sheltr-ai/apps/api/.venv/lib/python3.9/site-packages/grpc/_plugin_wrapping.py", line 105, in __call__
    self._metadata_plugin(
  File "/Users/mrjones/Github/Projects/sheltr-ai/apps/api/.venv/lib/python3.9/site-packages/google/auth/transport/grpc.py", line 95, in __call__
    callback(self._get_authorization_headers(context), None)
  File "/Users/mrjones/Github/Projects/sheltr-ai/apps/api/.venv/lib/python3.9/site-packages/google/auth/transport/grpc.py", line 81, in _get_authorization_headers
    self._credentials.before_request(
  File "/Users/mrjones/Github/Projects/sheltr-ai/apps/api/.venv/lib/python3.9/site-packages/google/auth/credentials.py", line 175, in before_request
    self.refresh(request)
  File "/Users/mrjones/Github/Projects/sheltr-ai/apps/api/.venv/lib/python3.9/site-packages/google/oauth2/service_account.py", line 449, in refresh
    access_token, expiry, _ = _client.jwt_grant(
  File "/Users/mrjones/Github/Projects/sheltr-ai/apps/api/.venv/lib/python3.9/site-packages/google/oauth2/_client.py", line 308, in jwt_grant
    response_data = _token_endpoint_request(
  File "/Users/mrjones/Github/Projects/sheltr-ai/apps/api/.venv/lib/python3.9/site-packages/google/oauth2/_client.py", line 279, in _token_endpoint_request
    _handle_error_response(response_data, retryable_error)
  File "/Users/mrjones/Github/Projects/sheltr-ai/apps/api/.venv/lib/python3.9/site-packages/google/oauth2/_client.py", line 72, in _handle_error_response
    raise exceptions.RefreshError(
google.auth.exceptions.RefreshError: ('invalid_grant: Invalid JWT Signature.', {'error': 'invalid_grant', 'error_description': 'Invalid JWT Signature.'})
ERROR:grpc._plugin_wrapping:AuthMetadataPluginCallback "<google.auth.transport.grpc.AuthMetadataPlugin object at 0x108428ac0>" raised exception!
Traceback (most recent call last):
  File "/Users/mrjones/Github/Projects/sheltr-ai/apps/api/.venv/lib/python3.9/site-packages/grpc/_plugin_wrapping.py", line 105, in __call__
    self._metadata_plugin(
  File "/Users/mrjones/Github/Projects/sheltr-ai/apps/api/.venv/lib/python3.9/site-packages/google/auth/transport/grpc.py", line 95, in __call__
    callback(self._get_authorization_headers(context), None)
  File "/Users/mrjones/Github/Projects/sheltr-ai/apps/api/.venv/lib/python3.9/site-packages/google/auth/transport/grpc.py", line 81, in _get_authorization_headers
    self._credentials.before_request(
  File "/Users/mrjones/Github/Projects/sheltr-ai/apps/api/.venv/lib/python3.9/site-packages/google/auth/credentials.py", line 175, in before_request
    self.refresh(request)
  File "/Users/mrjones/Github/Projects/sheltr-ai/apps/api/.venv/lib/python3.9/site-packages/google/oauth2/service_account.py", line 449, in refresh
    access_token, expiry, _ = _client.jwt_grant(
  File "/Users/mrjones/Github/Projects/sheltr-ai/apps/api/.venv/lib/python3.9/site-packages/google/oauth2/_client.py", line 308, in jwt_grant
    response_data = _token_endpoint_request(
  File "/Users/mrjones/Github/Projects/sheltr-ai/apps/api/.venv/lib/python3.9/site-packages/google/oauth2/_client.py", line 279, in _token_endpoint_request
    _handle_error_response(response_data, retryable_error)
  File "/Users/mrjones/Github/Projects/sheltr-ai/apps/api/.venv/lib/python3.9/site-packages/google/oauth2/_client.py", line 72, in _handle_error_response
    raise exceptions.RefreshError(
google.auth.exceptions.RefreshError: ('invalid_grant: Invalid JWT Signature.', {'error': 'invalid_grant', 'error_description': 'Invalid JWT Signature.'})
ERROR:grpc._plugin_wrapping:AuthMetadataPluginCallback "<google.auth.transport.grpc.AuthMetadataPlugin object at 0x108428ac0>" raised exception!
Traceback (most recent call last):
  File "/Users/mrjones/Github/Projects/sheltr-ai/apps/api/.venv/lib/python3.9/site-packages/grpc/_plugin_wrapping.py", line 105, in __call__
    self._metadata_plugin(
  File "/Users/mrjones/Github/Projects/sheltr-ai/apps/api/.venv/lib/python3.9/site-packages/google/auth/transport/grpc.py", line 95, in __call__
    callback(self._get_authorization_headers(context), None)
  File "/Users/mrjones/Github/Projects/sheltr-ai/apps/api/.venv/lib/python3.9/site-packages/google/auth/transport/grpc.py", line 81, in _get_authorization_headers
    self._credentials.before_request(
  File "/Users/mrjones/Github/Projects/sheltr-ai/apps/api/.venv/lib/python3.9/site-packages/google/auth/credentials.py", line 175, in before_request
    self.refresh(request)
  File "/Users/mrjones/Github/Projects/sheltr-ai/apps/api/.venv/lib/python3.9/site-packages/google/oauth2/service_account.py", line 449, in refresh
    access_token, expiry, _ = _client.jwt_grant(
  File "/Users/mrjones/Github/Projects/sheltr-ai/apps/api/.venv/lib/python3.9/site-packages/google/oauth2/_client.py", line 308, in jwt_grant
    response_data = _token_endpoint_request(
  File "/Users/mrjones/Github/Projects/sheltr-ai/apps/api/.venv/lib/python3.9/site-packages/google/oauth2/_client.py", line 279, in _token_endpoint_request
    _handle_error_response(response_data, retryable_error)
  File "/Users/mrjones/Github/Projects/sheltr-ai/apps/api/.venv/lib/python3.9/site-packages/google/oauth2/_client.py", line 72, in _handle_error_response
    raise exceptions.RefreshError(
google.auth.exceptions.RefreshError: ('invalid_grant: Invalid JWT Signature.', {'error': 'invalid_grant', 'error_description': 'Invalid JWT Signature.'})
ERROR:grpc._plugin_wrapping:AuthMetadataPluginCallback "<google.auth.transport.grpc.AuthMetadataPlugin object at 0x108428ac0>" raised exception!
Traceback (most recent call last):
  File "/Users/mrjones/Github/Projects/sheltr-ai/apps/api/.venv/lib/python3.9/site-packages/grpc/_plugin_wrapping.py", line 105, in __call__
    self._metadata_plugin(
  File "/Users/mrjones/Github/Projects/sheltr-ai/apps/api/.venv/lib/python3.9/site-packages/google/auth/transport/grpc.py", line 95, in __call__
    callback(self._get_authorization_headers(context), None)
  File "/Users/mrjones/Github/Projects/sheltr-ai/apps/api/.venv/lib/python3.9/site-packages/google/auth/transport/grpc.py", line 81, in _get_authorization_headers
    self._credentials.before_request(
  File "/Users/mrjones/Github/Projects/sheltr-ai/apps/api/.venv/lib/python3.9/site-packages/google/auth/credentials.py", line 175, in before_request
    self.refresh(request)
  File "/Users/mrjones/Github/Projects/sheltr-ai/apps/api/.venv/lib/python3.9/site-packages/google/oauth2/service_account.py", line 449, in refresh
    access_token, expiry, _ = _client.jwt_grant(
  File "/Users/mrjones/Github/Projects/sheltr-ai/apps/api/.venv/lib/python3.9/site-packages/google/oauth2/_client.py", line 308, in jwt_grant
    response_data = _token_endpoint_request(
  File "/Users/mrjones/Github/Projects/sheltr-ai/apps/api/.venv/lib/python3.9/site-packages/google/oauth2/_client.py", line 279, in _token_endpoint_request
    _handle_error_response(response_data, retryable_error)
  File "/Users/mrjones/Github/Projects/sheltr-ai/apps/api/.venv/lib/python3.9/site-packages/google/oauth2/_client.py", line 72, in _handle_error_response
    raise exceptions.RefreshError(
google.auth.exceptions.RefreshError: ('invalid_grant: Invalid JWT Signature.', {'error': 'invalid_grant', 'error_description': 'Invalid JWT Signature.'})
ERROR:grpc._plugin_wrapping:AuthMetadataPluginCallback "<google.auth.transport.grpc.AuthMetadataPlugin object at 0x108428ac0>" raised exception!
Traceback (most recent call last):
  File "/Users/mrjones/Github/Projects/sheltr-ai/apps/api/.venv/lib/python3.9/site-packages/grpc/_plugin_wrapping.py", line 105, in __call__
    self._metadata_plugin(
  File "/Users/mrjones/Github/Projects/sheltr-ai/apps/api/.venv/lib/python3.9/site-packages/google/auth/transport/grpc.py", line 95, in __call__
    callback(self._get_authorization_headers(context), None)
  File "/Users/mrjones/Github/Projects/sheltr-ai/apps/api/.venv/lib/python3.9/site-packages/google/auth/transport/grpc.py", line 81, in _get_authorization_headers
    self._credentials.before_request(
  File "/Users/mrjones/Github/Projects/sheltr-ai/apps/api/.venv/lib/python3.9/site-packages/google/auth/credentials.py", line 175, in before_request
    self.refresh(request)
  File "/Users/mrjones/Github/Projects/sheltr-ai/apps/api/.venv/lib/python3.9/site-packages/google/oauth2/service_account.py", line 449, in refresh
    access_token, expiry, _ = _client.jwt_grant(
  File "/Users/mrjones/Github/Projects/sheltr-ai/apps/api/.venv/lib/python3.9/site-packages/google/oauth2/_client.py", line 308, in jwt_grant
    response_data = _token_endpoint_request(
  File "/Users/mrjones/Github/Projects/sheltr-ai/apps/api/.venv/lib/python3.9/site-packages/google/oauth2/_client.py", line 279, in _token_endpoint_request
    _handle_error_response(response_data, retryable_error)
  File "/Users/mrjones/Github/Projects/sheltr-ai/apps/api/.venv/lib/python3.9/site-packages/google/oauth2/_client.py", line 72, in _handle_error_response
    raise exceptions.RefreshError(
google.auth.exceptions.RefreshError: ('invalid_grant: Invalid JWT Signature.', {'error': 'invalid_grant', 'error_description': 'Invalid JWT Signature.'})
ERROR:grpc._plugin_wrapping:AuthMetadataPluginCallback "<google.auth.transport.grpc.AuthMetadataPlugin object at 0x108428ac0>" raised exception!
Traceback (most recent call last):
  File "/Users/mrjones/Github/Projects/sheltr-ai/apps/api/.venv/lib/python3.9/site-packages/grpc/_plugin_wrapping.py", line 105, in __call__
    self._metadata_plugin(
  File "/Users/mrjones/Github/Projects/sheltr-ai/apps/api/.venv/lib/python3.9/site-packages/google/auth/transport/grpc.py", line 95, in __call__
    callback(self._get_authorization_headers(context), None)
  File "/Users/mrjones/Github/Projects/sheltr-ai/apps/api/.venv/lib/python3.9/site-packages/google/auth/transport/grpc.py", line 81, in _get_authorization_headers
    self._credentials.before_request(
  File "/Users/mrjones/Github/Projects/sheltr-ai/apps/api/.venv/lib/python3.9/site-packages/google/auth/credentials.py", line 175, in before_request
    self.refresh(request)
  File "/Users/mrjones/Github/Projects/sheltr-ai/apps/api/.venv/lib/python3.9/site-packages/google/oauth2/service_account.py", line 449, in refresh
    access_token, expiry, _ = _client.jwt_grant(
  File "/Users/mrjones/Github/Projects/sheltr-ai/apps/api/.venv/lib/python3.9/site-packages/google/oauth2/_client.py", line 308, in jwt_grant
    response_data = _token_endpoint_request(
  File "/Users/mrjones/Github/Projects/sheltr-ai/apps/api/.venv/lib/python3.9/site-packages/google/oauth2/_client.py", line 279, in _token_endpoint_request
    _handle_error_response(response_data, retryable_error)
  File "/Users/mrjones/Github/Projects/sheltr-ai/apps/api/.venv/lib/python3.9/site-packages/google/oauth2/_client.py", line 72, in _handle_error_response
    raise exceptions.RefreshError(
google.auth.exceptions.RefreshError: ('invalid_grant: Invalid JWT Signature.', {'error': 'invalid_grant', 'error_description': 'Invalid JWT Signature.'})
ERROR:grpc._plugin_wrapping:AuthMetadataPluginCallback "<google.auth.transport.grpc.AuthMetadataPlugin object at 0x108428ac0>" raised exception!
Traceback (most recent call last):
  File "/Users/mrjones/Github/Projects/sheltr-ai/apps/api/.venv/lib/python3.9/site-packages/grpc/_plugin_wrapping.py", line 105, in __call__
    self._metadata_plugin(
  File "/Users/mrjones/Github/Projects/sheltr-ai/apps/api/.venv/lib/python3.9/site-packages/google/auth/transport/grpc.py", line 95, in __call__
    callback(self._get_authorization_headers(context), None)
  File "/Users/mrjones/Github/Projects/sheltr-ai/apps/api/.venv/lib/python3.9/site-packages/google/auth/transport/grpc.py", line 81, in _get_authorization_headers
    self._credentials.before_request(
  File "/Users/mrjones/Github/Projects/sheltr-ai/apps/api/.venv/lib/python3.9/site-packages/google/auth/credentials.py", line 175, in before_request
    self.refresh(request)
  File "/Users/mrjones/Github/Projects/sheltr-ai/apps/api/.venv/lib/python3.9/site-packages/google/oauth2/service_account.py", line 449, in refresh
    access_token, expiry, _ = _client.jwt_grant(
  File "/Users/mrjones/Github/Projects/sheltr-ai/apps/api/.venv/lib/python3.9/site-packages/google/oauth2/_client.py", line 308, in jwt_grant
    response_data = _token_endpoint_request(
  File "/Users/mrjones/Github/Projects/sheltr-ai/apps/api/.venv/lib/python3.9/site-packages/google/oauth2/_client.py", line 279, in _token_endpoint_request
    _handle_error_response(response_data, retryable_error)
  File "/Users/mrjones/Github/Projects/sheltr-ai/apps/api/.venv/lib/python3.9/site-packages/google/oauth2/_client.py", line 72, in _handle_error_response
    raise exceptions.RefreshError(
google.auth.exceptions.RefreshError: ('invalid_grant: Invalid JWT Signature.', {'error': 'invalid_grant', 'error_description': 'Invalid JWT Signature.'})
ERROR:grpc._plugin_wrapping:AuthMetadataPluginCallback "<google.auth.transport.grpc.AuthMetadataPlugin object at 0x108428ac0>" raised exception!
Traceback (most recent call last):
  File "/Users/mrjones/Github/Projects/sheltr-ai/apps/api/.venv/lib/python3.9/site-packages/grpc/_plugin_wrapping.py", line 105, in __call__
    self._metadata_plugin(
  File "/Users/mrjones/Github/Projects/sheltr-ai/apps/api/.venv/lib/python3.9/site-packages/google/auth/transport/grpc.py", line 95, in __call__
    callback(self._get_authorization_headers(context), None)
  File "/Users/mrjones/Github/Projects/sheltr-ai/apps/api/.venv/lib/python3.9/site-packages/google/auth/transport/grpc.py", line 81, in _get_authorization_headers
    self._credentials.before_request(
  File "/Users/mrjones/Github/Projects/sheltr-ai/apps/api/.venv/lib/python3.9/site-packages/google/auth/credentials.py", line 175, in before_request
    self.refresh(request)
  File "/Users/mrjones/Github/Projects/sheltr-ai/apps/api/.venv/lib/python3.9/site-packages/google/oauth2/service_account.py", line 449, in refresh
    access_token, expiry, _ = _client.jwt_grant(
  File "/Users/mrjones/Github/Projects/sheltr-ai/apps/api/.venv/lib/python3.9/site-packages/google/oauth2/_client.py", line 308, in jwt_grant
    response_data = _token_endpoint_request(
  File "/Users/mrjones/Github/Projects/sheltr-ai/apps/api/.venv/lib/python3.9/site-packages/google/oauth2/_client.py", line 279, in _token_endpoint_request
    _handle_error_response(response_data, retryable_error)
  File "/Users/mrjones/Github/Projects/sheltr-ai/apps/api/.venv/lib/python3.9/site-packages/google/oauth2/_client.py", line 72, in _handle_error_response
    raise exceptions.RefreshError(
google.auth.exceptions.RefreshError: ('invalid_grant: Invalid JWT Signature.', {'error': 'invalid_grant', 'error_description': 'Invalid JWT Signature.'})
ERROR:services.analytics_service:Error getting user metrics: Timeout of 300.0s exceeded, last exception: 503 Getting metadata from plugin failed with error: ('invalid_grant: Invalid JWT Signature.', {'error': 'invalid_grant', 'error_description': 'Invalid JWT Signature.'})
ERROR:grpc._plugin_wrapping:AuthMetadataPluginCallback "<google.auth.transport.grpc.AuthMetadataPlugin object at 0x108428ac0>" raised exception!
Traceback (most recent call last):
  File "/Users/mrjones/Github/Projects/sheltr-ai/apps/api/.venv/lib/python3.9/site-packages/grpc/_plugin_wrapping.py", line 105, in __call__
    self._metadata_plugin(
  File "/Users/mrjones/Github/Projects/sheltr-ai/apps/api/.venv/lib/python3.9/site-packages/google/auth/transport/grpc.py", line 95, in __call__
    callback(self._get_authorization_headers(context), None)
  File "/Users/mrjones/Github/Projects/sheltr-ai/apps/api/.venv/lib/python3.9/site-packages/google/auth/transport/grpc.py", line 81, in _get_authorization_headers
    self._credentials.before_request(
  File "/Users/mrjones/Github/Projects/sheltr-ai/apps/api/.venv/lib/python3.9/site-packages/google/auth/credentials.py", line 175, in before_request
    self.refresh(request)
  File "/Users/mrjones/Github/Projects/sheltr-ai/apps/api/.venv/lib/python3.9/site-packages/google/oauth2/service_account.py", line 449, in refresh
    access_token, expiry, _ = _client.jwt_grant(
  File "/Users/mrjones/Github/Projects/sheltr-ai/apps/api/.venv/lib/python3.9/site-packages/google/oauth2/_client.py", line 308, in jwt_grant
    response_data = _token_endpoint_request(
  File "/Users/mrjones/Github/Projects/sheltr-ai/apps/api/.venv/lib/python3.9/site-packages/google/oauth2/_client.py", line 279, in _token_endpoint_request
    _handle_error_response(response_data, retryable_error)
  File "/Users/mrjones/Github/Projects/sheltr-ai/apps/api/.venv/lib/python3.9/site-packages/google/oauth2/_client.py", line 72, in _handle_error_response
    raise exceptions.RefreshError(
google.auth.exceptions.RefreshError: ('invalid_grant: Invalid JWT Signature.', {'error': 'invalid_grant', 'error_description': 'Invalid JWT Signature.'})
ERROR:grpc._plugin_wrapping:AuthMetadataPluginCallback "<google.auth.transport.grpc.AuthMetadataPlugin object at 0x108428ac0>" raised exception!
Traceback (most recent call last):
  File "/Users/mrjones/Github/Projects/sheltr-ai/apps/api/.venv/lib/python3.9/site-packages/grpc/_plugin_wrapping.py", line 105, in __call__
    self._metadata_plugin(
  File "/Users/mrjones/Github/Projects/sheltr-ai/apps/api/.venv/lib/python3.9/site-packages/google/auth/transport/grpc.py", line 95, in __call__
    callback(self._get_authorization_headers(context), None)
  File "/Users/mrjones/Github/Projects/sheltr-ai/apps/api/.venv/lib/python3.9/site-packages/google/auth/transport/grpc.py", line 81, in _get_authorization_headers
    self._credentials.before_request(
  File "/Users/mrjones/Github/Projects/sheltr-ai/apps/api/.venv/lib/python3.9/site-packages/google/auth/credentials.py", line 175, in before_request
    self.refresh(request)
  File "/Users/mrjones/Github/Projects/sheltr-ai/apps/api/.venv/lib/python3.9/site-packages/google/oauth2/service_account.py", line 449, in refresh
    access_token, expiry, _ = _client.jwt_grant(
  File "/Users/mrjones/Github/Projects/sheltr-ai/apps/api/.venv/lib/python3.9/site-packages/google/oauth2/_client.py", line 308, in jwt_grant
    response_data = _token_endpoint_request(
  File "/Users/mrjones/Github/Projects/sheltr-ai/apps/api/.venv/lib/python3.9/site-packages/google/oauth2/_client.py", line 279, in _token_endpoint_request
    _handle_error_response(response_data, retryable_error)
  File "/Users/mrjones/Github/Projects/sheltr-ai/apps/api/.venv/lib/python3.9/site-packages/google/oauth2/_client.py", line 72, in _handle_error_response
    raise exceptions.RefreshError(
google.auth.exceptions.RefreshError: ('invalid_grant: Invalid JWT Signature.', {'error': 'invalid_grant', 'error_description': 'Invalid JWT Signature.'})
ERROR:grpc._plugin_wrapping:AuthMetadataPluginCallback "<google.auth.transport.grpc.AuthMetadataPlugin object at 0x108428ac0>" raised exception!
Traceback (most recent call last):
  File "/Users/mrjones/Github/Projects/sheltr-ai/apps/api/.venv/lib/python3.9/site-packages/grpc/_plugin_wrapping.py", line 105, in __call__
    self._metadata_plugin(
  File "/Users/mrjones/Github/Projects/sheltr-ai/apps/api/.venv/lib/python3.9/site-packages/google/auth/transport/grpc.py", line 95, in __call__
    callback(self._get_authorization_headers(context), None)
  File "/Users/mrjones/Github/Projects/sheltr-ai/apps/api/.venv/lib/python3.9/site-packages/google/auth/transport/grpc.py", line 81, in _get_authorization_headers
    self._credentials.before_request(
  File "/Users/mrjones/Github/Projects/sheltr-ai/apps/api/.venv/lib/python3.9/site-packages/google/auth/credentials.py", line 175, in before_request
    self.refresh(request)
  File "/Users/mrjones/Github/Projects/sheltr-ai/apps/api/.venv/lib/python3.9/site-packages/google/oauth2/service_account.py", line 449, in refresh
    access_token, expiry, _ = _client.jwt_grant(
  File "/Users/mrjones/Github/Projects/sheltr-ai/apps/api/.venv/lib/python3.9/site-packages/google/oauth2/_client.py", line 308, in jwt_grant
    response_data = _token_endpoint_request(
  File "/Users/mrjones/Github/Projects/sheltr-ai/apps/api/.venv/lib/python3.9/site-packages/google/oauth2/_client.py", line 279, in _token_endpoint_request
    _handle_error_response(response_data, retryable_error)
  File "/Users/mrjones/Github/Projects/sheltr-ai/apps/api/.venv/lib/python3.9/site-packages/google/oauth2/_client.py", line 72, in _handle_error_response
    raise exceptions.RefreshError(
google.auth.exceptions.RefreshError: ('invalid_grant: Invalid JWT Signature.', {'error': 'invalid_grant', 'error_description': 'Invalid JWT Signature.'})
ERROR:grpc._plugin_wrapping:AuthMetadataPluginCallback "<google.auth.transport.grpc.AuthMetadataPlugin object at 0x108428ac0>" raised exception!
Traceback (most recent call last):
  File "/Users/mrjones/Github/Projects/sheltr-ai/apps/api/.venv/lib/python3.9/site-packages/grpc/_plugin_wrapping.py", line 105, in __call__
    self._metadata_plugin(
  File "/Users/mrjones/Github/Projects/sheltr-ai/apps/api/.venv/lib/python3.9/site-packages/google/auth/transport/grpc.py", line 95, in __call__
    callback(self._get_authorization_headers(context), None)
  File "/Users/mrjones/Github/Projects/sheltr-ai/apps/api/.venv/lib/python3.9/site-packages/google/auth/transport/grpc.py", line 81, in _get_authorization_headers
    self._credentials.before_request(
  File "/Users/mrjones/Github/Projects/sheltr-ai/apps/api/.venv/lib/python3.9/site-packages/google/auth/credentials.py", line 175, in before_request
    self.refresh(request)
  File "/Users/mrjones/Github/Projects/sheltr-ai/apps/api/.venv/lib/python3.9/site-packages/google/oauth2/service_account.py", line 449, in refresh
    access_token, expiry, _ = _client.jwt_grant(
  File "/Users/mrjones/Github/Projects/sheltr-ai/apps/api/.venv/lib/python3.9/site-packages/google/oauth2/_client.py", line 308, in jwt_grant
    response_data = _token_endpoint_request(
  File "/Users/mrjones/Github/Projects/sheltr-ai/apps/api/.venv/lib/python3.9/site-packages/google/oauth2/_client.py", line 279, in _token_endpoint_request
    _handle_error_response(response_data, retryable_error)
  File "/Users/mrjones/Github/Projects/sheltr-ai/apps/api/.venv/lib/python3.9/site-packages/google/oauth2/_client.py", line 72, in _handle_error_response
    raise exceptions.RefreshError(
google.auth.exceptions.RefreshError: ('invalid_grant: Invalid JWT Signature.', {'error': 'invalid_grant', 'error_description': 'Invalid JWT Signature.'})
ERROR:grpc._plugin_wrapping:AuthMetadataPluginCallback "<google.auth.transport.grpc.AuthMetadataPlugin object at 0x108428ac0>" raised exception!
Traceback (most recent call last):
  File "/Users/mrjones/Github/Projects/sheltr-ai/apps/api/.venv/lib/python3.9/site-packages/grpc/_plugin_wrapping.py", line 105, in __call__
    self._metadata_plugin(
  File "/Users/mrjones/Github/Projects/sheltr-ai/apps/api/.venv/lib/python3.9/site-packages/google/auth/transport/grpc.py", line 95, in __call__
    callback(self._get_authorization_headers(context), None)
  File "/Users/mrjones/Github/Projects/sheltr-ai/apps/api/.venv/lib/python3.9/site-packages/google/auth/transport/grpc.py", line 81, in _get_authorization_headers
    self._credentials.before_request(
  File "/Users/mrjones/Github/Projects/sheltr-ai/apps/api/.venv/lib/python3.9/site-packages/google/auth/credentials.py", line 175, in before_request
    self.refresh(request)
  File "/Users/mrjones/Github/Projects/sheltr-ai/apps/api/.venv/lib/python3.9/site-packages/google/oauth2/service_account.py", line 449, in refresh
    access_token, expiry, _ = _client.jwt_grant(
  File "/Users/mrjones/Github/Projects/sheltr-ai/apps/api/.venv/lib/python3.9/site-packages/google/oauth2/_client.py", line 308, in jwt_grant
    response_data = _token_endpoint_request(
  File "/Users/mrjones/Github/Projects/sheltr-ai/apps/api/.venv/lib/python3.9/site-packages/google/oauth2/_client.py", line 279, in _token_endpoint_request
    _handle_error_response(response_data, retryable_error)
  File "/Users/mrjones/Github/Projects/sheltr-ai/apps/api/.venv/lib/python3.9/site-packages/google/oauth2/_client.py", line 72, in _handle_error_response
    raise exceptions.RefreshError(
google.auth.exceptions.RefreshError: ('invalid_grant: Invalid JWT Signature.', {'error': 'invalid_grant', 'error_description': 'Invalid JWT Signature.'})
ERROR:grpc._plugin_wrapping:AuthMetadataPluginCallback "<google.auth.transport.grpc.AuthMetadataPlugin object at 0x108428ac0>" raised exception!
Traceback (most recent call last):
  File "/Users/mrjones/Github/Projects/sheltr-ai/apps/api/.venv/lib/python3.9/site-packages/grpc/_plugin_wrapping.py", line 105, in __call__
    self._metadata_plugin(
  File "/Users/mrjones/Github/Projects/sheltr-ai/apps/api/.venv/lib/python3.9/site-packages/google/auth/transport/grpc.py", line 95, in __call__
    callback(self._get_authorization_headers(context), None)
  File "/Users/mrjones/Github/Projects/sheltr-ai/apps/api/.venv/lib/python3.9/site-packages/google/auth/transport/grpc.py", line 81, in _get_authorization_headers
    self._credentials.before_request(
  File "/Users/mrjones/Github/Projects/sheltr-ai/apps/api/.venv/lib/python3.9/site-packages/google/auth/credentials.py", line 175, in before_request
    self.refresh(request)
  File "/Users/mrjones/Github/Projects/sheltr-ai/apps/api/.venv/lib/python3.9/site-packages/google/oauth2/service_account.py", line 449, in refresh
    access_token, expiry, _ = _client.jwt_grant(
  File "/Users/mrjones/Github/Projects/sheltr-ai/apps/api/.venv/lib/python3.9/site-packages/google/oauth2/_client.py", line 308, in jwt_grant
    response_data = _token_endpoint_request(
  File "/Users/mrjones/Github/Projects/sheltr-ai/apps/api/.venv/lib/python3.9/site-packages/google/oauth2/_client.py", line 279, in _token_endpoint_request
    _handle_error_response(response_data, retryable_error)
  File "/Users/mrjones/Github/Projects/sheltr-ai/apps/api/.venv/lib/python3.9/site-packages/google/oauth2/_client.py", line 72, in _handle_error_response
    raise exceptions.RefreshError(
google.auth.exceptions.RefreshError: ('invalid_grant: Invalid JWT Signature.', {'error': 'invalid_grant', 'error_description': 'Invalid JWT Signature.'})
ERROR:grpc._plugin_wrapping:AuthMetadataPluginCallback "<google.auth.transport.grpc.AuthMetadataPlugin object at 0x108428ac0>" raised exception!
Traceback (most recent call last):
  File "/Users/mrjones/Github/Projects/sheltr-ai/apps/api/.venv/lib/python3.9/site-packages/grpc/_plugin_wrapping.py", line 105, in __call__
    self._metadata_plugin(
  File "/Users/mrjones/Github/Projects/sheltr-ai/apps/api/.venv/lib/python3.9/site-packages/google/auth/transport/grpc.py", line 95, in __call__
    callback(self._get_authorization_headers(context), None)
  File "/Users/mrjones/Github/Projects/sheltr-ai/apps/api/.venv/lib/python3.9/site-packages/google/auth/transport/grpc.py", line 81, in _get_authorization_headers
    self._credentials.before_request(
  File "/Users/mrjones/Github/Projects/sheltr-ai/apps/api/.venv/lib/python3.9/site-packages/google/auth/credentials.py", line 175, in before_request
    self.refresh(request)
  File "/Users/mrjones/Github/Projects/sheltr-ai/apps/api/.venv/lib/python3.9/site-packages/google/oauth2/service_account.py", line 449, in refresh
    access_token, expiry, _ = _client.jwt_grant(
  File "/Users/mrjones/Github/Projects/sheltr-ai/apps/api/.venv/lib/python3.9/site-packages/google/oauth2/_client.py", line 308, in jwt_grant
    response_data = _token_endpoint_request(
  File "/Users/mrjones/Github/Projects/sheltr-ai/apps/api/.venv/lib/python3.9/site-packages/google/oauth2/_client.py", line 279, in _token_endpoint_request
    _handle_error_response(response_data, retryable_error)
  File "/Users/mrjones/Github/Projects/sheltr-ai/apps/api/.venv/lib/python3.9/site-packages/google/oauth2/_client.py", line 72, in _handle_error_response
    raise exceptions.RefreshError(
google.auth.exceptions.RefreshError: ('invalid_grant: Invalid JWT Signature.', {'error': 'invalid_grant', 'error_description': 'Invalid JWT Signature.'})
ERROR:grpc._plugin_wrapping:AuthMetadataPluginCallback "<google.auth.transport.grpc.AuthMetadataPlugin object at 0x108428ac0>" raised exception!
Traceback (most recent call last):
  File "/Users/mrjones/Github/Projects/sheltr-ai/apps/api/.venv/lib/python3.9/site-packages/grpc/_plugin_wrapping.py", line 105, in __call__
    self._metadata_plugin(
  File "/Users/mrjones/Github/Projects/sheltr-ai/apps/api/.venv/lib/python3.9/site-packages/google/auth/transport/grpc.py", line 95, in __call__
    callback(self._get_authorization_headers(context), None)
  File "/Users/mrjones/Github/Projects/sheltr-ai/apps/api/.venv/lib/python3.9/site-packages/google/auth/transport/grpc.py", line 81, in _get_authorization_headers
    self._credentials.before_request(
  File "/Users/mrjones/Github/Projects/sheltr-ai/apps/api/.venv/lib/python3.9/site-packages/google/auth/credentials.py", line 175, in before_request
    self.refresh(request)
  File "/Users/mrjones/Github/Projects/sheltr-ai/apps/api/.venv/lib/python3.9/site-packages/google/oauth2/service_account.py", line 449, in refresh
    access_token, expiry, _ = _client.jwt_grant(
  File "/Users/mrjones/Github/Projects/sheltr-ai/apps/api/.venv/lib/python3.9/site-packages/google/oauth2/_client.py", line 308, in jwt_grant
    response_data = _token_endpoint_request(
  File "/Users/mrjones/Github/Projects/sheltr-ai/apps/api/.venv/lib/python3.9/site-packages/google/oauth2/_client.py", line 279, in _token_endpoint_request
    _handle_error_response(response_data, retryable_error)
  File "/Users/mrjones/Github/Projects/sheltr-ai/apps/api/.venv/lib/python3.9/site-packages/google/oauth2/_client.py", line 72, in _handle_error_response
    raise exceptions.RefreshError(
google.auth.exceptions.RefreshError: ('invalid_grant: Invalid JWT Signature.', {'error': 'invalid_grant', 'error_description': 'Invalid JWT Signature.'})
ERROR:grpc._plugin_wrapping:AuthMetadataPluginCallback "<google.auth.transport.grpc.AuthMetadataPlugin object at 0x108428ac0>" raised exception!
Traceback (most recent call last):
  File "/Users/mrjones/Github/Projects/sheltr-ai/apps/api/.venv/lib/python3.9/site-packages/grpc/_plugin_wrapping.py", line 105, in __call__
    self._metadata_plugin(
  File "/Users/mrjones/Github/Projects/sheltr-ai/apps/api/.venv/lib/python3.9/site-packages/google/auth/transport/grpc.py", line 95, in __call__
    callback(self._get_authorization_headers(context), None)
  File "/Users/mrjones/Github/Projects/sheltr-ai/apps/api/.venv/lib/python3.9/site-packages/google/auth/transport/grpc.py", line 81, in _get_authorization_headers
    self._credentials.before_request(
  File "/Users/mrjones/Github/Projects/sheltr-ai/apps/api/.venv/lib/python3.9/site-packages/google/auth/credentials.py", line 175, in before_request
    self.refresh(request)
  File "/Users/mrjones/Github/Projects/sheltr-ai/apps/api/.venv/lib/python3.9/site-packages/google/oauth2/service_account.py", line 449, in refresh
    access_token, expiry, _ = _client.jwt_grant(
  File "/Users/mrjones/Github/Projects/sheltr-ai/apps/api/.venv/lib/python3.9/site-packages/google/oauth2/_client.py", line 308, in jwt_grant
    response_data = _token_endpoint_request(
  File "/Users/mrjones/Github/Projects/sheltr-ai/apps/api/.venv/lib/python3.9/site-packages/google/oauth2/_client.py", line 279, in _token_endpoint_request
    _handle_error_response(response_data, retryable_error)
  File "/Users/mrjones/Github/Projects/sheltr-ai/apps/api/.venv/lib/python3.9/site-packages/google/oauth2/_client.py", line 72, in _handle_error_response
    raise exceptions.RefreshError(
google.auth.exceptions.RefreshError: ('invalid_grant: Invalid JWT Signature.', {'error': 'invalid_grant', 'error_description': 'Invalid JWT Signature.'})
ERROR:grpc._plugin_wrapping:AuthMetadataPluginCallback "<google.auth.transport.grpc.AuthMetadataPlugin object at 0x108428ac0>" raised exception!
Traceback (most recent call last):
  File "/Users/mrjones/Github/Projects/sheltr-ai/apps/api/.venv/lib/python3.9/site-packages/grpc/_plugin_wrapping.py", line 105, in __call__
    self._metadata_plugin(
  File "/Users/mrjones/Github/Projects/sheltr-ai/apps/api/.venv/lib/python3.9/site-packages/google/auth/transport/grpc.py", line 95, in __call__
    callback(self._get_authorization_headers(context), None)
  File "/Users/mrjones/Github/Projects/sheltr-ai/apps/api/.venv/lib/python3.9/site-packages/google/auth/transport/grpc.py", line 81, in _get_authorization_headers
    self._credentials.before_request(
  File "/Users/mrjones/Github/Projects/sheltr-ai/apps/api/.venv/lib/python3.9/site-packages/google/auth/credentials.py", line 175, in before_request
    self.refresh(request)
  File "/Users/mrjones/Github/Projects/sheltr-ai/apps/api/.venv/lib/python3.9/site-packages/google/oauth2/service_account.py", line 449, in refresh
    access_token, expiry, _ = _client.jwt_grant(
  File "/Users/mrjones/Github/Projects/sheltr-ai/apps/api/.venv/lib/python3.9/site-packages/google/oauth2/_client.py", line 308, in jwt_grant
    response_data = _token_endpoint_request(
  File "/Users/mrjones/Github/Projects/sheltr-ai/apps/api/.venv/lib/python3.9/site-packages/google/oauth2/_client.py", line 279, in _token_endpoint_request
    _handle_error_response(response_data, retryable_error)
  File "/Users/mrjones/Github/Projects/sheltr-ai/apps/api/.venv/lib/python3.9/site-packages/google/oauth2/_client.py", line 72, in _handle_error_response
    raise exceptions.RefreshError(
google.auth.exceptions.RefreshError: ('invalid_grant: Invalid JWT Signature.', {'error': 'invalid_grant', 'error_description': 'Invalid JWT Signature.'})
ERROR:grpc._plugin_wrapping:AuthMetadataPluginCallback "<google.auth.transport.grpc.AuthMetadataPlugin object at 0x108428ac0>" raised exception!
Traceback (most recent call last):
  File "/Users/mrjones/Github/Projects/sheltr-ai/apps/api/.venv/lib/python3.9/site-packages/grpc/_plugin_wrapping.py", line 105, in __call__
    self._metadata_plugin(
  File "/Users/mrjones/Github/Projects/sheltr-ai/apps/api/.venv/lib/python3.9/site-packages/google/auth/transport/grpc.py", line 95, in __call__
    callback(self._get_authorization_headers(context), None)
  File "/Users/mrjones/Github/Projects/sheltr-ai/apps/api/.venv/lib/python3.9/site-packages/google/auth/transport/grpc.py", line 81, in _get_authorization_headers
    self._credentials.before_request(
  File "/Users/mrjones/Github/Projects/sheltr-ai/apps/api/.venv/lib/python3.9/site-packages/google/auth/credentials.py", line 175, in before_request
    self.refresh(request)
  File "/Users/mrjones/Github/Projects/sheltr-ai/apps/api/.venv/lib/python3.9/site-packages/google/oauth2/service_account.py", line 449, in refresh
    access_token, expiry, _ = _client.jwt_grant(
  File "/Users/mrjones/Github/Projects/sheltr-ai/apps/api/.venv/lib/python3.9/site-packages/google/oauth2/_client.py", line 308, in jwt_grant
    response_data = _token_endpoint_request(
  File "/Users/mrjones/Github/Projects/sheltr-ai/apps/api/.venv/lib/python3.9/site-packages/google/oauth2/_client.py", line 279, in _token_endpoint_request
    _handle_error_response(response_data, retryable_error)
  File "/Users/mrjones/Github/Projects/sheltr-ai/apps/api/.venv/lib/python3.9/site-packages/google/oauth2/_client.py", line 72, in _handle_error_response
    raise exceptions.RefreshError(
google.auth.exceptions.RefreshError: ('invalid_grant: Invalid JWT Signature.', {'error': 'invalid_grant', 'error_description': 'Invalid JWT Signature.'})
ERROR:grpc._plugin_wrapping:AuthMetadataPluginCallback "<google.auth.transport.grpc.AuthMetadataPlugin object at 0x108428ac0>" raised exception!
Traceback (most recent call last):
  File "/Users/mrjones/Github/Projects/sheltr-ai/apps/api/.venv/lib/python3.9/site-packages/grpc/_plugin_wrapping.py", line 105, in __call__
    self._metadata_plugin(
  File "/Users/mrjones/Github/Projects/sheltr-ai/apps/api/.venv/lib/python3.9/site-packages/google/auth/transport/grpc.py", line 95, in __call__
    callback(self._get_authorization_headers(context), None)
  File "/Users/mrjones/Github/Projects/sheltr-ai/apps/api/.venv/lib/python3.9/site-packages/google/auth/transport/grpc.py", line 81, in _get_authorization_headers
    self._credentials.before_request(
  File "/Users/mrjones/Github/Projects/sheltr-ai/apps/api/.venv/lib/python3.9/site-packages/google/auth/credentials.py", line 175, in before_request
    self.refresh(request)
  File "/Users/mrjones/Github/Projects/sheltr-ai/apps/api/.venv/lib/python3.9/site-packages/google/oauth2/service_account.py", line 449, in refresh
    access_token, expiry, _ = _client.jwt_grant(
  File "/Users/mrjones/Github/Projects/sheltr-ai/apps/api/.venv/lib/python3.9/site-packages/google/oauth2/_client.py", line 308, in jwt_grant
    response_data = _token_endpoint_request(
  File "/Users/mrjones/Github/Projects/sheltr-ai/apps/api/.venv/lib/python3.9/site-packages/google/oauth2/_client.py", line 279, in _token_endpoint_request
    _handle_error_response(response_data, retryable_error)
  File "/Users/mrjones/Github/Projects/sheltr-ai/apps/api/.venv/lib/python3.9/site-packages/google/oauth2/_client.py", line 72, in _handle_error_response
    raise exceptions.RefreshError(
google.auth.exceptions.RefreshError: ('invalid_grant: Invalid JWT Signature.', {'error': 'invalid_grant', 'error_description': 'Invalid JWT Signature.'})
ERROR:grpc._plugin_wrapping:AuthMetadataPluginCallback "<google.auth.transport.grpc.AuthMetadataPlugin object at 0x108428ac0>" raised exception!
Traceback (most recent call last):
  File "/Users/mrjones/Github/Projects/sheltr-ai/apps/api/.venv/lib/python3.9/site-packages/grpc/_plugin_wrapping.py", line 105, in __call__
    self._metadata_plugin(
  File "/Users/mrjones/Github/Projects/sheltr-ai/apps/api/.venv/lib/python3.9/site-packages/google/auth/transport/grpc.py", line 95, in __call__
    callback(self._get_authorization_headers(context), None)
  File "/Users/mrjones/Github/Projects/sheltr-ai/apps/api/.venv/lib/python3.9/site-packages/google/auth/transport/grpc.py", line 81, in _get_authorization_headers
    self._credentials.before_request(
  File "/Users/mrjones/Github/Projects/sheltr-ai/apps/api/.venv/lib/python3.9/site-packages/google/auth/credentials.py", line 175, in before_request
    self.refresh(request)
  File "/Users/mrjones/Github/Projects/sheltr-ai/apps/api/.venv/lib/python3.9/site-packages/google/oauth2/service_account.py", line 449, in refresh
    access_token, expiry, _ = _client.jwt_grant(
  File "/Users/mrjones/Github/Projects/sheltr-ai/apps/api/.venv/lib/python3.9/site-packages/google/oauth2/_client.py", line 308, in jwt_grant
    response_data = _token_endpoint_request(
  File "/Users/mrjones/Github/Projects/sheltr-ai/apps/api/.venv/lib/python3.9/site-packages/google/oauth2/_client.py", line 279, in _token_endpoint_request
    _handle_error_response(response_data, retryable_error)
  File "/Users/mrjones/Github/Projects/sheltr-ai/apps/api/.venv/lib/python3.9/site-packages/google/oauth2/_client.py", line 72, in _handle_error_response
    raise exceptions.RefreshError(
google.auth.exceptions.RefreshError: ('invalid_grant: Invalid JWT Signature.', {'error': 'invalid_grant', 'error_description': 'Invalid JWT Signature.'})
ERROR:grpc._plugin_wrapping:AuthMetadataPluginCallback "<google.auth.transport.grpc.AuthMetadataPlugin object at 0x108428ac0>" raised exception!
Traceback (most recent call last):
  File "/Users/mrjones/Github/Projects/sheltr-ai/apps/api/.venv/lib/python3.9/site-packages/grpc/_plugin_wrapping.py", line 105, in __call__
    self._metadata_plugin(
  File "/Users/mrjones/Github/Projects/sheltr-ai/apps/api/.venv/lib/python3.9/site-packages/google/auth/transport/grpc.py", line 95, in __call__
    callback(self._get_authorization_headers(context), None)
  File "/Users/mrjones/Github/Projects/sheltr-ai/apps/api/.venv/lib/python3.9/site-packages/google/auth/transport/grpc.py", line 81, in _get_authorization_headers
    self._credentials.before_request(
  File "/Users/mrjones/Github/Projects/sheltr-ai/apps/api/.venv/lib/python3.9/site-packages/google/auth/credentials.py", line 175, in before_request
    self.refresh(request)
  File "/Users/mrjones/Github/Projects/sheltr-ai/apps/api/.venv/lib/python3.9/site-packages/google/oauth2/service_account.py", line 449, in refresh
    access_token, expiry, _ = _client.jwt_grant(
  File "/Users/mrjones/Github/Projects/sheltr-ai/apps/api/.venv/lib/python3.9/site-packages/google/oauth2/_client.py", line 308, in jwt_grant
    response_data = _token_endpoint_request(
  File "/Users/mrjones/Github/Projects/sheltr-ai/apps/api/.venv/lib/python3.9/site-packages/google/oauth2/_client.py", line 279, in _token_endpoint_request
    _handle_error_response(response_data, retryable_error)
  File "/Users/mrjones/Github/Projects/sheltr-ai/apps/api/.venv/lib/python3.9/site-packages/google/oauth2/_client.py", line 72, in _handle_error_response
    raise exceptions.RefreshError(
google.auth.exceptions.RefreshError: ('invalid_grant: Invalid JWT Signature.', {'error': 'invalid_grant', 'error_description': 'Invalid JWT Signature.'})
ERROR:grpc._plugin_wrapping:AuthMetadataPluginCallback "<google.auth.transport.grpc.AuthMetadataPlugin object at 0x108428ac0>" raised exception!
Traceback (most recent call last):
  File "/Users/mrjones/Github/Projects/sheltr-ai/apps/api/.venv/lib/python3.9/site-packages/grpc/_plugin_wrapping.py", line 105, in __call__
    self._metadata_plugin(
  File "/Users/mrjones/Github/Projects/sheltr-ai/apps/api/.venv/lib/python3.9/site-packages/google/auth/transport/grpc.py", line 95, in __call__
    callback(self._get_authorization_headers(context), None)
  File "/Users/mrjones/Github/Projects/sheltr-ai/apps/api/.venv/lib/python3.9/site-packages/google/auth/transport/grpc.py", line 81, in _get_authorization_headers
    self._credentials.before_request(
  File "/Users/mrjones/Github/Projects/sheltr-ai/apps/api/.venv/lib/python3.9/site-packages/google/auth/credentials.py", line 175, in before_request
    self.refresh(request)
  File "/Users/mrjones/Github/Projects/sheltr-ai/apps/api/.venv/lib/python3.9/site-packages/google/oauth2/service_account.py", line 449, in refresh
    access_token, expiry, _ = _client.jwt_grant(
  File "/Users/mrjones/Github/Projects/sheltr-ai/apps/api/.venv/lib/python3.9/site-packages/google/oauth2/_client.py", line 308, in jwt_grant
    response_data = _token_endpoint_request(
  File "/Users/mrjones/Github/Projects/sheltr-ai/apps/api/.venv/lib/python3.9/site-packages/google/oauth2/_client.py", line 279, in _token_endpoint_request
    _handle_error_response(response_data, retryable_error)
  File "/Users/mrjones/Github/Projects/sheltr-ai/apps/api/.venv/lib/python3.9/site-packages/google/oauth2/_client.py", line 72, in _handle_error_response
    raise exceptions.RefreshError(
google.auth.exceptions.RefreshError: ('invalid_grant: Invalid JWT Signature.', {'error': 'invalid_grant', 'error_description': 'Invalid JWT Signature.'})
ERROR:grpc._plugin_wrapping:AuthMetadataPluginCallback "<google.auth.transport.grpc.AuthMetadataPlugin object at 0x108428ac0>" raised exception!
Traceback (most recent call last):
  File "/Users/mrjones/Github/Projects/sheltr-ai/apps/api/.venv/lib/python3.9/site-packages/grpc/_plugin_wrapping.py", line 105, in __call__
    self._metadata_plugin(
  File "/Users/mrjones/Github/Projects/sheltr-ai/apps/api/.venv/lib/python3.9/site-packages/google/auth/transport/grpc.py", line 95, in __call__
    callback(self._get_authorization_headers(context), None)
  File "/Users/mrjones/Github/Projects/sheltr-ai/apps/api/.venv/lib/python3.9/site-packages/google/auth/transport/grpc.py", line 81, in _get_authorization_headers
    self._credentials.before_request(
  File "/Users/mrjones/Github/Projects/sheltr-ai/apps/api/.venv/lib/python3.9/site-packages/google/auth/credentials.py", line 175, in before_request
    self.refresh(request)
  File "/Users/mrjones/Github/Projects/sheltr-ai/apps/api/.venv/lib/python3.9/site-packages/google/oauth2/service_account.py", line 449, in refresh
    access_token, expiry, _ = _client.jwt_grant(
  File "/Users/mrjones/Github/Projects/sheltr-ai/apps/api/.venv/lib/python3.9/site-packages/google/oauth2/_client.py", line 308, in jwt_grant
    response_data = _token_endpoint_request(
  File "/Users/mrjones/Github/Projects/sheltr-ai/apps/api/.venv/lib/python3.9/site-packages/google/oauth2/_client.py", line 279, in _token_endpoint_request
    _handle_error_response(response_data, retryable_error)
  File "/Users/mrjones/Github/Projects/sheltr-ai/apps/api/.venv/lib/python3.9/site-packages/google/oauth2/_client.py", line 72, in _handle_error_response
    raise exceptions.RefreshError(
google.auth.exceptions.RefreshError: ('invalid_grant: Invalid JWT Signature.', {'error': 'invalid_grant', 'error_description': 'Invalid JWT Signature.'})
ERROR:grpc._plugin_wrapping:AuthMetadataPluginCallback "<google.auth.transport.grpc.AuthMetadataPlugin object at 0x108428ac0>" raised exception!
Traceback (most recent call last):
  File "/Users/mrjones/Github/Projects/sheltr-ai/apps/api/.venv/lib/python3.9/site-packages/grpc/_plugin_wrapping.py", line 105, in __call__
    self._metadata_plugin(
  File "/Users/mrjones/Github/Projects/sheltr-ai/apps/api/.venv/lib/python3.9/site-packages/google/auth/transport/grpc.py", line 95, in __call__
    callback(self._get_authorization_headers(context), None)
  File "/Users/mrjones/Github/Projects/sheltr-ai/apps/api/.venv/lib/python3.9/site-packages/google/auth/transport/grpc.py", line 81, in _get_authorization_headers
    self._credentials.before_request(
  File "/Users/mrjones/Github/Projects/sheltr-ai/apps/api/.venv/lib/python3.9/site-packages/google/auth/credentials.py", line 175, in before_request
    self.refresh(request)
  File "/Users/mrjones/Github/Projects/sheltr-ai/apps/api/.venv/lib/python3.9/site-packages/google/oauth2/service_account.py", line 449, in refresh
    access_token, expiry, _ = _client.jwt_grant(
  File "/Users/mrjones/Github/Projects/sheltr-ai/apps/api/.venv/lib/python3.9/site-packages/google/oauth2/_client.py", line 308, in jwt_grant
    response_data = _token_endpoint_request(
  File "/Users/mrjones/Github/Projects/sheltr-ai/apps/api/.venv/lib/python3.9/site-packages/google/oauth2/_client.py", line 279, in _token_endpoint_request
    _handle_error_response(response_data, retryable_error)
  File "/Users/mrjones/Github/Projects/sheltr-ai/apps/api/.venv/lib/python3.9/site-packages/google/oauth2/_client.py", line 72, in _handle_error_response
    raise exceptions.RefreshError(
google.auth.exceptions.RefreshError: ('invalid_grant: Invalid JWT Signature.', {'error': 'invalid_grant', 'error_description': 'Invalid JWT Signature.'})
ERROR:grpc._plugin_wrapping:AuthMetadataPluginCallback "<google.auth.transport.grpc.AuthMetadataPlugin object at 0x108428ac0>" raised exception!
Traceback (most recent call last):
  File "/Users/mrjones/Github/Projects/sheltr-ai/apps/api/.venv/lib/python3.9/site-packages/grpc/_plugin_wrapping.py", line 105, in __call__
    self._metadata_plugin(
  File "/Users/mrjones/Github/Projects/sheltr-ai/apps/api/.venv/lib/python3.9/site-packages/google/auth/transport/grpc.py", line 95, in __call__
    callback(self._get_authorization_headers(context), None)
  File "/Users/mrjones/Github/Projects/sheltr-ai/apps/api/.venv/lib/python3.9/site-packages/google/auth/transport/grpc.py", line 81, in _get_authorization_headers
    self._credentials.before_request(
  File "/Users/mrjones/Github/Projects/sheltr-ai/apps/api/.venv/lib/python3.9/site-packages/google/auth/credentials.py", line 175, in before_request
    self.refresh(request)
  File "/Users/mrjones/Github/Projects/sheltr-ai/apps/api/.venv/lib/python3.9/site-packages/google/oauth2/service_account.py", line 449, in refresh
    access_token, expiry, _ = _client.jwt_grant(
  File "/Users/mrjones/Github/Projects/sheltr-ai/apps/api/.venv/lib/python3.9/site-packages/google/oauth2/_client.py", line 308, in jwt_grant
    response_data = _token_endpoint_request(
  File "/Users/mrjones/Github/Projects/sheltr-ai/apps/api/.venv/lib/python3.9/site-packages/google/oauth2/_client.py", line 279, in _token_endpoint_request
    _handle_error_response(response_data, retryable_error)
  File "/Users/mrjones/Github/Projects/sheltr-ai/apps/api/.venv/lib/python3.9/site-packages/google/oauth2/_client.py", line 72, in _handle_error_response
    raise exceptions.RefreshError(
google.auth.exceptions.RefreshError: ('invalid_grant: Invalid JWT Signature.', {'error': 'invalid_grant', 'error_description': 'Invalid JWT Signature.'})
ERROR:grpc._plugin_wrapping:AuthMetadataPluginCallback "<google.auth.transport.grpc.AuthMetadataPlugin object at 0x108428ac0>" raised exception!
Traceback (most recent call last):
  File "/Users/mrjones/Github/Projects/sheltr-ai/apps/api/.venv/lib/python3.9/site-packages/grpc/_plugin_wrapping.py", line 105, in __call__
    self._metadata_plugin(
  File "/Users/mrjones/Github/Projects/sheltr-ai/apps/api/.venv/lib/python3.9/site-packages/google/auth/transport/grpc.py", line 95, in __call__
    callback(self._get_authorization_headers(context), None)
  File "/Users/mrjones/Github/Projects/sheltr-ai/apps/api/.venv/lib/python3.9/site-packages/google/auth/transport/grpc.py", line 81, in _get_authorization_headers
    self._credentials.before_request(
  File "/Users/mrjones/Github/Projects/sheltr-ai/apps/api/.venv/lib/python3.9/site-packages/google/auth/credentials.py", line 175, in before_request
    self.refresh(request)
  File "/Users/mrjones/Github/Projects/sheltr-ai/apps/api/.venv/lib/python3.9/site-packages/google/oauth2/service_account.py", line 449, in refresh
    access_token, expiry, _ = _client.jwt_grant(
  File "/Users/mrjones/Github/Projects/sheltr-ai/apps/api/.venv/lib/python3.9/site-packages/google/oauth2/_client.py", line 308, in jwt_grant
    response_data = _token_endpoint_request(
  File "/Users/mrjones/Github/Projects/sheltr-ai/apps/api/.venv/lib/python3.9/site-packages/google/oauth2/_client.py", line 279, in _token_endpoint_request
    _handle_error_response(response_data, retryable_error)
  File "/Users/mrjones/Github/Projects/sheltr-ai/apps/api/.venv/lib/python3.9/site-packages/google/oauth2/_client.py", line 72, in _handle_error_response
    raise exceptions.RefreshError(
google.auth.exceptions.RefreshError: ('invalid_grant: Invalid JWT Signature.', {'error': 'invalid_grant', 'error_description': 'Invalid JWT Signature.'})
ERROR:grpc._plugin_wrapping:AuthMetadataPluginCallback "<google.auth.transport.grpc.AuthMetadataPlugin object at 0x108428ac0>" raised exception!
Traceback (most recent call last):
  File "/Users/mrjones/Github/Projects/sheltr-ai/apps/api/.venv/lib/python3.9/site-packages/grpc/_plugin_wrapping.py", line 105, in __call__
    self._metadata_plugin(
  File "/Users/mrjones/Github/Projects/sheltr-ai/apps/api/.venv/lib/python3.9/site-packages/google/auth/transport/grpc.py", line 95, in __call__
    callback(self._get_authorization_headers(context), None)
  File "/Users/mrjones/Github/Projects/sheltr-ai/apps/api/.venv/lib/python3.9/site-packages/google/auth/transport/grpc.py", line 81, in _get_authorization_headers
    self._credentials.before_request(
  File "/Users/mrjones/Github/Projects/sheltr-ai/apps/api/.venv/lib/python3.9/site-packages/google/auth/credentials.py", line 175, in before_request
    self.refresh(request)
  File "/Users/mrjones/Github/Projects/sheltr-ai/apps/api/.venv/lib/python3.9/site-packages/google/oauth2/service_account.py", line 449, in refresh
    access_token, expiry, _ = _client.jwt_grant(
  File "/Users/mrjones/Github/Projects/sheltr-ai/apps/api/.venv/lib/python3.9/site-packages/google/oauth2/_client.py", line 308, in jwt_grant
    response_data = _token_endpoint_request(
  File "/Users/mrjones/Github/Projects/sheltr-ai/apps/api/.venv/lib/python3.9/site-packages/google/oauth2/_client.py", line 279, in _token_endpoint_request
    _handle_error_response(response_data, retryable_error)
  File "/Users/mrjones/Github/Projects/sheltr-ai/apps/api/.venv/lib/python3.9/site-packages/google/oauth2/_client.py", line 72, in _handle_error_response
    raise exceptions.RefreshError(
google.auth.exceptions.RefreshError: ('invalid_grant: Invalid JWT Signature.', {'error': 'invalid_grant', 'error_description': 'Invalid JWT Signature.'})
