/Users/mrjones/Github/Projects/sheltr-ai/apps/api/.venv/lib/python3.9/site-packages/urllib3/__init__.py:35: NotOpenSSLWarning: urllib3 v2 only supports OpenSSL 1.1.1+, currently the 'ssl' module is compiled with 'LibreSSL 2.8.3'. See: https://github.com/urllib3/urllib3/issues/3020
  warnings.warn(
INFO:services.chatbot.orchestrator:ü§ñ Chatbot Orchestrator initialized
INFO:__main__:üè† Starting SHELTR-AI API server...
INFO:__main__:üîê Multi-tenant authentication system ready
INFO:__main__:üìö API documentation: http://localhost:8000/docs
INFO:__main__:üè• Health check: http://localhost:8000/health
INFO:     Will watch for changes in these directories: ['/Users/mrjones/Github/Projects/sheltr-ai/apps/api']
INFO:     Uvicorn running on http://0.0.0.0:8000 (Press CTRL+C to quit)
INFO:     Started reloader process [88164] using WatchFiles
/Users/mrjones/Github/Projects/sheltr-ai/apps/api/.venv/lib/python3.9/site-packages/urllib3/__init__.py:35: NotOpenSSLWarning: urllib3 v2 only supports OpenSSL 1.1.1+, currently the 'ssl' module is compiled with 'LibreSSL 2.8.3'. See: https://github.com/urllib3/urllib3/issues/3020
  warnings.warn(
INFO:services.chatbot.orchestrator:ü§ñ Chatbot Orchestrator initialized
INFO:     Started server process [88201]
INFO:     Waiting for application startup.
INFO:main:üöÄ SHELTR-AI API starting up...
INFO:main:üîê Authentication system initialized
INFO:main:üè¢ Multi-tenant architecture ready
INFO:     Application startup complete.
INFO:     127.0.0.1:63018 - "GET /health HTTP/1.1" 200 OK
INFO:     127.0.0.1:50905 - "OPTIONS /chatbot/message HTTP/1.1" 200 OK
INFO:routers.chatbot:Chat message from super_admin user joel.yaffe@gmail.com: Show me platform analytics...
INFO:services.chatbot.orchestrator:Processing message from super_admin user UbNhjY35yXWVpctEyusVkbIjjtJ2: information
ERROR:grpc._plugin_wrapping:AuthMetadataPluginCallback "<google.auth.transport.grpc.AuthMetadataPlugin object at 0x103e29b20>" raised exception!
Traceback (most recent call last):
  File "/Users/mrjones/Github/Projects/sheltr-ai/apps/api/.venv/lib/python3.9/site-packages/grpc/_plugin_wrapping.py", line 105, in __call__
    self._metadata_plugin(
  File "/Users/mrjones/Github/Projects/sheltr-ai/apps/api/.venv/lib/python3.9/site-packages/google/auth/transport/grpc.py", line 95, in __call__
    callback(self._get_authorization_headers(context), None)
  File "/Users/mrjones/Github/Projects/sheltr-ai/apps/api/.venv/lib/python3.9/site-packages/google/auth/transport/grpc.py", line 81, in _get_authorization_headers
    self._credentials.before_request(
  File "/Users/mrjones/Github/Projects/sheltr-ai/apps/api/.venv/lib/python3.9/site-packages/google/auth/credentials.py", line 175, in before_request
    self.refresh(request)
  File "/Users/mrjones/Github/Projects/sheltr-ai/apps/api/.venv/lib/python3.9/site-packages/google/oauth2/service_account.py", line 449, in refresh
    access_token, expiry, _ = _client.jwt_grant(
  File "/Users/mrjones/Github/Projects/sheltr-ai/apps/api/.venv/lib/python3.9/site-packages/google/oauth2/_client.py", line 308, in jwt_grant
    response_data = _token_endpoint_request(
  File "/Users/mrjones/Github/Projects/sheltr-ai/apps/api/.venv/lib/python3.9/site-packages/google/oauth2/_client.py", line 279, in _token_endpoint_request
    _handle_error_response(response_data, retryable_error)
  File "/Users/mrjones/Github/Projects/sheltr-ai/apps/api/.venv/lib/python3.9/site-packages/google/oauth2/_client.py", line 72, in _handle_error_response
    raise exceptions.RefreshError(
google.auth.exceptions.RefreshError: ('invalid_grant: Invalid JWT Signature.', {'error': 'invalid_grant', 'error_description': 'Invalid JWT Signature.'})
ERROR:grpc._plugin_wrapping:AuthMetadataPluginCallback "<google.auth.transport.grpc.AuthMetadataPlugin object at 0x103e29b20>" raised exception!
Traceback (most recent call last):
  File "/Users/mrjones/Github/Projects/sheltr-ai/apps/api/.venv/lib/python3.9/site-packages/grpc/_plugin_wrapping.py", line 105, in __call__
    self._metadata_plugin(
  File "/Users/mrjones/Github/Projects/sheltr-ai/apps/api/.venv/lib/python3.9/site-packages/google/auth/transport/grpc.py", line 95, in __call__
    callback(self._get_authorization_headers(context), None)
  File "/Users/mrjones/Github/Projects/sheltr-ai/apps/api/.venv/lib/python3.9/site-packages/google/auth/transport/grpc.py", line 81, in _get_authorization_headers
    self._credentials.before_request(
  File "/Users/mrjones/Github/Projects/sheltr-ai/apps/api/.venv/lib/python3.9/site-packages/google/auth/credentials.py", line 175, in before_request
    self.refresh(request)
  File "/Users/mrjones/Github/Projects/sheltr-ai/apps/api/.venv/lib/python3.9/site-packages/google/oauth2/service_account.py", line 449, in refresh
    access_token, expiry, _ = _client.jwt_grant(
  File "/Users/mrjones/Github/Projects/sheltr-ai/apps/api/.venv/lib/python3.9/site-packages/google/oauth2/_client.py", line 308, in jwt_grant
    response_data = _token_endpoint_request(
  File "/Users/mrjones/Github/Projects/sheltr-ai/apps/api/.venv/lib/python3.9/site-packages/google/oauth2/_client.py", line 279, in _token_endpoint_request
    _handle_error_response(response_data, retryable_error)
  File "/Users/mrjones/Github/Projects/sheltr-ai/apps/api/.venv/lib/python3.9/site-packages/google/oauth2/_client.py", line 72, in _handle_error_response
    raise exceptions.RefreshError(
google.auth.exceptions.RefreshError: ('invalid_grant: Invalid JWT Signature.', {'error': 'invalid_grant', 'error_description': 'Invalid JWT Signature.'})
ERROR:grpc._plugin_wrapping:AuthMetadataPluginCallback "<google.auth.transport.grpc.AuthMetadataPlugin object at 0x103e29b20>" raised exception!
Traceback (most recent call last):
  File "/Users/mrjones/Github/Projects/sheltr-ai/apps/api/.venv/lib/python3.9/site-packages/grpc/_plugin_wrapping.py", line 105, in __call__
    self._metadata_plugin(
  File "/Users/mrjones/Github/Projects/sheltr-ai/apps/api/.venv/lib/python3.9/site-packages/google/auth/transport/grpc.py", line 95, in __call__
    callback(self._get_authorization_headers(context), None)
  File "/Users/mrjones/Github/Projects/sheltr-ai/apps/api/.venv/lib/python3.9/site-packages/google/auth/transport/grpc.py", line 81, in _get_authorization_headers
    self._credentials.before_request(
  File "/Users/mrjones/Github/Projects/sheltr-ai/apps/api/.venv/lib/python3.9/site-packages/google/auth/credentials.py", line 175, in before_request
    self.refresh(request)
  File "/Users/mrjones/Github/Projects/sheltr-ai/apps/api/.venv/lib/python3.9/site-packages/google/oauth2/service_account.py", line 449, in refresh
    access_token, expiry, _ = _client.jwt_grant(
  File "/Users/mrjones/Github/Projects/sheltr-ai/apps/api/.venv/lib/python3.9/site-packages/google/oauth2/_client.py", line 308, in jwt_grant
    response_data = _token_endpoint_request(
  File "/Users/mrjones/Github/Projects/sheltr-ai/apps/api/.venv/lib/python3.9/site-packages/google/oauth2/_client.py", line 279, in _token_endpoint_request
    _handle_error_response(response_data, retryable_error)
  File "/Users/mrjones/Github/Projects/sheltr-ai/apps/api/.venv/lib/python3.9/site-packages/google/oauth2/_client.py", line 72, in _handle_error_response
    raise exceptions.RefreshError(
google.auth.exceptions.RefreshError: ('invalid_grant: Invalid JWT Signature.', {'error': 'invalid_grant', 'error_description': 'Invalid JWT Signature.'})
ERROR:grpc._plugin_wrapping:AuthMetadataPluginCallback "<google.auth.transport.grpc.AuthMetadataPlugin object at 0x103e29b20>" raised exception!
Traceback (most recent call last):
  File "/Users/mrjones/Github/Projects/sheltr-ai/apps/api/.venv/lib/python3.9/site-packages/grpc/_plugin_wrapping.py", line 105, in __call__
    self._metadata_plugin(
  File "/Users/mrjones/Github/Projects/sheltr-ai/apps/api/.venv/lib/python3.9/site-packages/google/auth/transport/grpc.py", line 95, in __call__
    callback(self._get_authorization_headers(context), None)
  File "/Users/mrjones/Github/Projects/sheltr-ai/apps/api/.venv/lib/python3.9/site-packages/google/auth/transport/grpc.py", line 81, in _get_authorization_headers
    self._credentials.before_request(
  File "/Users/mrjones/Github/Projects/sheltr-ai/apps/api/.venv/lib/python3.9/site-packages/google/auth/credentials.py", line 175, in before_request
    self.refresh(request)
  File "/Users/mrjones/Github/Projects/sheltr-ai/apps/api/.venv/lib/python3.9/site-packages/google/oauth2/service_account.py", line 449, in refresh
    access_token, expiry, _ = _client.jwt_grant(
  File "/Users/mrjones/Github/Projects/sheltr-ai/apps/api/.venv/lib/python3.9/site-packages/google/oauth2/_client.py", line 308, in jwt_grant
    response_data = _token_endpoint_request(
  File "/Users/mrjones/Github/Projects/sheltr-ai/apps/api/.venv/lib/python3.9/site-packages/google/oauth2/_client.py", line 279, in _token_endpoint_request
    _handle_error_response(response_data, retryable_error)
  File "/Users/mrjones/Github/Projects/sheltr-ai/apps/api/.venv/lib/python3.9/site-packages/google/oauth2/_client.py", line 72, in _handle_error_response
    raise exceptions.RefreshError(
google.auth.exceptions.RefreshError: ('invalid_grant: Invalid JWT Signature.', {'error': 'invalid_grant', 'error_description': 'Invalid JWT Signature.'})
ERROR:grpc._plugin_wrapping:AuthMetadataPluginCallback "<google.auth.transport.grpc.AuthMetadataPlugin object at 0x103e29b20>" raised exception!
Traceback (most recent call last):
  File "/Users/mrjones/Github/Projects/sheltr-ai/apps/api/.venv/lib/python3.9/site-packages/grpc/_plugin_wrapping.py", line 105, in __call__
    self._metadata_plugin(
  File "/Users/mrjones/Github/Projects/sheltr-ai/apps/api/.venv/lib/python3.9/site-packages/google/auth/transport/grpc.py", line 95, in __call__
    callback(self._get_authorization_headers(context), None)
  File "/Users/mrjones/Github/Projects/sheltr-ai/apps/api/.venv/lib/python3.9/site-packages/google/auth/transport/grpc.py", line 81, in _get_authorization_headers
    self._credentials.before_request(
  File "/Users/mrjones/Github/Projects/sheltr-ai/apps/api/.venv/lib/python3.9/site-packages/google/auth/credentials.py", line 175, in before_request
    self.refresh(request)
  File "/Users/mrjones/Github/Projects/sheltr-ai/apps/api/.venv/lib/python3.9/site-packages/google/oauth2/service_account.py", line 449, in refresh
    access_token, expiry, _ = _client.jwt_grant(
  File "/Users/mrjones/Github/Projects/sheltr-ai/apps/api/.venv/lib/python3.9/site-packages/google/oauth2/_client.py", line 308, in jwt_grant
    response_data = _token_endpoint_request(
  File "/Users/mrjones/Github/Projects/sheltr-ai/apps/api/.venv/lib/python3.9/site-packages/google/oauth2/_client.py", line 279, in _token_endpoint_request
    _handle_error_response(response_data, retryable_error)
  File "/Users/mrjones/Github/Projects/sheltr-ai/apps/api/.venv/lib/python3.9/site-packages/google/oauth2/_client.py", line 72, in _handle_error_response
    raise exceptions.RefreshError(
google.auth.exceptions.RefreshError: ('invalid_grant: Invalid JWT Signature.', {'error': 'invalid_grant', 'error_description': 'Invalid JWT Signature.'})
ERROR:grpc._plugin_wrapping:AuthMetadataPluginCallback "<google.auth.transport.grpc.AuthMetadataPlugin object at 0x103e29b20>" raised exception!
Traceback (most recent call last):
  File "/Users/mrjones/Github/Projects/sheltr-ai/apps/api/.venv/lib/python3.9/site-packages/grpc/_plugin_wrapping.py", line 105, in __call__
    self._metadata_plugin(
  File "/Users/mrjones/Github/Projects/sheltr-ai/apps/api/.venv/lib/python3.9/site-packages/google/auth/transport/grpc.py", line 95, in __call__
    callback(self._get_authorization_headers(context), None)
  File "/Users/mrjones/Github/Projects/sheltr-ai/apps/api/.venv/lib/python3.9/site-packages/google/auth/transport/grpc.py", line 81, in _get_authorization_headers
    self._credentials.before_request(
  File "/Users/mrjones/Github/Projects/sheltr-ai/apps/api/.venv/lib/python3.9/site-packages/google/auth/credentials.py", line 175, in before_request
    self.refresh(request)
  File "/Users/mrjones/Github/Projects/sheltr-ai/apps/api/.venv/lib/python3.9/site-packages/google/oauth2/service_account.py", line 449, in refresh
    access_token, expiry, _ = _client.jwt_grant(
  File "/Users/mrjones/Github/Projects/sheltr-ai/apps/api/.venv/lib/python3.9/site-packages/google/oauth2/_client.py", line 308, in jwt_grant
    response_data = _token_endpoint_request(
  File "/Users/mrjones/Github/Projects/sheltr-ai/apps/api/.venv/lib/python3.9/site-packages/google/oauth2/_client.py", line 279, in _token_endpoint_request
    _handle_error_response(response_data, retryable_error)
  File "/Users/mrjones/Github/Projects/sheltr-ai/apps/api/.venv/lib/python3.9/site-packages/google/oauth2/_client.py", line 72, in _handle_error_response
    raise exceptions.RefreshError(
google.auth.exceptions.RefreshError: ('invalid_grant: Invalid JWT Signature.', {'error': 'invalid_grant', 'error_description': 'Invalid JWT Signature.'})
ERROR:grpc._plugin_wrapping:AuthMetadataPluginCallback "<google.auth.transport.grpc.AuthMetadataPlugin object at 0x103e29b20>" raised exception!
Traceback (most recent call last):
  File "/Users/mrjones/Github/Projects/sheltr-ai/apps/api/.venv/lib/python3.9/site-packages/grpc/_plugin_wrapping.py", line 105, in __call__
    self._metadata_plugin(
  File "/Users/mrjones/Github/Projects/sheltr-ai/apps/api/.venv/lib/python3.9/site-packages/google/auth/transport/grpc.py", line 95, in __call__
    callback(self._get_authorization_headers(context), None)
  File "/Users/mrjones/Github/Projects/sheltr-ai/apps/api/.venv/lib/python3.9/site-packages/google/auth/transport/grpc.py", line 81, in _get_authorization_headers
    self._credentials.before_request(
  File "/Users/mrjones/Github/Projects/sheltr-ai/apps/api/.venv/lib/python3.9/site-packages/google/auth/credentials.py", line 175, in before_request
    self.refresh(request)
  File "/Users/mrjones/Github/Projects/sheltr-ai/apps/api/.venv/lib/python3.9/site-packages/google/oauth2/service_account.py", line 449, in refresh
    access_token, expiry, _ = _client.jwt_grant(
  File "/Users/mrjones/Github/Projects/sheltr-ai/apps/api/.venv/lib/python3.9/site-packages/google/oauth2/_client.py", line 308, in jwt_grant
    response_data = _token_endpoint_request(
  File "/Users/mrjones/Github/Projects/sheltr-ai/apps/api/.venv/lib/python3.9/site-packages/google/oauth2/_client.py", line 279, in _token_endpoint_request
    _handle_error_response(response_data, retryable_error)
  File "/Users/mrjones/Github/Projects/sheltr-ai/apps/api/.venv/lib/python3.9/site-packages/google/oauth2/_client.py", line 72, in _handle_error_response
    raise exceptions.RefreshError(
google.auth.exceptions.RefreshError: ('invalid_grant: Invalid JWT Signature.', {'error': 'invalid_grant', 'error_description': 'Invalid JWT Signature.'})
ERROR:grpc._plugin_wrapping:AuthMetadataPluginCallback "<google.auth.transport.grpc.AuthMetadataPlugin object at 0x103e29b20>" raised exception!
Traceback (most recent call last):
  File "/Users/mrjones/Github/Projects/sheltr-ai/apps/api/.venv/lib/python3.9/site-packages/grpc/_plugin_wrapping.py", line 105, in __call__
    self._metadata_plugin(
  File "/Users/mrjones/Github/Projects/sheltr-ai/apps/api/.venv/lib/python3.9/site-packages/google/auth/transport/grpc.py", line 95, in __call__
    callback(self._get_authorization_headers(context), None)
  File "/Users/mrjones/Github/Projects/sheltr-ai/apps/api/.venv/lib/python3.9/site-packages/google/auth/transport/grpc.py", line 81, in _get_authorization_headers
    self._credentials.before_request(
  File "/Users/mrjones/Github/Projects/sheltr-ai/apps/api/.venv/lib/python3.9/site-packages/google/auth/credentials.py", line 175, in before_request
    self.refresh(request)
  File "/Users/mrjones/Github/Projects/sheltr-ai/apps/api/.venv/lib/python3.9/site-packages/google/oauth2/service_account.py", line 449, in refresh
    access_token, expiry, _ = _client.jwt_grant(
  File "/Users/mrjones/Github/Projects/sheltr-ai/apps/api/.venv/lib/python3.9/site-packages/google/oauth2/_client.py", line 308, in jwt_grant
    response_data = _token_endpoint_request(
  File "/Users/mrjones/Github/Projects/sheltr-ai/apps/api/.venv/lib/python3.9/site-packages/google/oauth2/_client.py", line 279, in _token_endpoint_request
    _handle_error_response(response_data, retryable_error)
  File "/Users/mrjones/Github/Projects/sheltr-ai/apps/api/.venv/lib/python3.9/site-packages/google/oauth2/_client.py", line 72, in _handle_error_response
    raise exceptions.RefreshError(
google.auth.exceptions.RefreshError: ('invalid_grant: Invalid JWT Signature.', {'error': 'invalid_grant', 'error_description': 'Invalid JWT Signature.'})
ERROR:grpc._plugin_wrapping:AuthMetadataPluginCallback "<google.auth.transport.grpc.AuthMetadataPlugin object at 0x103e29b20>" raised exception!
Traceback (most recent call last):
  File "/Users/mrjones/Github/Projects/sheltr-ai/apps/api/.venv/lib/python3.9/site-packages/grpc/_plugin_wrapping.py", line 105, in __call__
    self._metadata_plugin(
  File "/Users/mrjones/Github/Projects/sheltr-ai/apps/api/.venv/lib/python3.9/site-packages/google/auth/transport/grpc.py", line 95, in __call__
    callback(self._get_authorization_headers(context), None)
  File "/Users/mrjones/Github/Projects/sheltr-ai/apps/api/.venv/lib/python3.9/site-packages/google/auth/transport/grpc.py", line 81, in _get_authorization_headers
    self._credentials.before_request(
  File "/Users/mrjones/Github/Projects/sheltr-ai/apps/api/.venv/lib/python3.9/site-packages/google/auth/credentials.py", line 175, in before_request
    self.refresh(request)
  File "/Users/mrjones/Github/Projects/sheltr-ai/apps/api/.venv/lib/python3.9/site-packages/google/oauth2/service_account.py", line 449, in refresh
    access_token, expiry, _ = _client.jwt_grant(
  File "/Users/mrjones/Github/Projects/sheltr-ai/apps/api/.venv/lib/python3.9/site-packages/google/oauth2/_client.py", line 308, in jwt_grant
    response_data = _token_endpoint_request(
  File "/Users/mrjones/Github/Projects/sheltr-ai/apps/api/.venv/lib/python3.9/site-packages/google/oauth2/_client.py", line 279, in _token_endpoint_request
    _handle_error_response(response_data, retryable_error)
  File "/Users/mrjones/Github/Projects/sheltr-ai/apps/api/.venv/lib/python3.9/site-packages/google/oauth2/_client.py", line 72, in _handle_error_response
    raise exceptions.RefreshError(
google.auth.exceptions.RefreshError: ('invalid_grant: Invalid JWT Signature.', {'error': 'invalid_grant', 'error_description': 'Invalid JWT Signature.'})
ERROR:grpc._plugin_wrapping:AuthMetadataPluginCallback "<google.auth.transport.grpc.AuthMetadataPlugin object at 0x103e29b20>" raised exception!
Traceback (most recent call last):
  File "/Users/mrjones/Github/Projects/sheltr-ai/apps/api/.venv/lib/python3.9/site-packages/grpc/_plugin_wrapping.py", line 105, in __call__
    self._metadata_plugin(
  File "/Users/mrjones/Github/Projects/sheltr-ai/apps/api/.venv/lib/python3.9/site-packages/google/auth/transport/grpc.py", line 95, in __call__
    callback(self._get_authorization_headers(context), None)
  File "/Users/mrjones/Github/Projects/sheltr-ai/apps/api/.venv/lib/python3.9/site-packages/google/auth/transport/grpc.py", line 81, in _get_authorization_headers
    self._credentials.before_request(
  File "/Users/mrjones/Github/Projects/sheltr-ai/apps/api/.venv/lib/python3.9/site-packages/google/auth/credentials.py", line 175, in before_request
    self.refresh(request)
  File "/Users/mrjones/Github/Projects/sheltr-ai/apps/api/.venv/lib/python3.9/site-packages/google/oauth2/service_account.py", line 449, in refresh
    access_token, expiry, _ = _client.jwt_grant(
  File "/Users/mrjones/Github/Projects/sheltr-ai/apps/api/.venv/lib/python3.9/site-packages/google/oauth2/_client.py", line 308, in jwt_grant
    response_data = _token_endpoint_request(
  File "/Users/mrjones/Github/Projects/sheltr-ai/apps/api/.venv/lib/python3.9/site-packages/google/oauth2/_client.py", line 279, in _token_endpoint_request
    _handle_error_response(response_data, retryable_error)
  File "/Users/mrjones/Github/Projects/sheltr-ai/apps/api/.venv/lib/python3.9/site-packages/google/oauth2/_client.py", line 72, in _handle_error_response
    raise exceptions.RefreshError(
google.auth.exceptions.RefreshError: ('invalid_grant: Invalid JWT Signature.', {'error': 'invalid_grant', 'error_description': 'Invalid JWT Signature.'})
ERROR:grpc._plugin_wrapping:AuthMetadataPluginCallback "<google.auth.transport.grpc.AuthMetadataPlugin object at 0x103e29b20>" raised exception!
Traceback (most recent call last):
  File "/Users/mrjones/Github/Projects/sheltr-ai/apps/api/.venv/lib/python3.9/site-packages/grpc/_plugin_wrapping.py", line 105, in __call__
    self._metadata_plugin(
  File "/Users/mrjones/Github/Projects/sheltr-ai/apps/api/.venv/lib/python3.9/site-packages/google/auth/transport/grpc.py", line 95, in __call__
    callback(self._get_authorization_headers(context), None)
  File "/Users/mrjones/Github/Projects/sheltr-ai/apps/api/.venv/lib/python3.9/site-packages/google/auth/transport/grpc.py", line 81, in _get_authorization_headers
    self._credentials.before_request(
  File "/Users/mrjones/Github/Projects/sheltr-ai/apps/api/.venv/lib/python3.9/site-packages/google/auth/credentials.py", line 175, in before_request
    self.refresh(request)
  File "/Users/mrjones/Github/Projects/sheltr-ai/apps/api/.venv/lib/python3.9/site-packages/google/oauth2/service_account.py", line 449, in refresh
    access_token, expiry, _ = _client.jwt_grant(
  File "/Users/mrjones/Github/Projects/sheltr-ai/apps/api/.venv/lib/python3.9/site-packages/google/oauth2/_client.py", line 308, in jwt_grant
    response_data = _token_endpoint_request(
  File "/Users/mrjones/Github/Projects/sheltr-ai/apps/api/.venv/lib/python3.9/site-packages/google/oauth2/_client.py", line 279, in _token_endpoint_request
    _handle_error_response(response_data, retryable_error)
  File "/Users/mrjones/Github/Projects/sheltr-ai/apps/api/.venv/lib/python3.9/site-packages/google/oauth2/_client.py", line 72, in _handle_error_response
    raise exceptions.RefreshError(
google.auth.exceptions.RefreshError: ('invalid_grant: Invalid JWT Signature.', {'error': 'invalid_grant', 'error_description': 'Invalid JWT Signature.'})
ERROR:grpc._plugin_wrapping:AuthMetadataPluginCallback "<google.auth.transport.grpc.AuthMetadataPlugin object at 0x103e29b20>" raised exception!
Traceback (most recent call last):
  File "/Users/mrjones/Github/Projects/sheltr-ai/apps/api/.venv/lib/python3.9/site-packages/grpc/_plugin_wrapping.py", line 105, in __call__
    self._metadata_plugin(
  File "/Users/mrjones/Github/Projects/sheltr-ai/apps/api/.venv/lib/python3.9/site-packages/google/auth/transport/grpc.py", line 95, in __call__
    callback(self._get_authorization_headers(context), None)
  File "/Users/mrjones/Github/Projects/sheltr-ai/apps/api/.venv/lib/python3.9/site-packages/google/auth/transport/grpc.py", line 81, in _get_authorization_headers
    self._credentials.before_request(
  File "/Users/mrjones/Github/Projects/sheltr-ai/apps/api/.venv/lib/python3.9/site-packages/google/auth/credentials.py", line 175, in before_request
    self.refresh(request)
  File "/Users/mrjones/Github/Projects/sheltr-ai/apps/api/.venv/lib/python3.9/site-packages/google/oauth2/service_account.py", line 449, in refresh
    access_token, expiry, _ = _client.jwt_grant(
  File "/Users/mrjones/Github/Projects/sheltr-ai/apps/api/.venv/lib/python3.9/site-packages/google/oauth2/_client.py", line 308, in jwt_grant
    response_data = _token_endpoint_request(
  File "/Users/mrjones/Github/Projects/sheltr-ai/apps/api/.venv/lib/python3.9/site-packages/google/oauth2/_client.py", line 279, in _token_endpoint_request
    _handle_error_response(response_data, retryable_error)
  File "/Users/mrjones/Github/Projects/sheltr-ai/apps/api/.venv/lib/python3.9/site-packages/google/oauth2/_client.py", line 72, in _handle_error_response
    raise exceptions.RefreshError(
google.auth.exceptions.RefreshError: ('invalid_grant: Invalid JWT Signature.', {'error': 'invalid_grant', 'error_description': 'Invalid JWT Signature.'})
ERROR:grpc._plugin_wrapping:AuthMetadataPluginCallback "<google.auth.transport.grpc.AuthMetadataPlugin object at 0x103e29b20>" raised exception!
Traceback (most recent call last):
  File "/Users/mrjones/Github/Projects/sheltr-ai/apps/api/.venv/lib/python3.9/site-packages/grpc/_plugin_wrapping.py", line 105, in __call__
    self._metadata_plugin(
  File "/Users/mrjones/Github/Projects/sheltr-ai/apps/api/.venv/lib/python3.9/site-packages/google/auth/transport/grpc.py", line 95, in __call__
    callback(self._get_authorization_headers(context), None)
  File "/Users/mrjones/Github/Projects/sheltr-ai/apps/api/.venv/lib/python3.9/site-packages/google/auth/transport/grpc.py", line 81, in _get_authorization_headers
    self._credentials.before_request(
  File "/Users/mrjones/Github/Projects/sheltr-ai/apps/api/.venv/lib/python3.9/site-packages/google/auth/credentials.py", line 175, in before_request
    self.refresh(request)
  File "/Users/mrjones/Github/Projects/sheltr-ai/apps/api/.venv/lib/python3.9/site-packages/google/oauth2/service_account.py", line 449, in refresh
    access_token, expiry, _ = _client.jwt_grant(
  File "/Users/mrjones/Github/Projects/sheltr-ai/apps/api/.venv/lib/python3.9/site-packages/google/oauth2/_client.py", line 308, in jwt_grant
    response_data = _token_endpoint_request(
  File "/Users/mrjones/Github/Projects/sheltr-ai/apps/api/.venv/lib/python3.9/site-packages/google/oauth2/_client.py", line 279, in _token_endpoint_request
    _handle_error_response(response_data, retryable_error)
  File "/Users/mrjones/Github/Projects/sheltr-ai/apps/api/.venv/lib/python3.9/site-packages/google/oauth2/_client.py", line 72, in _handle_error_response
    raise exceptions.RefreshError(
google.auth.exceptions.RefreshError: ('invalid_grant: Invalid JWT Signature.', {'error': 'invalid_grant', 'error_description': 'Invalid JWT Signature.'})
ERROR:grpc._plugin_wrapping:AuthMetadataPluginCallback "<google.auth.transport.grpc.AuthMetadataPlugin object at 0x103e29b20>" raised exception!
Traceback (most recent call last):
  File "/Users/mrjones/Github/Projects/sheltr-ai/apps/api/.venv/lib/python3.9/site-packages/grpc/_plugin_wrapping.py", line 105, in __call__
    self._metadata_plugin(
  File "/Users/mrjones/Github/Projects/sheltr-ai/apps/api/.venv/lib/python3.9/site-packages/google/auth/transport/grpc.py", line 95, in __call__
    callback(self._get_authorization_headers(context), None)
  File "/Users/mrjones/Github/Projects/sheltr-ai/apps/api/.venv/lib/python3.9/site-packages/google/auth/transport/grpc.py", line 81, in _get_authorization_headers
    self._credentials.before_request(
  File "/Users/mrjones/Github/Projects/sheltr-ai/apps/api/.venv/lib/python3.9/site-packages/google/auth/credentials.py", line 175, in before_request
    self.refresh(request)
  File "/Users/mrjones/Github/Projects/sheltr-ai/apps/api/.venv/lib/python3.9/site-packages/google/oauth2/service_account.py", line 449, in refresh
    access_token, expiry, _ = _client.jwt_grant(
  File "/Users/mrjones/Github/Projects/sheltr-ai/apps/api/.venv/lib/python3.9/site-packages/google/oauth2/_client.py", line 308, in jwt_grant
    response_data = _token_endpoint_request(
  File "/Users/mrjones/Github/Projects/sheltr-ai/apps/api/.venv/lib/python3.9/site-packages/google/oauth2/_client.py", line 279, in _token_endpoint_request
    _handle_error_response(response_data, retryable_error)
  File "/Users/mrjones/Github/Projects/sheltr-ai/apps/api/.venv/lib/python3.9/site-packages/google/oauth2/_client.py", line 72, in _handle_error_response
    raise exceptions.RefreshError(
google.auth.exceptions.RefreshError: ('invalid_grant: Invalid JWT Signature.', {'error': 'invalid_grant', 'error_description': 'Invalid JWT Signature.'})
ERROR:grpc._plugin_wrapping:AuthMetadataPluginCallback "<google.auth.transport.grpc.AuthMetadataPlugin object at 0x103e29b20>" raised exception!
Traceback (most recent call last):
  File "/Users/mrjones/Github/Projects/sheltr-ai/apps/api/.venv/lib/python3.9/site-packages/grpc/_plugin_wrapping.py", line 105, in __call__
    self._metadata_plugin(
  File "/Users/mrjones/Github/Projects/sheltr-ai/apps/api/.venv/lib/python3.9/site-packages/google/auth/transport/grpc.py", line 95, in __call__
    callback(self._get_authorization_headers(context), None)
  File "/Users/mrjones/Github/Projects/sheltr-ai/apps/api/.venv/lib/python3.9/site-packages/google/auth/transport/grpc.py", line 81, in _get_authorization_headers
    self._credentials.before_request(
  File "/Users/mrjones/Github/Projects/sheltr-ai/apps/api/.venv/lib/python3.9/site-packages/google/auth/credentials.py", line 175, in before_request
    self.refresh(request)
  File "/Users/mrjones/Github/Projects/sheltr-ai/apps/api/.venv/lib/python3.9/site-packages/google/oauth2/service_account.py", line 449, in refresh
    access_token, expiry, _ = _client.jwt_grant(
  File "/Users/mrjones/Github/Projects/sheltr-ai/apps/api/.venv/lib/python3.9/site-packages/google/oauth2/_client.py", line 308, in jwt_grant
    response_data = _token_endpoint_request(
  File "/Users/mrjones/Github/Projects/sheltr-ai/apps/api/.venv/lib/python3.9/site-packages/google/oauth2/_client.py", line 279, in _token_endpoint_request
    _handle_error_response(response_data, retryable_error)
  File "/Users/mrjones/Github/Projects/sheltr-ai/apps/api/.venv/lib/python3.9/site-packages/google/oauth2/_client.py", line 72, in _handle_error_response
    raise exceptions.RefreshError(
google.auth.exceptions.RefreshError: ('invalid_grant: Invalid JWT Signature.', {'error': 'invalid_grant', 'error_description': 'Invalid JWT Signature.'})
ERROR:grpc._plugin_wrapping:AuthMetadataPluginCallback "<google.auth.transport.grpc.AuthMetadataPlugin object at 0x103e29b20>" raised exception!
Traceback (most recent call last):
  File "/Users/mrjones/Github/Projects/sheltr-ai/apps/api/.venv/lib/python3.9/site-packages/grpc/_plugin_wrapping.py", line 105, in __call__
    self._metadata_plugin(
  File "/Users/mrjones/Github/Projects/sheltr-ai/apps/api/.venv/lib/python3.9/site-packages/google/auth/transport/grpc.py", line 95, in __call__
    callback(self._get_authorization_headers(context), None)
  File "/Users/mrjones/Github/Projects/sheltr-ai/apps/api/.venv/lib/python3.9/site-packages/google/auth/transport/grpc.py", line 81, in _get_authorization_headers
    self._credentials.before_request(
  File "/Users/mrjones/Github/Projects/sheltr-ai/apps/api/.venv/lib/python3.9/site-packages/google/auth/credentials.py", line 175, in before_request
    self.refresh(request)
  File "/Users/mrjones/Github/Projects/sheltr-ai/apps/api/.venv/lib/python3.9/site-packages/google/oauth2/service_account.py", line 449, in refresh
    access_token, expiry, _ = _client.jwt_grant(
  File "/Users/mrjones/Github/Projects/sheltr-ai/apps/api/.venv/lib/python3.9/site-packages/google/oauth2/_client.py", line 308, in jwt_grant
    response_data = _token_endpoint_request(
  File "/Users/mrjones/Github/Projects/sheltr-ai/apps/api/.venv/lib/python3.9/site-packages/google/oauth2/_client.py", line 279, in _token_endpoint_request
    _handle_error_response(response_data, retryable_error)
  File "/Users/mrjones/Github/Projects/sheltr-ai/apps/api/.venv/lib/python3.9/site-packages/google/oauth2/_client.py", line 72, in _handle_error_response
    raise exceptions.RefreshError(
google.auth.exceptions.RefreshError: ('invalid_grant: Invalid JWT Signature.', {'error': 'invalid_grant', 'error_description': 'Invalid JWT Signature.'})
ERROR:grpc._plugin_wrapping:AuthMetadataPluginCallback "<google.auth.transport.grpc.AuthMetadataPlugin object at 0x103e29b20>" raised exception!
Traceback (most recent call last):
  File "/Users/mrjones/Github/Projects/sheltr-ai/apps/api/.venv/lib/python3.9/site-packages/grpc/_plugin_wrapping.py", line 105, in __call__
    self._metadata_plugin(
  File "/Users/mrjones/Github/Projects/sheltr-ai/apps/api/.venv/lib/python3.9/site-packages/google/auth/transport/grpc.py", line 95, in __call__
    callback(self._get_authorization_headers(context), None)
  File "/Users/mrjones/Github/Projects/sheltr-ai/apps/api/.venv/lib/python3.9/site-packages/google/auth/transport/grpc.py", line 81, in _get_authorization_headers
    self._credentials.before_request(
  File "/Users/mrjones/Github/Projects/sheltr-ai/apps/api/.venv/lib/python3.9/site-packages/google/auth/credentials.py", line 175, in before_request
    self.refresh(request)
  File "/Users/mrjones/Github/Projects/sheltr-ai/apps/api/.venv/lib/python3.9/site-packages/google/oauth2/service_account.py", line 449, in refresh
    access_token, expiry, _ = _client.jwt_grant(
  File "/Users/mrjones/Github/Projects/sheltr-ai/apps/api/.venv/lib/python3.9/site-packages/google/oauth2/_client.py", line 308, in jwt_grant
    response_data = _token_endpoint_request(
  File "/Users/mrjones/Github/Projects/sheltr-ai/apps/api/.venv/lib/python3.9/site-packages/google/oauth2/_client.py", line 279, in _token_endpoint_request
    _handle_error_response(response_data, retryable_error)
  File "/Users/mrjones/Github/Projects/sheltr-ai/apps/api/.venv/lib/python3.9/site-packages/google/oauth2/_client.py", line 72, in _handle_error_response
    raise exceptions.RefreshError(
google.auth.exceptions.RefreshError: ('invalid_grant: Invalid JWT Signature.', {'error': 'invalid_grant', 'error_description': 'Invalid JWT Signature.'})
ERROR:grpc._plugin_wrapping:AuthMetadataPluginCallback "<google.auth.transport.grpc.AuthMetadataPlugin object at 0x103e29b20>" raised exception!
Traceback (most recent call last):
  File "/Users/mrjones/Github/Projects/sheltr-ai/apps/api/.venv/lib/python3.9/site-packages/grpc/_plugin_wrapping.py", line 105, in __call__
    self._metadata_plugin(
  File "/Users/mrjones/Github/Projects/sheltr-ai/apps/api/.venv/lib/python3.9/site-packages/google/auth/transport/grpc.py", line 95, in __call__
    callback(self._get_authorization_headers(context), None)
  File "/Users/mrjones/Github/Projects/sheltr-ai/apps/api/.venv/lib/python3.9/site-packages/google/auth/transport/grpc.py", line 81, in _get_authorization_headers
    self._credentials.before_request(
  File "/Users/mrjones/Github/Projects/sheltr-ai/apps/api/.venv/lib/python3.9/site-packages/google/auth/credentials.py", line 175, in before_request
    self.refresh(request)
  File "/Users/mrjones/Github/Projects/sheltr-ai/apps/api/.venv/lib/python3.9/site-packages/google/oauth2/service_account.py", line 449, in refresh
    access_token, expiry, _ = _client.jwt_grant(
  File "/Users/mrjones/Github/Projects/sheltr-ai/apps/api/.venv/lib/python3.9/site-packages/google/oauth2/_client.py", line 308, in jwt_grant
    response_data = _token_endpoint_request(
  File "/Users/mrjones/Github/Projects/sheltr-ai/apps/api/.venv/lib/python3.9/site-packages/google/oauth2/_client.py", line 279, in _token_endpoint_request
    _handle_error_response(response_data, retryable_error)
  File "/Users/mrjones/Github/Projects/sheltr-ai/apps/api/.venv/lib/python3.9/site-packages/google/oauth2/_client.py", line 72, in _handle_error_response
    raise exceptions.RefreshError(
google.auth.exceptions.RefreshError: ('invalid_grant: Invalid JWT Signature.', {'error': 'invalid_grant', 'error_description': 'Invalid JWT Signature.'})
ERROR:grpc._plugin_wrapping:AuthMetadataPluginCallback "<google.auth.transport.grpc.AuthMetadataPlugin object at 0x103e29b20>" raised exception!
Traceback (most recent call last):
  File "/Users/mrjones/Github/Projects/sheltr-ai/apps/api/.venv/lib/python3.9/site-packages/grpc/_plugin_wrapping.py", line 105, in __call__
    self._metadata_plugin(
  File "/Users/mrjones/Github/Projects/sheltr-ai/apps/api/.venv/lib/python3.9/site-packages/google/auth/transport/grpc.py", line 95, in __call__
    callback(self._get_authorization_headers(context), None)
  File "/Users/mrjones/Github/Projects/sheltr-ai/apps/api/.venv/lib/python3.9/site-packages/google/auth/transport/grpc.py", line 81, in _get_authorization_headers
    self._credentials.before_request(
  File "/Users/mrjones/Github/Projects/sheltr-ai/apps/api/.venv/lib/python3.9/site-packages/google/auth/credentials.py", line 175, in before_request
    self.refresh(request)
  File "/Users/mrjones/Github/Projects/sheltr-ai/apps/api/.venv/lib/python3.9/site-packages/google/oauth2/service_account.py", line 449, in refresh
    access_token, expiry, _ = _client.jwt_grant(
  File "/Users/mrjones/Github/Projects/sheltr-ai/apps/api/.venv/lib/python3.9/site-packages/google/oauth2/_client.py", line 308, in jwt_grant
    response_data = _token_endpoint_request(
  File "/Users/mrjones/Github/Projects/sheltr-ai/apps/api/.venv/lib/python3.9/site-packages/google/oauth2/_client.py", line 279, in _token_endpoint_request
    _handle_error_response(response_data, retryable_error)
  File "/Users/mrjones/Github/Projects/sheltr-ai/apps/api/.venv/lib/python3.9/site-packages/google/oauth2/_client.py", line 72, in _handle_error_response
    raise exceptions.RefreshError(
google.auth.exceptions.RefreshError: ('invalid_grant: Invalid JWT Signature.', {'error': 'invalid_grant', 'error_description': 'Invalid JWT Signature.'})
ERROR:grpc._plugin_wrapping:AuthMetadataPluginCallback "<google.auth.transport.grpc.AuthMetadataPlugin object at 0x103e29b20>" raised exception!
Traceback (most recent call last):
  File "/Users/mrjones/Github/Projects/sheltr-ai/apps/api/.venv/lib/python3.9/site-packages/grpc/_plugin_wrapping.py", line 105, in __call__
    self._metadata_plugin(
  File "/Users/mrjones/Github/Projects/sheltr-ai/apps/api/.venv/lib/python3.9/site-packages/google/auth/transport/grpc.py", line 95, in __call__
    callback(self._get_authorization_headers(context), None)
  File "/Users/mrjones/Github/Projects/sheltr-ai/apps/api/.venv/lib/python3.9/site-packages/google/auth/transport/grpc.py", line 81, in _get_authorization_headers
    self._credentials.before_request(
  File "/Users/mrjones/Github/Projects/sheltr-ai/apps/api/.venv/lib/python3.9/site-packages/google/auth/credentials.py", line 175, in before_request
    self.refresh(request)
  File "/Users/mrjones/Github/Projects/sheltr-ai/apps/api/.venv/lib/python3.9/site-packages/google/oauth2/service_account.py", line 449, in refresh
    access_token, expiry, _ = _client.jwt_grant(
  File "/Users/mrjones/Github/Projects/sheltr-ai/apps/api/.venv/lib/python3.9/site-packages/google/oauth2/_client.py", line 308, in jwt_grant
    response_data = _token_endpoint_request(
  File "/Users/mrjones/Github/Projects/sheltr-ai/apps/api/.venv/lib/python3.9/site-packages/google/oauth2/_client.py", line 279, in _token_endpoint_request
    _handle_error_response(response_data, retryable_error)
  File "/Users/mrjones/Github/Projects/sheltr-ai/apps/api/.venv/lib/python3.9/site-packages/google/oauth2/_client.py", line 72, in _handle_error_response
    raise exceptions.RefreshError(
google.auth.exceptions.RefreshError: ('invalid_grant: Invalid JWT Signature.', {'error': 'invalid_grant', 'error_description': 'Invalid JWT Signature.'})
ERROR:grpc._plugin_wrapping:AuthMetadataPluginCallback "<google.auth.transport.grpc.AuthMetadataPlugin object at 0x103e29b20>" raised exception!
Traceback (most recent call last):
  File "/Users/mrjones/Github/Projects/sheltr-ai/apps/api/.venv/lib/python3.9/site-packages/grpc/_plugin_wrapping.py", line 105, in __call__
    self._metadata_plugin(
  File "/Users/mrjones/Github/Projects/sheltr-ai/apps/api/.venv/lib/python3.9/site-packages/google/auth/transport/grpc.py", line 95, in __call__
    callback(self._get_authorization_headers(context), None)
  File "/Users/mrjones/Github/Projects/sheltr-ai/apps/api/.venv/lib/python3.9/site-packages/google/auth/transport/grpc.py", line 81, in _get_authorization_headers
    self._credentials.before_request(
  File "/Users/mrjones/Github/Projects/sheltr-ai/apps/api/.venv/lib/python3.9/site-packages/google/auth/credentials.py", line 175, in before_request
    self.refresh(request)
  File "/Users/mrjones/Github/Projects/sheltr-ai/apps/api/.venv/lib/python3.9/site-packages/google/oauth2/service_account.py", line 449, in refresh
    access_token, expiry, _ = _client.jwt_grant(
  File "/Users/mrjones/Github/Projects/sheltr-ai/apps/api/.venv/lib/python3.9/site-packages/google/oauth2/_client.py", line 308, in jwt_grant
    response_data = _token_endpoint_request(
  File "/Users/mrjones/Github/Projects/sheltr-ai/apps/api/.venv/lib/python3.9/site-packages/google/oauth2/_client.py", line 279, in _token_endpoint_request
    _handle_error_response(response_data, retryable_error)
  File "/Users/mrjones/Github/Projects/sheltr-ai/apps/api/.venv/lib/python3.9/site-packages/google/oauth2/_client.py", line 72, in _handle_error_response
    raise exceptions.RefreshError(
google.auth.exceptions.RefreshError: ('invalid_grant: Invalid JWT Signature.', {'error': 'invalid_grant', 'error_description': 'Invalid JWT Signature.'})
ERROR:grpc._plugin_wrapping:AuthMetadataPluginCallback "<google.auth.transport.grpc.AuthMetadataPlugin object at 0x103e29b20>" raised exception!
Traceback (most recent call last):
  File "/Users/mrjones/Github/Projects/sheltr-ai/apps/api/.venv/lib/python3.9/site-packages/grpc/_plugin_wrapping.py", line 105, in __call__
    self._metadata_plugin(
  File "/Users/mrjones/Github/Projects/sheltr-ai/apps/api/.venv/lib/python3.9/site-packages/google/auth/transport/grpc.py", line 95, in __call__
    callback(self._get_authorization_headers(context), None)
  File "/Users/mrjones/Github/Projects/sheltr-ai/apps/api/.venv/lib/python3.9/site-packages/google/auth/transport/grpc.py", line 81, in _get_authorization_headers
    self._credentials.before_request(
  File "/Users/mrjones/Github/Projects/sheltr-ai/apps/api/.venv/lib/python3.9/site-packages/google/auth/credentials.py", line 175, in before_request
    self.refresh(request)
  File "/Users/mrjones/Github/Projects/sheltr-ai/apps/api/.venv/lib/python3.9/site-packages/google/oauth2/service_account.py", line 449, in refresh
    access_token, expiry, _ = _client.jwt_grant(
  File "/Users/mrjones/Github/Projects/sheltr-ai/apps/api/.venv/lib/python3.9/site-packages/google/oauth2/_client.py", line 308, in jwt_grant
    response_data = _token_endpoint_request(
  File "/Users/mrjones/Github/Projects/sheltr-ai/apps/api/.venv/lib/python3.9/site-packages/google/oauth2/_client.py", line 279, in _token_endpoint_request
    _handle_error_response(response_data, retryable_error)
  File "/Users/mrjones/Github/Projects/sheltr-ai/apps/api/.venv/lib/python3.9/site-packages/google/oauth2/_client.py", line 72, in _handle_error_response
    raise exceptions.RefreshError(
google.auth.exceptions.RefreshError: ('invalid_grant: Invalid JWT Signature.', {'error': 'invalid_grant', 'error_description': 'Invalid JWT Signature.'})
ERROR:services.analytics_service:Error tracking event: Timeout of 60.0s exceeded, last exception: 503 Getting metadata from plugin failed with error: ('invalid_grant: Invalid JWT Signature.', {'error': 'invalid_grant', 'error_description': 'Invalid JWT Signature.'})
WARNING:main:Slow request: POST http://localhost:8000/chatbot/message took 49.14s
INFO:     127.0.0.1:50905 - "POST /chatbot/message HTTP/1.1" 200 OK
INFO:watchfiles.main:1 change detected
WARNING:  WatchFiles detected changes in 'routers/chatbot.py'. Reloading...
INFO:     Shutting down
INFO:     Waiting for application shutdown.
INFO:main:üõë SHELTR-AI API shutting down...
INFO:     Application shutdown complete.
INFO:     Finished server process [88201]
/Users/mrjones/Github/Projects/sheltr-ai/apps/api/.venv/lib/python3.9/site-packages/urllib3/__init__.py:35: NotOpenSSLWarning: urllib3 v2 only supports OpenSSL 1.1.1+, currently the 'ssl' module is compiled with 'LibreSSL 2.8.3'. See: https://github.com/urllib3/urllib3/issues/3020
  warnings.warn(
INFO:services.chatbot.orchestrator:ü§ñ Chatbot Orchestrator initialized
INFO:     Started server process [89429]
INFO:     Waiting for application startup.
INFO:main:üöÄ SHELTR-AI API starting up...
INFO:main:üîê Authentication system initialized
INFO:main:üè¢ Multi-tenant architecture ready
INFO:     Application startup complete.
INFO:routers.chatbot:TEST: Chat message from super_admin user test@example.com: Hello, can you help me?...
INFO:services.chatbot.orchestrator:Processing message from super_admin user test_user: information
INFO:     127.0.0.1:52419 - "POST /chatbot/test-message HTTP/1.1" 200 OK
INFO:routers.chatbot:TEST: Chat message from super_admin user test@example.com: This is an emergency, I need help now!...
INFO:services.chatbot.orchestrator:Processing message from super_admin user test_user: emergency
WARNING:services.chatbot.orchestrator:Escalation triggered for user test_user: emergency
INFO:     127.0.0.1:52469 - "POST /chatbot/test-message HTTP/1.1" 200 OK
INFO:     127.0.0.1:52748 - "OPTIONS /chatbot/test-message HTTP/1.1" 200 OK
INFO:routers.chatbot:TEST: Chat message from super_admin user test@example.com: Hello, can you help me?...
INFO:services.chatbot.orchestrator:Processing message from super_admin user test_user: information
INFO:     127.0.0.1:52748 - "POST /chatbot/test-message HTTP/1.1" 200 OK
INFO:routers.chatbot:TEST: Chat message from super_admin user test@example.com: This is an emergency...
INFO:services.chatbot.orchestrator:Processing message from super_admin user test_user: emergency
WARNING:services.chatbot.orchestrator:Escalation triggered for user test_user: emergency
INFO:     127.0.0.1:52850 - "POST /chatbot/test-message HTTP/1.1" 200 OK
INFO:     127.0.0.1:53412 - "OPTIONS /analytics/platform HTTP/1.1" 200 OK
INFO:     127.0.0.1:53414 - "OPTIONS /analytics/platform HTTP/1.1" 200 OK
INFO:routers.analytics:Super Admin joel.yaffe@gmail.com requested platform analytics
ERROR:grpc._plugin_wrapping:AuthMetadataPluginCallback "<google.auth.transport.grpc.AuthMetadataPlugin object at 0x107d00250>" raised exception!
Traceback (most recent call last):
  File "/Users/mrjones/Github/Projects/sheltr-ai/apps/api/.venv/lib/python3.9/site-packages/grpc/_plugin_wrapping.py", line 105, in __call__
    self._metadata_plugin(
  File "/Users/mrjones/Github/Projects/sheltr-ai/apps/api/.venv/lib/python3.9/site-packages/google/auth/transport/grpc.py", line 95, in __call__
    callback(self._get_authorization_headers(context), None)
  File "/Users/mrjones/Github/Projects/sheltr-ai/apps/api/.venv/lib/python3.9/site-packages/google/auth/transport/grpc.py", line 81, in _get_authorization_headers
    self._credentials.before_request(
  File "/Users/mrjones/Github/Projects/sheltr-ai/apps/api/.venv/lib/python3.9/site-packages/google/auth/credentials.py", line 175, in before_request
    self.refresh(request)
  File "/Users/mrjones/Github/Projects/sheltr-ai/apps/api/.venv/lib/python3.9/site-packages/google/oauth2/service_account.py", line 449, in refresh
    access_token, expiry, _ = _client.jwt_grant(
  File "/Users/mrjones/Github/Projects/sheltr-ai/apps/api/.venv/lib/python3.9/site-packages/google/oauth2/_client.py", line 308, in jwt_grant
    response_data = _token_endpoint_request(
  File "/Users/mrjones/Github/Projects/sheltr-ai/apps/api/.venv/lib/python3.9/site-packages/google/oauth2/_client.py", line 279, in _token_endpoint_request
    _handle_error_response(response_data, retryable_error)
  File "/Users/mrjones/Github/Projects/sheltr-ai/apps/api/.venv/lib/python3.9/site-packages/google/oauth2/_client.py", line 72, in _handle_error_response
    raise exceptions.RefreshError(
google.auth.exceptions.RefreshError: ('invalid_grant: Invalid JWT Signature.', {'error': 'invalid_grant', 'error_description': 'Invalid JWT Signature.'})
ERROR:grpc._plugin_wrapping:AuthMetadataPluginCallback "<google.auth.transport.grpc.AuthMetadataPlugin object at 0x107d00250>" raised exception!
Traceback (most recent call last):
  File "/Users/mrjones/Github/Projects/sheltr-ai/apps/api/.venv/lib/python3.9/site-packages/grpc/_plugin_wrapping.py", line 105, in __call__
    self._metadata_plugin(
  File "/Users/mrjones/Github/Projects/sheltr-ai/apps/api/.venv/lib/python3.9/site-packages/google/auth/transport/grpc.py", line 95, in __call__
    callback(self._get_authorization_headers(context), None)
  File "/Users/mrjones/Github/Projects/sheltr-ai/apps/api/.venv/lib/python3.9/site-packages/google/auth/transport/grpc.py", line 81, in _get_authorization_headers
    self._credentials.before_request(
  File "/Users/mrjones/Github/Projects/sheltr-ai/apps/api/.venv/lib/python3.9/site-packages/google/auth/credentials.py", line 175, in before_request
    self.refresh(request)
  File "/Users/mrjones/Github/Projects/sheltr-ai/apps/api/.venv/lib/python3.9/site-packages/google/oauth2/service_account.py", line 449, in refresh
    access_token, expiry, _ = _client.jwt_grant(
  File "/Users/mrjones/Github/Projects/sheltr-ai/apps/api/.venv/lib/python3.9/site-packages/google/oauth2/_client.py", line 308, in jwt_grant
    response_data = _token_endpoint_request(
  File "/Users/mrjones/Github/Projects/sheltr-ai/apps/api/.venv/lib/python3.9/site-packages/google/oauth2/_client.py", line 279, in _token_endpoint_request
    _handle_error_response(response_data, retryable_error)
  File "/Users/mrjones/Github/Projects/sheltr-ai/apps/api/.venv/lib/python3.9/site-packages/google/oauth2/_client.py", line 72, in _handle_error_response
    raise exceptions.RefreshError(
google.auth.exceptions.RefreshError: ('invalid_grant: Invalid JWT Signature.', {'error': 'invalid_grant', 'error_description': 'Invalid JWT Signature.'})
ERROR:grpc._plugin_wrapping:AuthMetadataPluginCallback "<google.auth.transport.grpc.AuthMetadataPlugin object at 0x107d00250>" raised exception!
Traceback (most recent call last):
  File "/Users/mrjones/Github/Projects/sheltr-ai/apps/api/.venv/lib/python3.9/site-packages/grpc/_plugin_wrapping.py", line 105, in __call__
    self._metadata_plugin(
  File "/Users/mrjones/Github/Projects/sheltr-ai/apps/api/.venv/lib/python3.9/site-packages/google/auth/transport/grpc.py", line 95, in __call__
    callback(self._get_authorization_headers(context), None)
  File "/Users/mrjones/Github/Projects/sheltr-ai/apps/api/.venv/lib/python3.9/site-packages/google/auth/transport/grpc.py", line 81, in _get_authorization_headers
    self._credentials.before_request(
  File "/Users/mrjones/Github/Projects/sheltr-ai/apps/api/.venv/lib/python3.9/site-packages/google/auth/credentials.py", line 175, in before_request
    self.refresh(request)
  File "/Users/mrjones/Github/Projects/sheltr-ai/apps/api/.venv/lib/python3.9/site-packages/google/oauth2/service_account.py", line 449, in refresh
    access_token, expiry, _ = _client.jwt_grant(
  File "/Users/mrjones/Github/Projects/sheltr-ai/apps/api/.venv/lib/python3.9/site-packages/google/oauth2/_client.py", line 308, in jwt_grant
    response_data = _token_endpoint_request(
  File "/Users/mrjones/Github/Projects/sheltr-ai/apps/api/.venv/lib/python3.9/site-packages/google/oauth2/_client.py", line 279, in _token_endpoint_request
    _handle_error_response(response_data, retryable_error)
  File "/Users/mrjones/Github/Projects/sheltr-ai/apps/api/.venv/lib/python3.9/site-packages/google/oauth2/_client.py", line 72, in _handle_error_response
    raise exceptions.RefreshError(
google.auth.exceptions.RefreshError: ('invalid_grant: Invalid JWT Signature.', {'error': 'invalid_grant', 'error_description': 'Invalid JWT Signature.'})
ERROR:grpc._plugin_wrapping:AuthMetadataPluginCallback "<google.auth.transport.grpc.AuthMetadataPlugin object at 0x107d00250>" raised exception!
Traceback (most recent call last):
  File "/Users/mrjones/Github/Projects/sheltr-ai/apps/api/.venv/lib/python3.9/site-packages/grpc/_plugin_wrapping.py", line 105, in __call__
    self._metadata_plugin(
  File "/Users/mrjones/Github/Projects/sheltr-ai/apps/api/.venv/lib/python3.9/site-packages/google/auth/transport/grpc.py", line 95, in __call__
    callback(self._get_authorization_headers(context), None)
  File "/Users/mrjones/Github/Projects/sheltr-ai/apps/api/.venv/lib/python3.9/site-packages/google/auth/transport/grpc.py", line 81, in _get_authorization_headers
    self._credentials.before_request(
  File "/Users/mrjones/Github/Projects/sheltr-ai/apps/api/.venv/lib/python3.9/site-packages/google/auth/credentials.py", line 175, in before_request
    self.refresh(request)
  File "/Users/mrjones/Github/Projects/sheltr-ai/apps/api/.venv/lib/python3.9/site-packages/google/oauth2/service_account.py", line 449, in refresh
    access_token, expiry, _ = _client.jwt_grant(
  File "/Users/mrjones/Github/Projects/sheltr-ai/apps/api/.venv/lib/python3.9/site-packages/google/oauth2/_client.py", line 308, in jwt_grant
    response_data = _token_endpoint_request(
  File "/Users/mrjones/Github/Projects/sheltr-ai/apps/api/.venv/lib/python3.9/site-packages/google/oauth2/_client.py", line 279, in _token_endpoint_request
    _handle_error_response(response_data, retryable_error)
  File "/Users/mrjones/Github/Projects/sheltr-ai/apps/api/.venv/lib/python3.9/site-packages/google/oauth2/_client.py", line 72, in _handle_error_response
    raise exceptions.RefreshError(
google.auth.exceptions.RefreshError: ('invalid_grant: Invalid JWT Signature.', {'error': 'invalid_grant', 'error_description': 'Invalid JWT Signature.'})
ERROR:grpc._plugin_wrapping:AuthMetadataPluginCallback "<google.auth.transport.grpc.AuthMetadataPlugin object at 0x107d00250>" raised exception!
Traceback (most recent call last):
  File "/Users/mrjones/Github/Projects/sheltr-ai/apps/api/.venv/lib/python3.9/site-packages/grpc/_plugin_wrapping.py", line 105, in __call__
    self._metadata_plugin(
  File "/Users/mrjones/Github/Projects/sheltr-ai/apps/api/.venv/lib/python3.9/site-packages/google/auth/transport/grpc.py", line 95, in __call__
    callback(self._get_authorization_headers(context), None)
  File "/Users/mrjones/Github/Projects/sheltr-ai/apps/api/.venv/lib/python3.9/site-packages/google/auth/transport/grpc.py", line 81, in _get_authorization_headers
    self._credentials.before_request(
  File "/Users/mrjones/Github/Projects/sheltr-ai/apps/api/.venv/lib/python3.9/site-packages/google/auth/credentials.py", line 175, in before_request
    self.refresh(request)
  File "/Users/mrjones/Github/Projects/sheltr-ai/apps/api/.venv/lib/python3.9/site-packages/google/oauth2/service_account.py", line 449, in refresh
    access_token, expiry, _ = _client.jwt_grant(
  File "/Users/mrjones/Github/Projects/sheltr-ai/apps/api/.venv/lib/python3.9/site-packages/google/oauth2/_client.py", line 308, in jwt_grant
    response_data = _token_endpoint_request(
  File "/Users/mrjones/Github/Projects/sheltr-ai/apps/api/.venv/lib/python3.9/site-packages/google/oauth2/_client.py", line 279, in _token_endpoint_request
    _handle_error_response(response_data, retryable_error)
  File "/Users/mrjones/Github/Projects/sheltr-ai/apps/api/.venv/lib/python3.9/site-packages/google/oauth2/_client.py", line 72, in _handle_error_response
    raise exceptions.RefreshError(
google.auth.exceptions.RefreshError: ('invalid_grant: Invalid JWT Signature.', {'error': 'invalid_grant', 'error_description': 'Invalid JWT Signature.'})
ERROR:grpc._plugin_wrapping:AuthMetadataPluginCallback "<google.auth.transport.grpc.AuthMetadataPlugin object at 0x107d00250>" raised exception!
Traceback (most recent call last):
  File "/Users/mrjones/Github/Projects/sheltr-ai/apps/api/.venv/lib/python3.9/site-packages/grpc/_plugin_wrapping.py", line 105, in __call__
    self._metadata_plugin(
  File "/Users/mrjones/Github/Projects/sheltr-ai/apps/api/.venv/lib/python3.9/site-packages/google/auth/transport/grpc.py", line 95, in __call__
    callback(self._get_authorization_headers(context), None)
  File "/Users/mrjones/Github/Projects/sheltr-ai/apps/api/.venv/lib/python3.9/site-packages/google/auth/transport/grpc.py", line 81, in _get_authorization_headers
    self._credentials.before_request(
  File "/Users/mrjones/Github/Projects/sheltr-ai/apps/api/.venv/lib/python3.9/site-packages/google/auth/credentials.py", line 175, in before_request
    self.refresh(request)
  File "/Users/mrjones/Github/Projects/sheltr-ai/apps/api/.venv/lib/python3.9/site-packages/google/oauth2/service_account.py", line 449, in refresh
    access_token, expiry, _ = _client.jwt_grant(
  File "/Users/mrjones/Github/Projects/sheltr-ai/apps/api/.venv/lib/python3.9/site-packages/google/oauth2/_client.py", line 308, in jwt_grant
    response_data = _token_endpoint_request(
  File "/Users/mrjones/Github/Projects/sheltr-ai/apps/api/.venv/lib/python3.9/site-packages/google/oauth2/_client.py", line 279, in _token_endpoint_request
    _handle_error_response(response_data, retryable_error)
  File "/Users/mrjones/Github/Projects/sheltr-ai/apps/api/.venv/lib/python3.9/site-packages/google/oauth2/_client.py", line 72, in _handle_error_response
    raise exceptions.RefreshError(
google.auth.exceptions.RefreshError: ('invalid_grant: Invalid JWT Signature.', {'error': 'invalid_grant', 'error_description': 'Invalid JWT Signature.'})
ERROR:grpc._plugin_wrapping:AuthMetadataPluginCallback "<google.auth.transport.grpc.AuthMetadataPlugin object at 0x107d00250>" raised exception!
Traceback (most recent call last):
  File "/Users/mrjones/Github/Projects/sheltr-ai/apps/api/.venv/lib/python3.9/site-packages/grpc/_plugin_wrapping.py", line 105, in __call__
    self._metadata_plugin(
  File "/Users/mrjones/Github/Projects/sheltr-ai/apps/api/.venv/lib/python3.9/site-packages/google/auth/transport/grpc.py", line 95, in __call__
    callback(self._get_authorization_headers(context), None)
  File "/Users/mrjones/Github/Projects/sheltr-ai/apps/api/.venv/lib/python3.9/site-packages/google/auth/transport/grpc.py", line 81, in _get_authorization_headers
    self._credentials.before_request(
  File "/Users/mrjones/Github/Projects/sheltr-ai/apps/api/.venv/lib/python3.9/site-packages/google/auth/credentials.py", line 175, in before_request
    self.refresh(request)
  File "/Users/mrjones/Github/Projects/sheltr-ai/apps/api/.venv/lib/python3.9/site-packages/google/oauth2/service_account.py", line 449, in refresh
    access_token, expiry, _ = _client.jwt_grant(
  File "/Users/mrjones/Github/Projects/sheltr-ai/apps/api/.venv/lib/python3.9/site-packages/google/oauth2/_client.py", line 308, in jwt_grant
    response_data = _token_endpoint_request(
  File "/Users/mrjones/Github/Projects/sheltr-ai/apps/api/.venv/lib/python3.9/site-packages/google/oauth2/_client.py", line 279, in _token_endpoint_request
    _handle_error_response(response_data, retryable_error)
  File "/Users/mrjones/Github/Projects/sheltr-ai/apps/api/.venv/lib/python3.9/site-packages/google/oauth2/_client.py", line 72, in _handle_error_response
    raise exceptions.RefreshError(
google.auth.exceptions.RefreshError: ('invalid_grant: Invalid JWT Signature.', {'error': 'invalid_grant', 'error_description': 'Invalid JWT Signature.'})
ERROR:grpc._plugin_wrapping:AuthMetadataPluginCallback "<google.auth.transport.grpc.AuthMetadataPlugin object at 0x107d00250>" raised exception!
Traceback (most recent call last):
  File "/Users/mrjones/Github/Projects/sheltr-ai/apps/api/.venv/lib/python3.9/site-packages/grpc/_plugin_wrapping.py", line 105, in __call__
    self._metadata_plugin(
  File "/Users/mrjones/Github/Projects/sheltr-ai/apps/api/.venv/lib/python3.9/site-packages/google/auth/transport/grpc.py", line 95, in __call__
    callback(self._get_authorization_headers(context), None)
  File "/Users/mrjones/Github/Projects/sheltr-ai/apps/api/.venv/lib/python3.9/site-packages/google/auth/transport/grpc.py", line 81, in _get_authorization_headers
    self._credentials.before_request(
  File "/Users/mrjones/Github/Projects/sheltr-ai/apps/api/.venv/lib/python3.9/site-packages/google/auth/credentials.py", line 175, in before_request
    self.refresh(request)
  File "/Users/mrjones/Github/Projects/sheltr-ai/apps/api/.venv/lib/python3.9/site-packages/google/oauth2/service_account.py", line 449, in refresh
    access_token, expiry, _ = _client.jwt_grant(
  File "/Users/mrjones/Github/Projects/sheltr-ai/apps/api/.venv/lib/python3.9/site-packages/google/oauth2/_client.py", line 308, in jwt_grant
    response_data = _token_endpoint_request(
  File "/Users/mrjones/Github/Projects/sheltr-ai/apps/api/.venv/lib/python3.9/site-packages/google/oauth2/_client.py", line 279, in _token_endpoint_request
    _handle_error_response(response_data, retryable_error)
  File "/Users/mrjones/Github/Projects/sheltr-ai/apps/api/.venv/lib/python3.9/site-packages/google/oauth2/_client.py", line 72, in _handle_error_response
    raise exceptions.RefreshError(
google.auth.exceptions.RefreshError: ('invalid_grant: Invalid JWT Signature.', {'error': 'invalid_grant', 'error_description': 'Invalid JWT Signature.'})
ERROR:grpc._plugin_wrapping:AuthMetadataPluginCallback "<google.auth.transport.grpc.AuthMetadataPlugin object at 0x107d00250>" raised exception!
Traceback (most recent call last):
  File "/Users/mrjones/Github/Projects/sheltr-ai/apps/api/.venv/lib/python3.9/site-packages/grpc/_plugin_wrapping.py", line 105, in __call__
    self._metadata_plugin(
  File "/Users/mrjones/Github/Projects/sheltr-ai/apps/api/.venv/lib/python3.9/site-packages/google/auth/transport/grpc.py", line 95, in __call__
    callback(self._get_authorization_headers(context), None)
  File "/Users/mrjones/Github/Projects/sheltr-ai/apps/api/.venv/lib/python3.9/site-packages/google/auth/transport/grpc.py", line 81, in _get_authorization_headers
    self._credentials.before_request(
  File "/Users/mrjones/Github/Projects/sheltr-ai/apps/api/.venv/lib/python3.9/site-packages/google/auth/credentials.py", line 175, in before_request
    self.refresh(request)
  File "/Users/mrjones/Github/Projects/sheltr-ai/apps/api/.venv/lib/python3.9/site-packages/google/oauth2/service_account.py", line 449, in refresh
    access_token, expiry, _ = _client.jwt_grant(
  File "/Users/mrjones/Github/Projects/sheltr-ai/apps/api/.venv/lib/python3.9/site-packages/google/oauth2/_client.py", line 308, in jwt_grant
    response_data = _token_endpoint_request(
  File "/Users/mrjones/Github/Projects/sheltr-ai/apps/api/.venv/lib/python3.9/site-packages/google/oauth2/_client.py", line 279, in _token_endpoint_request
    _handle_error_response(response_data, retryable_error)
  File "/Users/mrjones/Github/Projects/sheltr-ai/apps/api/.venv/lib/python3.9/site-packages/google/oauth2/_client.py", line 72, in _handle_error_response
    raise exceptions.RefreshError(
google.auth.exceptions.RefreshError: ('invalid_grant: Invalid JWT Signature.', {'error': 'invalid_grant', 'error_description': 'Invalid JWT Signature.'})
ERROR:grpc._plugin_wrapping:AuthMetadataPluginCallback "<google.auth.transport.grpc.AuthMetadataPlugin object at 0x107d00250>" raised exception!
Traceback (most recent call last):
  File "/Users/mrjones/Github/Projects/sheltr-ai/apps/api/.venv/lib/python3.9/site-packages/grpc/_plugin_wrapping.py", line 105, in __call__
    self._metadata_plugin(
  File "/Users/mrjones/Github/Projects/sheltr-ai/apps/api/.venv/lib/python3.9/site-packages/google/auth/transport/grpc.py", line 95, in __call__
    callback(self._get_authorization_headers(context), None)
  File "/Users/mrjones/Github/Projects/sheltr-ai/apps/api/.venv/lib/python3.9/site-packages/google/auth/transport/grpc.py", line 81, in _get_authorization_headers
    self._credentials.before_request(
  File "/Users/mrjones/Github/Projects/sheltr-ai/apps/api/.venv/lib/python3.9/site-packages/google/auth/credentials.py", line 175, in before_request
    self.refresh(request)
  File "/Users/mrjones/Github/Projects/sheltr-ai/apps/api/.venv/lib/python3.9/site-packages/google/oauth2/service_account.py", line 449, in refresh
    access_token, expiry, _ = _client.jwt_grant(
  File "/Users/mrjones/Github/Projects/sheltr-ai/apps/api/.venv/lib/python3.9/site-packages/google/oauth2/_client.py", line 308, in jwt_grant
    response_data = _token_endpoint_request(
  File "/Users/mrjones/Github/Projects/sheltr-ai/apps/api/.venv/lib/python3.9/site-packages/google/oauth2/_client.py", line 279, in _token_endpoint_request
    _handle_error_response(response_data, retryable_error)
  File "/Users/mrjones/Github/Projects/sheltr-ai/apps/api/.venv/lib/python3.9/site-packages/google/oauth2/_client.py", line 72, in _handle_error_response
    raise exceptions.RefreshError(
google.auth.exceptions.RefreshError: ('invalid_grant: Invalid JWT Signature.', {'error': 'invalid_grant', 'error_description': 'Invalid JWT Signature.'})
ERROR:grpc._plugin_wrapping:AuthMetadataPluginCallback "<google.auth.transport.grpc.AuthMetadataPlugin object at 0x107d00250>" raised exception!
Traceback (most recent call last):
  File "/Users/mrjones/Github/Projects/sheltr-ai/apps/api/.venv/lib/python3.9/site-packages/grpc/_plugin_wrapping.py", line 105, in __call__
    self._metadata_plugin(
  File "/Users/mrjones/Github/Projects/sheltr-ai/apps/api/.venv/lib/python3.9/site-packages/google/auth/transport/grpc.py", line 95, in __call__
    callback(self._get_authorization_headers(context), None)
  File "/Users/mrjones/Github/Projects/sheltr-ai/apps/api/.venv/lib/python3.9/site-packages/google/auth/transport/grpc.py", line 81, in _get_authorization_headers
    self._credentials.before_request(
  File "/Users/mrjones/Github/Projects/sheltr-ai/apps/api/.venv/lib/python3.9/site-packages/google/auth/credentials.py", line 175, in before_request
    self.refresh(request)
  File "/Users/mrjones/Github/Projects/sheltr-ai/apps/api/.venv/lib/python3.9/site-packages/google/oauth2/service_account.py", line 449, in refresh
    access_token, expiry, _ = _client.jwt_grant(
  File "/Users/mrjones/Github/Projects/sheltr-ai/apps/api/.venv/lib/python3.9/site-packages/google/oauth2/_client.py", line 308, in jwt_grant
    response_data = _token_endpoint_request(
  File "/Users/mrjones/Github/Projects/sheltr-ai/apps/api/.venv/lib/python3.9/site-packages/google/oauth2/_client.py", line 279, in _token_endpoint_request
    _handle_error_response(response_data, retryable_error)
  File "/Users/mrjones/Github/Projects/sheltr-ai/apps/api/.venv/lib/python3.9/site-packages/google/oauth2/_client.py", line 72, in _handle_error_response
    raise exceptions.RefreshError(
google.auth.exceptions.RefreshError: ('invalid_grant: Invalid JWT Signature.', {'error': 'invalid_grant', 'error_description': 'Invalid JWT Signature.'})
ERROR:grpc._plugin_wrapping:AuthMetadataPluginCallback "<google.auth.transport.grpc.AuthMetadataPlugin object at 0x107d00250>" raised exception!
Traceback (most recent call last):
  File "/Users/mrjones/Github/Projects/sheltr-ai/apps/api/.venv/lib/python3.9/site-packages/grpc/_plugin_wrapping.py", line 105, in __call__
    self._metadata_plugin(
  File "/Users/mrjones/Github/Projects/sheltr-ai/apps/api/.venv/lib/python3.9/site-packages/google/auth/transport/grpc.py", line 95, in __call__
    callback(self._get_authorization_headers(context), None)
  File "/Users/mrjones/Github/Projects/sheltr-ai/apps/api/.venv/lib/python3.9/site-packages/google/auth/transport/grpc.py", line 81, in _get_authorization_headers
    self._credentials.before_request(
  File "/Users/mrjones/Github/Projects/sheltr-ai/apps/api/.venv/lib/python3.9/site-packages/google/auth/credentials.py", line 175, in before_request
    self.refresh(request)
  File "/Users/mrjones/Github/Projects/sheltr-ai/apps/api/.venv/lib/python3.9/site-packages/google/oauth2/service_account.py", line 449, in refresh
    access_token, expiry, _ = _client.jwt_grant(
  File "/Users/mrjones/Github/Projects/sheltr-ai/apps/api/.venv/lib/python3.9/site-packages/google/oauth2/_client.py", line 308, in jwt_grant
    response_data = _token_endpoint_request(
  File "/Users/mrjones/Github/Projects/sheltr-ai/apps/api/.venv/lib/python3.9/site-packages/google/oauth2/_client.py", line 279, in _token_endpoint_request
    _handle_error_response(response_data, retryable_error)
  File "/Users/mrjones/Github/Projects/sheltr-ai/apps/api/.venv/lib/python3.9/site-packages/google/oauth2/_client.py", line 72, in _handle_error_response
    raise exceptions.RefreshError(
google.auth.exceptions.RefreshError: ('invalid_grant: Invalid JWT Signature.', {'error': 'invalid_grant', 'error_description': 'Invalid JWT Signature.'})
ERROR:grpc._plugin_wrapping:AuthMetadataPluginCallback "<google.auth.transport.grpc.AuthMetadataPlugin object at 0x107d00250>" raised exception!
Traceback (most recent call last):
  File "/Users/mrjones/Github/Projects/sheltr-ai/apps/api/.venv/lib/python3.9/site-packages/grpc/_plugin_wrapping.py", line 105, in __call__
    self._metadata_plugin(
  File "/Users/mrjones/Github/Projects/sheltr-ai/apps/api/.venv/lib/python3.9/site-packages/google/auth/transport/grpc.py", line 95, in __call__
    callback(self._get_authorization_headers(context), None)
  File "/Users/mrjones/Github/Projects/sheltr-ai/apps/api/.venv/lib/python3.9/site-packages/google/auth/transport/grpc.py", line 81, in _get_authorization_headers
    self._credentials.before_request(
  File "/Users/mrjones/Github/Projects/sheltr-ai/apps/api/.venv/lib/python3.9/site-packages/google/auth/credentials.py", line 175, in before_request
    self.refresh(request)
  File "/Users/mrjones/Github/Projects/sheltr-ai/apps/api/.venv/lib/python3.9/site-packages/google/oauth2/service_account.py", line 449, in refresh
    access_token, expiry, _ = _client.jwt_grant(
  File "/Users/mrjones/Github/Projects/sheltr-ai/apps/api/.venv/lib/python3.9/site-packages/google/oauth2/_client.py", line 308, in jwt_grant
    response_data = _token_endpoint_request(
  File "/Users/mrjones/Github/Projects/sheltr-ai/apps/api/.venv/lib/python3.9/site-packages/google/oauth2/_client.py", line 279, in _token_endpoint_request
    _handle_error_response(response_data, retryable_error)
  File "/Users/mrjones/Github/Projects/sheltr-ai/apps/api/.venv/lib/python3.9/site-packages/google/oauth2/_client.py", line 72, in _handle_error_response
    raise exceptions.RefreshError(
google.auth.exceptions.RefreshError: ('invalid_grant: Invalid JWT Signature.', {'error': 'invalid_grant', 'error_description': 'Invalid JWT Signature.'})
ERROR:grpc._plugin_wrapping:AuthMetadataPluginCallback "<google.auth.transport.grpc.AuthMetadataPlugin object at 0x107d00250>" raised exception!
Traceback (most recent call last):
  File "/Users/mrjones/Github/Projects/sheltr-ai/apps/api/.venv/lib/python3.9/site-packages/grpc/_plugin_wrapping.py", line 105, in __call__
    self._metadata_plugin(
  File "/Users/mrjones/Github/Projects/sheltr-ai/apps/api/.venv/lib/python3.9/site-packages/google/auth/transport/grpc.py", line 95, in __call__
    callback(self._get_authorization_headers(context), None)
  File "/Users/mrjones/Github/Projects/sheltr-ai/apps/api/.venv/lib/python3.9/site-packages/google/auth/transport/grpc.py", line 81, in _get_authorization_headers
    self._credentials.before_request(
  File "/Users/mrjones/Github/Projects/sheltr-ai/apps/api/.venv/lib/python3.9/site-packages/google/auth/credentials.py", line 175, in before_request
    self.refresh(request)
  File "/Users/mrjones/Github/Projects/sheltr-ai/apps/api/.venv/lib/python3.9/site-packages/google/oauth2/service_account.py", line 449, in refresh
    access_token, expiry, _ = _client.jwt_grant(
  File "/Users/mrjones/Github/Projects/sheltr-ai/apps/api/.venv/lib/python3.9/site-packages/google/oauth2/_client.py", line 308, in jwt_grant
    response_data = _token_endpoint_request(
  File "/Users/mrjones/Github/Projects/sheltr-ai/apps/api/.venv/lib/python3.9/site-packages/google/oauth2/_client.py", line 279, in _token_endpoint_request
    _handle_error_response(response_data, retryable_error)
  File "/Users/mrjones/Github/Projects/sheltr-ai/apps/api/.venv/lib/python3.9/site-packages/google/oauth2/_client.py", line 72, in _handle_error_response
    raise exceptions.RefreshError(
google.auth.exceptions.RefreshError: ('invalid_grant: Invalid JWT Signature.', {'error': 'invalid_grant', 'error_description': 'Invalid JWT Signature.'})
ERROR:grpc._plugin_wrapping:AuthMetadataPluginCallback "<google.auth.transport.grpc.AuthMetadataPlugin object at 0x107d00250>" raised exception!
Traceback (most recent call last):
  File "/Users/mrjones/Github/Projects/sheltr-ai/apps/api/.venv/lib/python3.9/site-packages/grpc/_plugin_wrapping.py", line 105, in __call__
    self._metadata_plugin(
  File "/Users/mrjones/Github/Projects/sheltr-ai/apps/api/.venv/lib/python3.9/site-packages/google/auth/transport/grpc.py", line 95, in __call__
    callback(self._get_authorization_headers(context), None)
  File "/Users/mrjones/Github/Projects/sheltr-ai/apps/api/.venv/lib/python3.9/site-packages/google/auth/transport/grpc.py", line 81, in _get_authorization_headers
    self._credentials.before_request(
  File "/Users/mrjones/Github/Projects/sheltr-ai/apps/api/.venv/lib/python3.9/site-packages/google/auth/credentials.py", line 175, in before_request
    self.refresh(request)
  File "/Users/mrjones/Github/Projects/sheltr-ai/apps/api/.venv/lib/python3.9/site-packages/google/oauth2/service_account.py", line 449, in refresh
    access_token, expiry, _ = _client.jwt_grant(
  File "/Users/mrjones/Github/Projects/sheltr-ai/apps/api/.venv/lib/python3.9/site-packages/google/oauth2/_client.py", line 308, in jwt_grant
    response_data = _token_endpoint_request(
  File "/Users/mrjones/Github/Projects/sheltr-ai/apps/api/.venv/lib/python3.9/site-packages/google/oauth2/_client.py", line 279, in _token_endpoint_request
    _handle_error_response(response_data, retryable_error)
  File "/Users/mrjones/Github/Projects/sheltr-ai/apps/api/.venv/lib/python3.9/site-packages/google/oauth2/_client.py", line 72, in _handle_error_response
    raise exceptions.RefreshError(
google.auth.exceptions.RefreshError: ('invalid_grant: Invalid JWT Signature.', {'error': 'invalid_grant', 'error_description': 'Invalid JWT Signature.'})
ERROR:grpc._plugin_wrapping:AuthMetadataPluginCallback "<google.auth.transport.grpc.AuthMetadataPlugin object at 0x107d00250>" raised exception!
Traceback (most recent call last):
  File "/Users/mrjones/Github/Projects/sheltr-ai/apps/api/.venv/lib/python3.9/site-packages/grpc/_plugin_wrapping.py", line 105, in __call__
    self._metadata_plugin(
  File "/Users/mrjones/Github/Projects/sheltr-ai/apps/api/.venv/lib/python3.9/site-packages/google/auth/transport/grpc.py", line 95, in __call__
    callback(self._get_authorization_headers(context), None)
  File "/Users/mrjones/Github/Projects/sheltr-ai/apps/api/.venv/lib/python3.9/site-packages/google/auth/transport/grpc.py", line 81, in _get_authorization_headers
    self._credentials.before_request(
  File "/Users/mrjones/Github/Projects/sheltr-ai/apps/api/.venv/lib/python3.9/site-packages/google/auth/credentials.py", line 175, in before_request
    self.refresh(request)
  File "/Users/mrjones/Github/Projects/sheltr-ai/apps/api/.venv/lib/python3.9/site-packages/google/oauth2/service_account.py", line 449, in refresh
    access_token, expiry, _ = _client.jwt_grant(
  File "/Users/mrjones/Github/Projects/sheltr-ai/apps/api/.venv/lib/python3.9/site-packages/google/oauth2/_client.py", line 308, in jwt_grant
    response_data = _token_endpoint_request(
  File "/Users/mrjones/Github/Projects/sheltr-ai/apps/api/.venv/lib/python3.9/site-packages/google/oauth2/_client.py", line 279, in _token_endpoint_request
    _handle_error_response(response_data, retryable_error)
  File "/Users/mrjones/Github/Projects/sheltr-ai/apps/api/.venv/lib/python3.9/site-packages/google/oauth2/_client.py", line 72, in _handle_error_response
    raise exceptions.RefreshError(
google.auth.exceptions.RefreshError: ('invalid_grant: Invalid JWT Signature.', {'error': 'invalid_grant', 'error_description': 'Invalid JWT Signature.'})
ERROR:grpc._plugin_wrapping:AuthMetadataPluginCallback "<google.auth.transport.grpc.AuthMetadataPlugin object at 0x107d00250>" raised exception!
Traceback (most recent call last):
  File "/Users/mrjones/Github/Projects/sheltr-ai/apps/api/.venv/lib/python3.9/site-packages/grpc/_plugin_wrapping.py", line 105, in __call__
    self._metadata_plugin(
  File "/Users/mrjones/Github/Projects/sheltr-ai/apps/api/.venv/lib/python3.9/site-packages/google/auth/transport/grpc.py", line 95, in __call__
    callback(self._get_authorization_headers(context), None)
  File "/Users/mrjones/Github/Projects/sheltr-ai/apps/api/.venv/lib/python3.9/site-packages/google/auth/transport/grpc.py", line 81, in _get_authorization_headers
    self._credentials.before_request(
  File "/Users/mrjones/Github/Projects/sheltr-ai/apps/api/.venv/lib/python3.9/site-packages/google/auth/credentials.py", line 175, in before_request
    self.refresh(request)
  File "/Users/mrjones/Github/Projects/sheltr-ai/apps/api/.venv/lib/python3.9/site-packages/google/oauth2/service_account.py", line 449, in refresh
    access_token, expiry, _ = _client.jwt_grant(
  File "/Users/mrjones/Github/Projects/sheltr-ai/apps/api/.venv/lib/python3.9/site-packages/google/oauth2/_client.py", line 308, in jwt_grant
    response_data = _token_endpoint_request(
  File "/Users/mrjones/Github/Projects/sheltr-ai/apps/api/.venv/lib/python3.9/site-packages/google/oauth2/_client.py", line 279, in _token_endpoint_request
    _handle_error_response(response_data, retryable_error)
  File "/Users/mrjones/Github/Projects/sheltr-ai/apps/api/.venv/lib/python3.9/site-packages/google/oauth2/_client.py", line 72, in _handle_error_response
    raise exceptions.RefreshError(
google.auth.exceptions.RefreshError: ('invalid_grant: Invalid JWT Signature.', {'error': 'invalid_grant', 'error_description': 'Invalid JWT Signature.'})
ERROR:grpc._plugin_wrapping:AuthMetadataPluginCallback "<google.auth.transport.grpc.AuthMetadataPlugin object at 0x107d00250>" raised exception!
Traceback (most recent call last):
  File "/Users/mrjones/Github/Projects/sheltr-ai/apps/api/.venv/lib/python3.9/site-packages/grpc/_plugin_wrapping.py", line 105, in __call__
    self._metadata_plugin(
  File "/Users/mrjones/Github/Projects/sheltr-ai/apps/api/.venv/lib/python3.9/site-packages/google/auth/transport/grpc.py", line 95, in __call__
    callback(self._get_authorization_headers(context), None)
  File "/Users/mrjones/Github/Projects/sheltr-ai/apps/api/.venv/lib/python3.9/site-packages/google/auth/transport/grpc.py", line 81, in _get_authorization_headers
    self._credentials.before_request(
  File "/Users/mrjones/Github/Projects/sheltr-ai/apps/api/.venv/lib/python3.9/site-packages/google/auth/credentials.py", line 175, in before_request
    self.refresh(request)
  File "/Users/mrjones/Github/Projects/sheltr-ai/apps/api/.venv/lib/python3.9/site-packages/google/oauth2/service_account.py", line 449, in refresh
    access_token, expiry, _ = _client.jwt_grant(
  File "/Users/mrjones/Github/Projects/sheltr-ai/apps/api/.venv/lib/python3.9/site-packages/google/oauth2/_client.py", line 308, in jwt_grant
    response_data = _token_endpoint_request(
  File "/Users/mrjones/Github/Projects/sheltr-ai/apps/api/.venv/lib/python3.9/site-packages/google/oauth2/_client.py", line 279, in _token_endpoint_request
    _handle_error_response(response_data, retryable_error)
  File "/Users/mrjones/Github/Projects/sheltr-ai/apps/api/.venv/lib/python3.9/site-packages/google/oauth2/_client.py", line 72, in _handle_error_response
    raise exceptions.RefreshError(
google.auth.exceptions.RefreshError: ('invalid_grant: Invalid JWT Signature.', {'error': 'invalid_grant', 'error_description': 'Invalid JWT Signature.'})
INFO:watchfiles.main:1 change detected
WARNING:  WatchFiles detected changes in 'services/analytics_service.py'. Reloading...
ERROR:grpc._plugin_wrapping:AuthMetadataPluginCallback "<google.auth.transport.grpc.AuthMetadataPlugin object at 0x107d00250>" raised exception!
Traceback (most recent call last):
  File "/Users/mrjones/Github/Projects/sheltr-ai/apps/api/.venv/lib/python3.9/site-packages/grpc/_plugin_wrapping.py", line 105, in __call__
    self._metadata_plugin(
  File "/Users/mrjones/Github/Projects/sheltr-ai/apps/api/.venv/lib/python3.9/site-packages/google/auth/transport/grpc.py", line 95, in __call__
    callback(self._get_authorization_headers(context), None)
  File "/Users/mrjones/Github/Projects/sheltr-ai/apps/api/.venv/lib/python3.9/site-packages/google/auth/transport/grpc.py", line 81, in _get_authorization_headers
    self._credentials.before_request(
  File "/Users/mrjones/Github/Projects/sheltr-ai/apps/api/.venv/lib/python3.9/site-packages/google/auth/credentials.py", line 175, in before_request
    self.refresh(request)
  File "/Users/mrjones/Github/Projects/sheltr-ai/apps/api/.venv/lib/python3.9/site-packages/google/oauth2/service_account.py", line 449, in refresh
    access_token, expiry, _ = _client.jwt_grant(
  File "/Users/mrjones/Github/Projects/sheltr-ai/apps/api/.venv/lib/python3.9/site-packages/google/oauth2/_client.py", line 308, in jwt_grant
    response_data = _token_endpoint_request(
  File "/Users/mrjones/Github/Projects/sheltr-ai/apps/api/.venv/lib/python3.9/site-packages/google/oauth2/_client.py", line 279, in _token_endpoint_request
    _handle_error_response(response_data, retryable_error)
  File "/Users/mrjones/Github/Projects/sheltr-ai/apps/api/.venv/lib/python3.9/site-packages/google/oauth2/_client.py", line 72, in _handle_error_response
    raise exceptions.RefreshError(
google.auth.exceptions.RefreshError: ('invalid_grant: Invalid JWT Signature.', {'error': 'invalid_grant', 'error_description': 'Invalid JWT Signature.'})
ERROR:grpc._plugin_wrapping:AuthMetadataPluginCallback "<google.auth.transport.grpc.AuthMetadataPlugin object at 0x107d00250>" raised exception!
Traceback (most recent call last):
  File "/Users/mrjones/Github/Projects/sheltr-ai/apps/api/.venv/lib/python3.9/site-packages/grpc/_plugin_wrapping.py", line 105, in __call__
    self._metadata_plugin(
  File "/Users/mrjones/Github/Projects/sheltr-ai/apps/api/.venv/lib/python3.9/site-packages/google/auth/transport/grpc.py", line 95, in __call__
    callback(self._get_authorization_headers(context), None)
  File "/Users/mrjones/Github/Projects/sheltr-ai/apps/api/.venv/lib/python3.9/site-packages/google/auth/transport/grpc.py", line 81, in _get_authorization_headers
    self._credentials.before_request(
  File "/Users/mrjones/Github/Projects/sheltr-ai/apps/api/.venv/lib/python3.9/site-packages/google/auth/credentials.py", line 175, in before_request
    self.refresh(request)
  File "/Users/mrjones/Github/Projects/sheltr-ai/apps/api/.venv/lib/python3.9/site-packages/google/oauth2/service_account.py", line 449, in refresh
    access_token, expiry, _ = _client.jwt_grant(
  File "/Users/mrjones/Github/Projects/sheltr-ai/apps/api/.venv/lib/python3.9/site-packages/google/oauth2/_client.py", line 308, in jwt_grant
    response_data = _token_endpoint_request(
  File "/Users/mrjones/Github/Projects/sheltr-ai/apps/api/.venv/lib/python3.9/site-packages/google/oauth2/_client.py", line 279, in _token_endpoint_request
    _handle_error_response(response_data, retryable_error)
  File "/Users/mrjones/Github/Projects/sheltr-ai/apps/api/.venv/lib/python3.9/site-packages/google/oauth2/_client.py", line 72, in _handle_error_response
    raise exceptions.RefreshError(
google.auth.exceptions.RefreshError: ('invalid_grant: Invalid JWT Signature.', {'error': 'invalid_grant', 'error_description': 'Invalid JWT Signature.'})
ERROR:grpc._plugin_wrapping:AuthMetadataPluginCallback "<google.auth.transport.grpc.AuthMetadataPlugin object at 0x107d00250>" raised exception!
Traceback (most recent call last):
  File "/Users/mrjones/Github/Projects/sheltr-ai/apps/api/.venv/lib/python3.9/site-packages/grpc/_plugin_wrapping.py", line 105, in __call__
    self._metadata_plugin(
  File "/Users/mrjones/Github/Projects/sheltr-ai/apps/api/.venv/lib/python3.9/site-packages/google/auth/transport/grpc.py", line 95, in __call__
    callback(self._get_authorization_headers(context), None)
  File "/Users/mrjones/Github/Projects/sheltr-ai/apps/api/.venv/lib/python3.9/site-packages/google/auth/transport/grpc.py", line 81, in _get_authorization_headers
    self._credentials.before_request(
  File "/Users/mrjones/Github/Projects/sheltr-ai/apps/api/.venv/lib/python3.9/site-packages/google/auth/credentials.py", line 175, in before_request
    self.refresh(request)
  File "/Users/mrjones/Github/Projects/sheltr-ai/apps/api/.venv/lib/python3.9/site-packages/google/oauth2/service_account.py", line 449, in refresh
    access_token, expiry, _ = _client.jwt_grant(
  File "/Users/mrjones/Github/Projects/sheltr-ai/apps/api/.venv/lib/python3.9/site-packages/google/oauth2/_client.py", line 308, in jwt_grant
    response_data = _token_endpoint_request(
  File "/Users/mrjones/Github/Projects/sheltr-ai/apps/api/.venv/lib/python3.9/site-packages/google/oauth2/_client.py", line 279, in _token_endpoint_request
    _handle_error_response(response_data, retryable_error)
  File "/Users/mrjones/Github/Projects/sheltr-ai/apps/api/.venv/lib/python3.9/site-packages/google/oauth2/_client.py", line 72, in _handle_error_response
    raise exceptions.RefreshError(
google.auth.exceptions.RefreshError: ('invalid_grant: Invalid JWT Signature.', {'error': 'invalid_grant', 'error_description': 'Invalid JWT Signature.'})
ERROR:grpc._plugin_wrapping:AuthMetadataPluginCallback "<google.auth.transport.grpc.AuthMetadataPlugin object at 0x107d00250>" raised exception!
Traceback (most recent call last):
  File "/Users/mrjones/Github/Projects/sheltr-ai/apps/api/.venv/lib/python3.9/site-packages/grpc/_plugin_wrapping.py", line 105, in __call__
    self._metadata_plugin(
  File "/Users/mrjones/Github/Projects/sheltr-ai/apps/api/.venv/lib/python3.9/site-packages/google/auth/transport/grpc.py", line 95, in __call__
    callback(self._get_authorization_headers(context), None)
  File "/Users/mrjones/Github/Projects/sheltr-ai/apps/api/.venv/lib/python3.9/site-packages/google/auth/transport/grpc.py", line 81, in _get_authorization_headers
    self._credentials.before_request(
  File "/Users/mrjones/Github/Projects/sheltr-ai/apps/api/.venv/lib/python3.9/site-packages/google/auth/credentials.py", line 175, in before_request
    self.refresh(request)
  File "/Users/mrjones/Github/Projects/sheltr-ai/apps/api/.venv/lib/python3.9/site-packages/google/oauth2/service_account.py", line 449, in refresh
    access_token, expiry, _ = _client.jwt_grant(
  File "/Users/mrjones/Github/Projects/sheltr-ai/apps/api/.venv/lib/python3.9/site-packages/google/oauth2/_client.py", line 308, in jwt_grant
    response_data = _token_endpoint_request(
  File "/Users/mrjones/Github/Projects/sheltr-ai/apps/api/.venv/lib/python3.9/site-packages/google/oauth2/_client.py", line 279, in _token_endpoint_request
    _handle_error_response(response_data, retryable_error)
  File "/Users/mrjones/Github/Projects/sheltr-ai/apps/api/.venv/lib/python3.9/site-packages/google/oauth2/_client.py", line 72, in _handle_error_response
    raise exceptions.RefreshError(
google.auth.exceptions.RefreshError: ('invalid_grant: Invalid JWT Signature.', {'error': 'invalid_grant', 'error_description': 'Invalid JWT Signature.'})
ERROR:grpc._plugin_wrapping:AuthMetadataPluginCallback "<google.auth.transport.grpc.AuthMetadataPlugin object at 0x107d00250>" raised exception!
Traceback (most recent call last):
  File "/Users/mrjones/Github/Projects/sheltr-ai/apps/api/.venv/lib/python3.9/site-packages/grpc/_plugin_wrapping.py", line 105, in __call__
    self._metadata_plugin(
  File "/Users/mrjones/Github/Projects/sheltr-ai/apps/api/.venv/lib/python3.9/site-packages/google/auth/transport/grpc.py", line 95, in __call__
    callback(self._get_authorization_headers(context), None)
  File "/Users/mrjones/Github/Projects/sheltr-ai/apps/api/.venv/lib/python3.9/site-packages/google/auth/transport/grpc.py", line 81, in _get_authorization_headers
    self._credentials.before_request(
  File "/Users/mrjones/Github/Projects/sheltr-ai/apps/api/.venv/lib/python3.9/site-packages/google/auth/credentials.py", line 175, in before_request
    self.refresh(request)
  File "/Users/mrjones/Github/Projects/sheltr-ai/apps/api/.venv/lib/python3.9/site-packages/google/oauth2/service_account.py", line 449, in refresh
    access_token, expiry, _ = _client.jwt_grant(
  File "/Users/mrjones/Github/Projects/sheltr-ai/apps/api/.venv/lib/python3.9/site-packages/google/oauth2/_client.py", line 308, in jwt_grant
    response_data = _token_endpoint_request(
  File "/Users/mrjones/Github/Projects/sheltr-ai/apps/api/.venv/lib/python3.9/site-packages/google/oauth2/_client.py", line 279, in _token_endpoint_request
    _handle_error_response(response_data, retryable_error)
  File "/Users/mrjones/Github/Projects/sheltr-ai/apps/api/.venv/lib/python3.9/site-packages/google/oauth2/_client.py", line 72, in _handle_error_response
    raise exceptions.RefreshError(
google.auth.exceptions.RefreshError: ('invalid_grant: Invalid JWT Signature.', {'error': 'invalid_grant', 'error_description': 'Invalid JWT Signature.'})
ERROR:grpc._plugin_wrapping:AuthMetadataPluginCallback "<google.auth.transport.grpc.AuthMetadataPlugin object at 0x107d00250>" raised exception!
Traceback (most recent call last):
  File "/Users/mrjones/Github/Projects/sheltr-ai/apps/api/.venv/lib/python3.9/site-packages/grpc/_plugin_wrapping.py", line 105, in __call__
    self._metadata_plugin(
  File "/Users/mrjones/Github/Projects/sheltr-ai/apps/api/.venv/lib/python3.9/site-packages/google/auth/transport/grpc.py", line 95, in __call__
    callback(self._get_authorization_headers(context), None)
  File "/Users/mrjones/Github/Projects/sheltr-ai/apps/api/.venv/lib/python3.9/site-packages/google/auth/transport/grpc.py", line 81, in _get_authorization_headers
    self._credentials.before_request(
  File "/Users/mrjones/Github/Projects/sheltr-ai/apps/api/.venv/lib/python3.9/site-packages/google/auth/credentials.py", line 175, in before_request
    self.refresh(request)
  File "/Users/mrjones/Github/Projects/sheltr-ai/apps/api/.venv/lib/python3.9/site-packages/google/oauth2/service_account.py", line 449, in refresh
    access_token, expiry, _ = _client.jwt_grant(
  File "/Users/mrjones/Github/Projects/sheltr-ai/apps/api/.venv/lib/python3.9/site-packages/google/oauth2/_client.py", line 308, in jwt_grant
    response_data = _token_endpoint_request(
  File "/Users/mrjones/Github/Projects/sheltr-ai/apps/api/.venv/lib/python3.9/site-packages/google/oauth2/_client.py", line 279, in _token_endpoint_request
    _handle_error_response(response_data, retryable_error)
  File "/Users/mrjones/Github/Projects/sheltr-ai/apps/api/.venv/lib/python3.9/site-packages/google/oauth2/_client.py", line 72, in _handle_error_response
    raise exceptions.RefreshError(
google.auth.exceptions.RefreshError: ('invalid_grant: Invalid JWT Signature.', {'error': 'invalid_grant', 'error_description': 'Invalid JWT Signature.'})
ERROR:grpc._plugin_wrapping:AuthMetadataPluginCallback "<google.auth.transport.grpc.AuthMetadataPlugin object at 0x107d00250>" raised exception!
Traceback (most recent call last):
  File "/Users/mrjones/Github/Projects/sheltr-ai/apps/api/.venv/lib/python3.9/site-packages/grpc/_plugin_wrapping.py", line 105, in __call__
    self._metadata_plugin(
  File "/Users/mrjones/Github/Projects/sheltr-ai/apps/api/.venv/lib/python3.9/site-packages/google/auth/transport/grpc.py", line 95, in __call__
    callback(self._get_authorization_headers(context), None)
  File "/Users/mrjones/Github/Projects/sheltr-ai/apps/api/.venv/lib/python3.9/site-packages/google/auth/transport/grpc.py", line 81, in _get_authorization_headers
    self._credentials.before_request(
  File "/Users/mrjones/Github/Projects/sheltr-ai/apps/api/.venv/lib/python3.9/site-packages/google/auth/credentials.py", line 175, in before_request
    self.refresh(request)
  File "/Users/mrjones/Github/Projects/sheltr-ai/apps/api/.venv/lib/python3.9/site-packages/google/oauth2/service_account.py", line 449, in refresh
    access_token, expiry, _ = _client.jwt_grant(
  File "/Users/mrjones/Github/Projects/sheltr-ai/apps/api/.venv/lib/python3.9/site-packages/google/oauth2/_client.py", line 308, in jwt_grant
    response_data = _token_endpoint_request(
  File "/Users/mrjones/Github/Projects/sheltr-ai/apps/api/.venv/lib/python3.9/site-packages/google/oauth2/_client.py", line 279, in _token_endpoint_request
    _handle_error_response(response_data, retryable_error)
  File "/Users/mrjones/Github/Projects/sheltr-ai/apps/api/.venv/lib/python3.9/site-packages/google/oauth2/_client.py", line 72, in _handle_error_response
    raise exceptions.RefreshError(
google.auth.exceptions.RefreshError: ('invalid_grant: Invalid JWT Signature.', {'error': 'invalid_grant', 'error_description': 'Invalid JWT Signature.'})
ERROR:grpc._plugin_wrapping:AuthMetadataPluginCallback "<google.auth.transport.grpc.AuthMetadataPlugin object at 0x107d00250>" raised exception!
Traceback (most recent call last):
  File "/Users/mrjones/Github/Projects/sheltr-ai/apps/api/.venv/lib/python3.9/site-packages/grpc/_plugin_wrapping.py", line 105, in __call__
    self._metadata_plugin(
  File "/Users/mrjones/Github/Projects/sheltr-ai/apps/api/.venv/lib/python3.9/site-packages/google/auth/transport/grpc.py", line 95, in __call__
    callback(self._get_authorization_headers(context), None)
  File "/Users/mrjones/Github/Projects/sheltr-ai/apps/api/.venv/lib/python3.9/site-packages/google/auth/transport/grpc.py", line 81, in _get_authorization_headers
    self._credentials.before_request(
  File "/Users/mrjones/Github/Projects/sheltr-ai/apps/api/.venv/lib/python3.9/site-packages/google/auth/credentials.py", line 175, in before_request
    self.refresh(request)
  File "/Users/mrjones/Github/Projects/sheltr-ai/apps/api/.venv/lib/python3.9/site-packages/google/oauth2/service_account.py", line 449, in refresh
    access_token, expiry, _ = _client.jwt_grant(
  File "/Users/mrjones/Github/Projects/sheltr-ai/apps/api/.venv/lib/python3.9/site-packages/google/oauth2/_client.py", line 308, in jwt_grant
    response_data = _token_endpoint_request(
  File "/Users/mrjones/Github/Projects/sheltr-ai/apps/api/.venv/lib/python3.9/site-packages/google/oauth2/_client.py", line 279, in _token_endpoint_request
    _handle_error_response(response_data, retryable_error)
  File "/Users/mrjones/Github/Projects/sheltr-ai/apps/api/.venv/lib/python3.9/site-packages/google/oauth2/_client.py", line 72, in _handle_error_response
    raise exceptions.RefreshError(
google.auth.exceptions.RefreshError: ('invalid_grant: Invalid JWT Signature.', {'error': 'invalid_grant', 'error_description': 'Invalid JWT Signature.'})
ERROR:grpc._plugin_wrapping:AuthMetadataPluginCallback "<google.auth.transport.grpc.AuthMetadataPlugin object at 0x107d00250>" raised exception!
Traceback (most recent call last):
  File "/Users/mrjones/Github/Projects/sheltr-ai/apps/api/.venv/lib/python3.9/site-packages/grpc/_plugin_wrapping.py", line 105, in __call__
    self._metadata_plugin(
  File "/Users/mrjones/Github/Projects/sheltr-ai/apps/api/.venv/lib/python3.9/site-packages/google/auth/transport/grpc.py", line 95, in __call__
    callback(self._get_authorization_headers(context), None)
  File "/Users/mrjones/Github/Projects/sheltr-ai/apps/api/.venv/lib/python3.9/site-packages/google/auth/transport/grpc.py", line 81, in _get_authorization_headers
    self._credentials.before_request(
  File "/Users/mrjones/Github/Projects/sheltr-ai/apps/api/.venv/lib/python3.9/site-packages/google/auth/credentials.py", line 175, in before_request
    self.refresh(request)
  File "/Users/mrjones/Github/Projects/sheltr-ai/apps/api/.venv/lib/python3.9/site-packages/google/oauth2/service_account.py", line 449, in refresh
    access_token, expiry, _ = _client.jwt_grant(
  File "/Users/mrjones/Github/Projects/sheltr-ai/apps/api/.venv/lib/python3.9/site-packages/google/oauth2/_client.py", line 308, in jwt_grant
    response_data = _token_endpoint_request(
  File "/Users/mrjones/Github/Projects/sheltr-ai/apps/api/.venv/lib/python3.9/site-packages/google/oauth2/_client.py", line 279, in _token_endpoint_request
    _handle_error_response(response_data, retryable_error)
  File "/Users/mrjones/Github/Projects/sheltr-ai/apps/api/.venv/lib/python3.9/site-packages/google/oauth2/_client.py", line 72, in _handle_error_response
    raise exceptions.RefreshError(
google.auth.exceptions.RefreshError: ('invalid_grant: Invalid JWT Signature.', {'error': 'invalid_grant', 'error_description': 'Invalid JWT Signature.'})
ERROR:grpc._plugin_wrapping:AuthMetadataPluginCallback "<google.auth.transport.grpc.AuthMetadataPlugin object at 0x107d00250>" raised exception!
Traceback (most recent call last):
  File "/Users/mrjones/Github/Projects/sheltr-ai/apps/api/.venv/lib/python3.9/site-packages/grpc/_plugin_wrapping.py", line 105, in __call__
    self._metadata_plugin(
  File "/Users/mrjones/Github/Projects/sheltr-ai/apps/api/.venv/lib/python3.9/site-packages/google/auth/transport/grpc.py", line 95, in __call__
    callback(self._get_authorization_headers(context), None)
  File "/Users/mrjones/Github/Projects/sheltr-ai/apps/api/.venv/lib/python3.9/site-packages/google/auth/transport/grpc.py", line 81, in _get_authorization_headers
    self._credentials.before_request(
  File "/Users/mrjones/Github/Projects/sheltr-ai/apps/api/.venv/lib/python3.9/site-packages/google/auth/credentials.py", line 175, in before_request
    self.refresh(request)
  File "/Users/mrjones/Github/Projects/sheltr-ai/apps/api/.venv/lib/python3.9/site-packages/google/oauth2/service_account.py", line 449, in refresh
    access_token, expiry, _ = _client.jwt_grant(
  File "/Users/mrjones/Github/Projects/sheltr-ai/apps/api/.venv/lib/python3.9/site-packages/google/oauth2/_client.py", line 308, in jwt_grant
    response_data = _token_endpoint_request(
  File "/Users/mrjones/Github/Projects/sheltr-ai/apps/api/.venv/lib/python3.9/site-packages/google/oauth2/_client.py", line 279, in _token_endpoint_request
    _handle_error_response(response_data, retryable_error)
  File "/Users/mrjones/Github/Projects/sheltr-ai/apps/api/.venv/lib/python3.9/site-packages/google/oauth2/_client.py", line 72, in _handle_error_response
    raise exceptions.RefreshError(
google.auth.exceptions.RefreshError: ('invalid_grant: Invalid JWT Signature.', {'error': 'invalid_grant', 'error_description': 'Invalid JWT Signature.'})
ERROR:grpc._plugin_wrapping:AuthMetadataPluginCallback "<google.auth.transport.grpc.AuthMetadataPlugin object at 0x107d00250>" raised exception!
Traceback (most recent call last):
  File "/Users/mrjones/Github/Projects/sheltr-ai/apps/api/.venv/lib/python3.9/site-packages/grpc/_plugin_wrapping.py", line 105, in __call__
    self._metadata_plugin(
  File "/Users/mrjones/Github/Projects/sheltr-ai/apps/api/.venv/lib/python3.9/site-packages/google/auth/transport/grpc.py", line 95, in __call__
    callback(self._get_authorization_headers(context), None)
  File "/Users/mrjones/Github/Projects/sheltr-ai/apps/api/.venv/lib/python3.9/site-packages/google/auth/transport/grpc.py", line 81, in _get_authorization_headers
    self._credentials.before_request(
  File "/Users/mrjones/Github/Projects/sheltr-ai/apps/api/.venv/lib/python3.9/site-packages/google/auth/credentials.py", line 175, in before_request
    self.refresh(request)
  File "/Users/mrjones/Github/Projects/sheltr-ai/apps/api/.venv/lib/python3.9/site-packages/google/oauth2/service_account.py", line 449, in refresh
    access_token, expiry, _ = _client.jwt_grant(
  File "/Users/mrjones/Github/Projects/sheltr-ai/apps/api/.venv/lib/python3.9/site-packages/google/oauth2/_client.py", line 308, in jwt_grant
    response_data = _token_endpoint_request(
  File "/Users/mrjones/Github/Projects/sheltr-ai/apps/api/.venv/lib/python3.9/site-packages/google/oauth2/_client.py", line 279, in _token_endpoint_request
    _handle_error_response(response_data, retryable_error)
  File "/Users/mrjones/Github/Projects/sheltr-ai/apps/api/.venv/lib/python3.9/site-packages/google/oauth2/_client.py", line 72, in _handle_error_response
    raise exceptions.RefreshError(
google.auth.exceptions.RefreshError: ('invalid_grant: Invalid JWT Signature.', {'error': 'invalid_grant', 'error_description': 'Invalid JWT Signature.'})
ERROR:grpc._plugin_wrapping:AuthMetadataPluginCallback "<google.auth.transport.grpc.AuthMetadataPlugin object at 0x107d00250>" raised exception!
Traceback (most recent call last):
  File "/Users/mrjones/Github/Projects/sheltr-ai/apps/api/.venv/lib/python3.9/site-packages/grpc/_plugin_wrapping.py", line 105, in __call__
    self._metadata_plugin(
  File "/Users/mrjones/Github/Projects/sheltr-ai/apps/api/.venv/lib/python3.9/site-packages/google/auth/transport/grpc.py", line 95, in __call__
    callback(self._get_authorization_headers(context), None)
  File "/Users/mrjones/Github/Projects/sheltr-ai/apps/api/.venv/lib/python3.9/site-packages/google/auth/transport/grpc.py", line 81, in _get_authorization_headers
    self._credentials.before_request(
  File "/Users/mrjones/Github/Projects/sheltr-ai/apps/api/.venv/lib/python3.9/site-packages/google/auth/credentials.py", line 175, in before_request
    self.refresh(request)
  File "/Users/mrjones/Github/Projects/sheltr-ai/apps/api/.venv/lib/python3.9/site-packages/google/oauth2/service_account.py", line 449, in refresh
    access_token, expiry, _ = _client.jwt_grant(
  File "/Users/mrjones/Github/Projects/sheltr-ai/apps/api/.venv/lib/python3.9/site-packages/google/oauth2/_client.py", line 308, in jwt_grant
    response_data = _token_endpoint_request(
  File "/Users/mrjones/Github/Projects/sheltr-ai/apps/api/.venv/lib/python3.9/site-packages/google/oauth2/_client.py", line 279, in _token_endpoint_request
    _handle_error_response(response_data, retryable_error)
  File "/Users/mrjones/Github/Projects/sheltr-ai/apps/api/.venv/lib/python3.9/site-packages/google/oauth2/_client.py", line 72, in _handle_error_response
    raise exceptions.RefreshError(
google.auth.exceptions.RefreshError: ('invalid_grant: Invalid JWT Signature.', {'error': 'invalid_grant', 'error_description': 'Invalid JWT Signature.'})
ERROR:grpc._plugin_wrapping:AuthMetadataPluginCallback "<google.auth.transport.grpc.AuthMetadataPlugin object at 0x107d00250>" raised exception!
Traceback (most recent call last):
  File "/Users/mrjones/Github/Projects/sheltr-ai/apps/api/.venv/lib/python3.9/site-packages/grpc/_plugin_wrapping.py", line 105, in __call__
    self._metadata_plugin(
  File "/Users/mrjones/Github/Projects/sheltr-ai/apps/api/.venv/lib/python3.9/site-packages/google/auth/transport/grpc.py", line 95, in __call__
    callback(self._get_authorization_headers(context), None)
  File "/Users/mrjones/Github/Projects/sheltr-ai/apps/api/.venv/lib/python3.9/site-packages/google/auth/transport/grpc.py", line 81, in _get_authorization_headers
    self._credentials.before_request(
  File "/Users/mrjones/Github/Projects/sheltr-ai/apps/api/.venv/lib/python3.9/site-packages/google/auth/credentials.py", line 175, in before_request
    self.refresh(request)
  File "/Users/mrjones/Github/Projects/sheltr-ai/apps/api/.venv/lib/python3.9/site-packages/google/oauth2/service_account.py", line 449, in refresh
    access_token, expiry, _ = _client.jwt_grant(
  File "/Users/mrjones/Github/Projects/sheltr-ai/apps/api/.venv/lib/python3.9/site-packages/google/oauth2/_client.py", line 308, in jwt_grant
    response_data = _token_endpoint_request(
  File "/Users/mrjones/Github/Projects/sheltr-ai/apps/api/.venv/lib/python3.9/site-packages/google/oauth2/_client.py", line 279, in _token_endpoint_request
    _handle_error_response(response_data, retryable_error)
  File "/Users/mrjones/Github/Projects/sheltr-ai/apps/api/.venv/lib/python3.9/site-packages/google/oauth2/_client.py", line 72, in _handle_error_response
    raise exceptions.RefreshError(
google.auth.exceptions.RefreshError: ('invalid_grant: Invalid JWT Signature.', {'error': 'invalid_grant', 'error_description': 'Invalid JWT Signature.'})
